03144a0cb23de877-Traceback (most recent call last):
  File "C:\Users\YQ\Desktop\小满海关数据爬取\step4.py", line 78, in get_data
    response = self.session.get(url=url_, proxies={'http': proxy}).json()
  File "D:\Anaconda\lib\site-packages\requests\models.py", line 892, in json
    return complexjson.loads(self.text, **kwargs)
  File "D:\Anaconda\lib\json\__init__.py", line 354, in loads
    return _default_decoder.decode(s)
  File "D:\Anaconda\lib\json\decoder.py", line 339, in decode
    obj, end = self.raw_decode(s, idx=_w(s, 0).end())
  File "D:\Anaconda\lib\json\decoder.py", line 357, in raw_decode
    raise JSONDecodeError("Expecting value", s, err.value) from None
json.decoder.JSONDecodeError: Expecting value: line 1 column 1 (char 0)
&ccabc2f38e8cb087-Traceback (most recent call last):
  File "C:\Users\YQ\Desktop\小满海关数据爬取\step4.py", line 78, in get_data
    response = self.session.get(url=url_, proxies={'http': proxy}).json()
  File "D:\Anaconda\lib\site-packages\requests\models.py", line 892, in json
    return complexjson.loads(self.text, **kwargs)
  File "D:\Anaconda\lib\json\__init__.py", line 354, in loads
    return _default_decoder.decode(s)
  File "D:\Anaconda\lib\json\decoder.py", line 339, in decode
    obj, end = self.raw_decode(s, idx=_w(s, 0).end())
  File "D:\Anaconda\lib\json\decoder.py", line 357, in raw_decode
    raise JSONDecodeError("Expecting value", s, err.value) from None
json.decoder.JSONDecodeError: Expecting value: line 1 column 1 (char 0)
&uszi3f755175136019af374871d4317aaf53-Traceback (most recent call last):
  File "D:\Anaconda\lib\site-packages\pymysql\connections.py", line 690, in _read_bytes
    data = self._rfile.read(num_bytes)
  File "D:\Anaconda\lib\socket.py", line 586, in readinto
    return self._sock.recv_into(b)
ConnectionAbortedError: [WinError 10053] 你的主机中的软件中止了一个已建立的连接。

During handling of the above exception, another exception occurred:

Traceback (most recent call last):
  File "C:\Users\YQ\Desktop\小满海关数据爬取\step4.py", line 115, in get_data
    self.write2sql(sql)
  File "C:\Users\YQ\Desktop\小满海关数据爬取\step4.py", line 130, in write2sql
    cur.execute(sql)
  File "D:\Anaconda\lib\site-packages\pymysql\cursors.py", line 170, in execute
    result = self._query(query)
  File "D:\Anaconda\lib\site-packages\pymysql\cursors.py", line 328, in _query
    conn.query(q)
  File "D:\Anaconda\lib\site-packages\pymysql\connections.py", line 516, in query
    self._affected_rows = self._read_query_result(unbuffered=unbuffered)
  File "D:\Anaconda\lib\site-packages\pymysql\connections.py", line 727, in _read_query_result
    result.read()
  File "D:\Anaconda\lib\site-packages\pymysql\connections.py", line 1066, in read
    first_packet = self.connection._read_packet()
  File "D:\Anaconda\lib\site-packages\pymysql\connections.py", line 656, in _read_packet
    packet_header = self._read_bytes(4)
  File "D:\Anaconda\lib\site-packages\pymysql\connections.py", line 698, in _read_bytes
    "Lost connection to MySQL server during query (%s)" % (e,))
pymysql.err.OperationalError: (2013, 'Lost connection to MySQL server during query ([WinError 10053] 你的主机中的软件中止了一个已建立的连接。)')
&0106751e11024cab-Traceback (most recent call last):
  File "C:\Users\YQ\Desktop\小满海关数据爬取\step4.py", line 115, in get_data
    self.write2sql(sql)
  File "C:\Users\YQ\Desktop\小满海关数据爬取\step4.py", line 130, in write2sql
    cur.execute(sql)
  File "D:\Anaconda\lib\site-packages\pymysql\cursors.py", line 170, in execute
    result = self._query(query)
  File "D:\Anaconda\lib\site-packages\pymysql\cursors.py", line 328, in _query
    conn.query(q)
  File "D:\Anaconda\lib\site-packages\pymysql\connections.py", line 515, in query
    self._execute_command(COMMAND.COM_QUERY, sql)
  File "D:\Anaconda\lib\site-packages\pymysql\connections.py", line 745, in _execute_command
    raise err.InterfaceError("(0, '')")
pymysql.err.InterfaceError: (0, '')
&