07dd44744cb0b141-Traceback (most recent call last):
  File "C:\Users\YQ\Desktop\小满海关数据爬取\step2.py", line 116, in get_data
    self.write2sql(sql)
  File "C:\Users\YQ\Desktop\小满海关数据爬取\step2.py", line 245, in write2sql
    cur.execute(sql)
  File "D:\Anaconda\lib\site-packages\pymysql\cursors.py", line 170, in execute
    result = self._query(query)
  File "D:\Anaconda\lib\site-packages\pymysql\cursors.py", line 328, in _query
    conn.query(q)
  File "D:\Anaconda\lib\site-packages\pymysql\connections.py", line 516, in query
    self._affected_rows = self._read_query_result(unbuffered=unbuffered)
  File "D:\Anaconda\lib\site-packages\pymysql\connections.py", line 727, in _read_query_result
    result.read()
  File "D:\Anaconda\lib\site-packages\pymysql\connections.py", line 1066, in read
    first_packet = self.connection._read_packet()
  File "D:\Anaconda\lib\site-packages\pymysql\connections.py", line 683, in _read_packet
    packet.check_error()
  File "D:\Anaconda\lib\site-packages\pymysql\protocol.py", line 220, in check_error
    err.raise_mysql_exception(self._data)
  File "D:\Anaconda\lib\site-packages\pymysql\err.py", line 109, in raise_mysql_exception
    raise errorclass(errno, errval)
pymysql.err.ProgrammingError: (1064, "You have an error in your SQL syntax; check the manual that corresponds to your MySQL server version for the right syntax to use near 's Furniture in the  Baton Rouge and Lafayette, Louisiana for all of your furnitu' at line 1")
&a1c016abd4ab22d9-Traceback (most recent call last):
  File "C:\Users\YQ\Desktop\小满海关数据爬取\step2.py", line 116, in get_data
    self.write2sql(sql)
  File "C:\Users\YQ\Desktop\小满海关数据爬取\step2.py", line 245, in write2sql
    cur.execute(sql)
  File "D:\Anaconda\lib\site-packages\pymysql\cursors.py", line 170, in execute
    result = self._query(query)
  File "D:\Anaconda\lib\site-packages\pymysql\cursors.py", line 328, in _query
    conn.query(q)
  File "D:\Anaconda\lib\site-packages\pymysql\connections.py", line 516, in query
    self._affected_rows = self._read_query_result(unbuffered=unbuffered)
  File "D:\Anaconda\lib\site-packages\pymysql\connections.py", line 727, in _read_query_result
    result.read()
  File "D:\Anaconda\lib\site-packages\pymysql\connections.py", line 1066, in read
    first_packet = self.connection._read_packet()
  File "D:\Anaconda\lib\site-packages\pymysql\connections.py", line 683, in _read_packet
    packet.check_error()
  File "D:\Anaconda\lib\site-packages\pymysql\protocol.py", line 220, in check_error
    err.raise_mysql_exception(self._data)
  File "D:\Anaconda\lib\site-packages\pymysql\err.py", line 109, in raise_mysql_exception
    raise errorclass(errno, errval)
pymysql.err.ProgrammingError: (1064, "You have an error in your SQL syntax; check the manual that corresponds to your MySQL server version for the right syntax to use near 's' trusted mattress store and sleep expert. Visit our site for sales or speak to' at line 1")
&bc1cd2ab1f216b23-Traceback (most recent call last):
  File "C:\Users\YQ\Desktop\小满海关数据爬取\step2.py", line 116, in get_data
    self.write2sql(sql)
  File "C:\Users\YQ\Desktop\小满海关数据爬取\step2.py", line 245, in write2sql
    cur.execute(sql)
  File "D:\Anaconda\lib\site-packages\pymysql\cursors.py", line 170, in execute
    result = self._query(query)
  File "D:\Anaconda\lib\site-packages\pymysql\cursors.py", line 328, in _query
    conn.query(q)
  File "D:\Anaconda\lib\site-packages\pymysql\connections.py", line 516, in query
    self._affected_rows = self._read_query_result(unbuffered=unbuffered)
  File "D:\Anaconda\lib\site-packages\pymysql\connections.py", line 727, in _read_query_result
    result.read()
  File "D:\Anaconda\lib\site-packages\pymysql\connections.py", line 1066, in read
    first_packet = self.connection._read_packet()
  File "D:\Anaconda\lib\site-packages\pymysql\connections.py", line 683, in _read_packet
    packet.check_error()
  File "D:\Anaconda\lib\site-packages\pymysql\protocol.py", line 220, in check_error
    err.raise_mysql_exception(self._data)
  File "D:\Anaconda\lib\site-packages\pymysql\err.py", line 109, in raise_mysql_exception
    raise errorclass(errno, errval)
pymysql.err.ProgrammingError: (1064, "You have an error in your SQL syntax; check the manual that corresponds to your MySQL server version for the right syntax to use near 's Home Appliance Mart online for the best pricing in Home Appliances, Audio Vide' at line 1")
&d2d0a3df0c5bf3a9-Traceback (most recent call last):
  File "D:\Anaconda\lib\site-packages\urllib3\connectionpool.py", line 601, in urlopen
    chunked=chunked)
  File "D:\Anaconda\lib\site-packages\urllib3\connectionpool.py", line 387, in _make_request
    six.raise_from(e, None)
  File "<string>", line 2, in raise_from
  File "D:\Anaconda\lib\site-packages\urllib3\connectionpool.py", line 383, in _make_request
    httplib_response = conn.getresponse()
  File "D:\Anaconda\lib\http\client.py", line 1331, in getresponse
    response.begin()
  File "D:\Anaconda\lib\http\client.py", line 297, in begin
    version, status, reason = self._read_status()
  File "D:\Anaconda\lib\http\client.py", line 258, in _read_status
    line = str(self.fp.readline(_MAXLINE + 1), "iso-8859-1")
  File "D:\Anaconda\lib\socket.py", line 586, in readinto
    return self._sock.recv_into(b)
  File "D:\Anaconda\lib\site-packages\urllib3\contrib\pyopenssl.py", line 285, in recv_into
    raise SocketError(str(e))
OSError: (10054, 'WSAECONNRESET')

During handling of the above exception, another exception occurred:

Traceback (most recent call last):
  File "D:\Anaconda\lib\site-packages\requests\adapters.py", line 440, in send
    timeout=timeout
  File "D:\Anaconda\lib\site-packages\urllib3\connectionpool.py", line 639, in urlopen
    _stacktrace=sys.exc_info()[2])
  File "D:\Anaconda\lib\site-packages\urllib3\util\retry.py", line 388, in increment
    raise MaxRetryError(_pool, url, error or ResponseError(cause))
urllib3.exceptions.MaxRetryError: HTTPSConnectionPool(host='x.xiaoman.cn', port=443): Max retries exceeded with url: /api/company-read/profile?brief_only=true&id=d2d0a3df0c5bf3a9 (Caused by ProxyError('Cannot connect to proxy.', OSError("(10054, 'WSAECONNRESET')",)))

During handling of the above exception, another exception occurred:

Traceback (most recent call last):
  File "C:\Users\YQ\Desktop\小满海关数据爬取\step2.py", line 68, in get_data
    response = self.session.get(url=url, proxies={'http': proxy}).json()
  File "D:\Anaconda\lib\site-packages\requests\sessions.py", line 521, in get
    return self.request('GET', url, **kwargs)
  File "D:\Anaconda\lib\site-packages\requests\sessions.py", line 508, in request
    resp = self.send(prep, **send_kwargs)
  File "D:\Anaconda\lib\site-packages\requests\sessions.py", line 618, in send
    r = adapter.send(request, **kwargs)
  File "D:\Anaconda\lib\site-packages\requests\adapters.py", line 502, in send
    raise ProxyError(e, request=request)
requests.exceptions.ProxyError: HTTPSConnectionPool(host='x.xiaoman.cn', port=443): Max retries exceeded with url: /api/company-read/profile?brief_only=true&id=d2d0a3df0c5bf3a9 (Caused by ProxyError('Cannot connect to proxy.', OSError("(10054, 'WSAECONNRESET')",)))
&