904949d4a6d883c2-Traceback (most recent call last):
  File "C:\Users\YQ\Desktop\小满海关数据爬取\step2.py", line 145, in get_data
    self.write2sql(sql)
  File "C:\Users\YQ\Desktop\小满海关数据爬取\step2.py", line 228, in write2sql
    cur1.execute(sql)
  File "D:\Anaconda\lib\site-packages\pymysql\cursors.py", line 170, in execute
    result = self._query(query)
  File "D:\Anaconda\lib\site-packages\pymysql\cursors.py", line 328, in _query
    conn.query(q)
  File "D:\Anaconda\lib\site-packages\pymysql\connections.py", line 516, in query
    self._affected_rows = self._read_query_result(unbuffered=unbuffered)
  File "D:\Anaconda\lib\site-packages\pymysql\connections.py", line 727, in _read_query_result
    result.read()
  File "D:\Anaconda\lib\site-packages\pymysql\connections.py", line 1066, in read
    first_packet = self.connection._read_packet()
  File "D:\Anaconda\lib\site-packages\pymysql\connections.py", line 683, in _read_packet
    packet.check_error()
  File "D:\Anaconda\lib\site-packages\pymysql\protocol.py", line 220, in check_error
    err.raise_mysql_exception(self._data)
  File "D:\Anaconda\lib\site-packages\pymysql\err.py", line 109, in raise_mysql_exception
    raise errorclass(errno, errval)
pymysql.err.InternalError: (1136, "Column count doesn't match value count at row 1")
&2f1e1c73e3365b35-Traceback (most recent call last):
  File "C:\Users\YQ\Desktop\小满海关数据爬取\step2.py", line 145, in get_data
    self.write2sql(sql)
  File "C:\Users\YQ\Desktop\小满海关数据爬取\step2.py", line 228, in write2sql
    cur1.execute(sql)
  File "D:\Anaconda\lib\site-packages\pymysql\cursors.py", line 170, in execute
    result = self._query(query)
  File "D:\Anaconda\lib\site-packages\pymysql\cursors.py", line 328, in _query
    conn.query(q)
  File "D:\Anaconda\lib\site-packages\pymysql\connections.py", line 516, in query
    self._affected_rows = self._read_query_result(unbuffered=unbuffered)
  File "D:\Anaconda\lib\site-packages\pymysql\connections.py", line 727, in _read_query_result
    result.read()
  File "D:\Anaconda\lib\site-packages\pymysql\connections.py", line 1066, in read
    first_packet = self.connection._read_packet()
  File "D:\Anaconda\lib\site-packages\pymysql\connections.py", line 683, in _read_packet
    packet.check_error()
  File "D:\Anaconda\lib\site-packages\pymysql\protocol.py", line 220, in check_error
    err.raise_mysql_exception(self._data)
  File "D:\Anaconda\lib\site-packages\pymysql\err.py", line 109, in raise_mysql_exception
    raise errorclass(errno, errval)
pymysql.err.InternalError: (1136, "Column count doesn't match value count at row 1")
&879c680b56466fa7-Traceback (most recent call last):
  File "C:\Users\YQ\Desktop\小满海关数据爬取\step2.py", line 145, in get_data
    self.write2sql(sql)
  File "C:\Users\YQ\Desktop\小满海关数据爬取\step2.py", line 228, in write2sql
    cur1.execute(sql)
  File "D:\Anaconda\lib\site-packages\pymysql\cursors.py", line 170, in execute
    result = self._query(query)
  File "D:\Anaconda\lib\site-packages\pymysql\cursors.py", line 328, in _query
    conn.query(q)
  File "D:\Anaconda\lib\site-packages\pymysql\connections.py", line 516, in query
    self._affected_rows = self._read_query_result(unbuffered=unbuffered)
  File "D:\Anaconda\lib\site-packages\pymysql\connections.py", line 727, in _read_query_result
    result.read()
  File "D:\Anaconda\lib\site-packages\pymysql\connections.py", line 1066, in read
    first_packet = self.connection._read_packet()
  File "D:\Anaconda\lib\site-packages\pymysql\connections.py", line 683, in _read_packet
    packet.check_error()
  File "D:\Anaconda\lib\site-packages\pymysql\protocol.py", line 220, in check_error
    err.raise_mysql_exception(self._data)
  File "D:\Anaconda\lib\site-packages\pymysql\err.py", line 109, in raise_mysql_exception
    raise errorclass(errno, errval)
pymysql.err.InternalError: (1136, "Column count doesn't match value count at row 1")
&433d6c1417553f5b-Traceback (most recent call last):
  File "C:\Users\YQ\Desktop\小满海关数据爬取\step2.py", line 145, in get_data
    self.write2sql(sql)
  File "C:\Users\YQ\Desktop\小满海关数据爬取\step2.py", line 228, in write2sql
    cur1.execute(sql)
  File "D:\Anaconda\lib\site-packages\pymysql\cursors.py", line 170, in execute
    result = self._query(query)
  File "D:\Anaconda\lib\site-packages\pymysql\cursors.py", line 328, in _query
    conn.query(q)
  File "D:\Anaconda\lib\site-packages\pymysql\connections.py", line 516, in query
    self._affected_rows = self._read_query_result(unbuffered=unbuffered)
  File "D:\Anaconda\lib\site-packages\pymysql\connections.py", line 727, in _read_query_result
    result.read()
  File "D:\Anaconda\lib\site-packages\pymysql\connections.py", line 1066, in read
    first_packet = self.connection._read_packet()
  File "D:\Anaconda\lib\site-packages\pymysql\connections.py", line 683, in _read_packet
    packet.check_error()
  File "D:\Anaconda\lib\site-packages\pymysql\protocol.py", line 220, in check_error
    err.raise_mysql_exception(self._data)
  File "D:\Anaconda\lib\site-packages\pymysql\err.py", line 109, in raise_mysql_exception
    raise errorclass(errno, errval)
pymysql.err.InternalError: (1136, "Column count doesn't match value count at row 1")
&b0951958140d9ec1-Traceback (most recent call last):
  File "C:\Users\YQ\Desktop\小满海关数据爬取\step2.py", line 145, in get_data
    self.write2sql(sql)
  File "C:\Users\YQ\Desktop\小满海关数据爬取\step2.py", line 228, in write2sql
    cur1.execute(sql)
  File "D:\Anaconda\lib\site-packages\pymysql\cursors.py", line 170, in execute
    result = self._query(query)
  File "D:\Anaconda\lib\site-packages\pymysql\cursors.py", line 328, in _query
    conn.query(q)
  File "D:\Anaconda\lib\site-packages\pymysql\connections.py", line 516, in query
    self._affected_rows = self._read_query_result(unbuffered=unbuffered)
  File "D:\Anaconda\lib\site-packages\pymysql\connections.py", line 727, in _read_query_result
    result.read()
  File "D:\Anaconda\lib\site-packages\pymysql\connections.py", line 1066, in read
    first_packet = self.connection._read_packet()
  File "D:\Anaconda\lib\site-packages\pymysql\connections.py", line 683, in _read_packet
    packet.check_error()
  File "D:\Anaconda\lib\site-packages\pymysql\protocol.py", line 220, in check_error
    err.raise_mysql_exception(self._data)
  File "D:\Anaconda\lib\site-packages\pymysql\err.py", line 109, in raise_mysql_exception
    raise errorclass(errno, errval)
pymysql.err.InternalError: (1136, "Column count doesn't match value count at row 1")
&aa3e40e9230ec935-Traceback (most recent call last):
  File "C:\Users\YQ\Desktop\小满海关数据爬取\step2.py", line 145, in get_data
    self.write2sql(sql)
  File "C:\Users\YQ\Desktop\小满海关数据爬取\step2.py", line 228, in write2sql
    cur1.execute(sql)
  File "D:\Anaconda\lib\site-packages\pymysql\cursors.py", line 170, in execute
    result = self._query(query)
  File "D:\Anaconda\lib\site-packages\pymysql\cursors.py", line 328, in _query
    conn.query(q)
  File "D:\Anaconda\lib\site-packages\pymysql\connections.py", line 516, in query
    self._affected_rows = self._read_query_result(unbuffered=unbuffered)
  File "D:\Anaconda\lib\site-packages\pymysql\connections.py", line 727, in _read_query_result
    result.read()
  File "D:\Anaconda\lib\site-packages\pymysql\connections.py", line 1066, in read
    first_packet = self.connection._read_packet()
  File "D:\Anaconda\lib\site-packages\pymysql\connections.py", line 683, in _read_packet
    packet.check_error()
  File "D:\Anaconda\lib\site-packages\pymysql\protocol.py", line 220, in check_error
    err.raise_mysql_exception(self._data)
  File "D:\Anaconda\lib\site-packages\pymysql\err.py", line 109, in raise_mysql_exception
    raise errorclass(errno, errval)
pymysql.err.InternalError: (1136, "Column count doesn't match value count at row 1")
&972394f0c07abe8d-Traceback (most recent call last):
  File "C:\Users\YQ\Desktop\小满海关数据爬取\step2.py", line 145, in get_data
    self.write2sql(sql)
  File "C:\Users\YQ\Desktop\小满海关数据爬取\step2.py", line 228, in write2sql
    cur1.execute(sql)
  File "D:\Anaconda\lib\site-packages\pymysql\cursors.py", line 170, in execute
    result = self._query(query)
  File "D:\Anaconda\lib\site-packages\pymysql\cursors.py", line 328, in _query
    conn.query(q)
  File "D:\Anaconda\lib\site-packages\pymysql\connections.py", line 516, in query
    self._affected_rows = self._read_query_result(unbuffered=unbuffered)
  File "D:\Anaconda\lib\site-packages\pymysql\connections.py", line 727, in _read_query_result
    result.read()
  File "D:\Anaconda\lib\site-packages\pymysql\connections.py", line 1066, in read
    first_packet = self.connection._read_packet()
  File "D:\Anaconda\lib\site-packages\pymysql\connections.py", line 683, in _read_packet
    packet.check_error()
  File "D:\Anaconda\lib\site-packages\pymysql\protocol.py", line 220, in check_error
    err.raise_mysql_exception(self._data)
  File "D:\Anaconda\lib\site-packages\pymysql\err.py", line 109, in raise_mysql_exception
    raise errorclass(errno, errval)
pymysql.err.InternalError: (1136, "Column count doesn't match value count at row 1")
&b2e492ffac8d3754-Traceback (most recent call last):
  File "C:\Users\YQ\Desktop\小满海关数据爬取\step2.py", line 145, in get_data
    self.write2sql(sql)
  File "C:\Users\YQ\Desktop\小满海关数据爬取\step2.py", line 228, in write2sql
    cur1.execute(sql)
  File "D:\Anaconda\lib\site-packages\pymysql\cursors.py", line 170, in execute
    result = self._query(query)
  File "D:\Anaconda\lib\site-packages\pymysql\cursors.py", line 328, in _query
    conn.query(q)
  File "D:\Anaconda\lib\site-packages\pymysql\connections.py", line 516, in query
    self._affected_rows = self._read_query_result(unbuffered=unbuffered)
  File "D:\Anaconda\lib\site-packages\pymysql\connections.py", line 727, in _read_query_result
    result.read()
  File "D:\Anaconda\lib\site-packages\pymysql\connections.py", line 1066, in read
    first_packet = self.connection._read_packet()
  File "D:\Anaconda\lib\site-packages\pymysql\connections.py", line 683, in _read_packet
    packet.check_error()
  File "D:\Anaconda\lib\site-packages\pymysql\protocol.py", line 220, in check_error
    err.raise_mysql_exception(self._data)
  File "D:\Anaconda\lib\site-packages\pymysql\err.py", line 109, in raise_mysql_exception
    raise errorclass(errno, errval)
pymysql.err.InternalError: (1136, "Column count doesn't match value count at row 1")
&1c0bdaf2bdad3cf2-Traceback (most recent call last):
  File "C:\Users\YQ\Desktop\小满海关数据爬取\step2.py", line 145, in get_data
    self.write2sql(sql)
  File "C:\Users\YQ\Desktop\小满海关数据爬取\step2.py", line 228, in write2sql
    cur1.execute(sql)
  File "D:\Anaconda\lib\site-packages\pymysql\cursors.py", line 170, in execute
    result = self._query(query)
  File "D:\Anaconda\lib\site-packages\pymysql\cursors.py", line 328, in _query
    conn.query(q)
  File "D:\Anaconda\lib\site-packages\pymysql\connections.py", line 516, in query
    self._affected_rows = self._read_query_result(unbuffered=unbuffered)
  File "D:\Anaconda\lib\site-packages\pymysql\connections.py", line 727, in _read_query_result
    result.read()
  File "D:\Anaconda\lib\site-packages\pymysql\connections.py", line 1066, in read
    first_packet = self.connection._read_packet()
  File "D:\Anaconda\lib\site-packages\pymysql\connections.py", line 683, in _read_packet
    packet.check_error()
  File "D:\Anaconda\lib\site-packages\pymysql\protocol.py", line 220, in check_error
    err.raise_mysql_exception(self._data)
  File "D:\Anaconda\lib\site-packages\pymysql\err.py", line 109, in raise_mysql_exception
    raise errorclass(errno, errval)
pymysql.err.InternalError: (1136, "Column count doesn't match value count at row 1")
&8c0be26ca809f4a0-Traceback (most recent call last):
  File "C:\Users\YQ\Desktop\小满海关数据爬取\step2.py", line 145, in get_data
    self.write2sql(sql)
  File "C:\Users\YQ\Desktop\小满海关数据爬取\step2.py", line 228, in write2sql
    cur1.execute(sql)
  File "D:\Anaconda\lib\site-packages\pymysql\cursors.py", line 170, in execute
    result = self._query(query)
  File "D:\Anaconda\lib\site-packages\pymysql\cursors.py", line 328, in _query
    conn.query(q)
  File "D:\Anaconda\lib\site-packages\pymysql\connections.py", line 516, in query
    self._affected_rows = self._read_query_result(unbuffered=unbuffered)
  File "D:\Anaconda\lib\site-packages\pymysql\connections.py", line 727, in _read_query_result
    result.read()
  File "D:\Anaconda\lib\site-packages\pymysql\connections.py", line 1066, in read
    first_packet = self.connection._read_packet()
  File "D:\Anaconda\lib\site-packages\pymysql\connections.py", line 683, in _read_packet
    packet.check_error()
  File "D:\Anaconda\lib\site-packages\pymysql\protocol.py", line 220, in check_error
    err.raise_mysql_exception(self._data)
  File "D:\Anaconda\lib\site-packages\pymysql\err.py", line 109, in raise_mysql_exception
    raise errorclass(errno, errval)
pymysql.err.InternalError: (1136, "Column count doesn't match value count at row 1")
&b7896826ad369753-Traceback (most recent call last):
  File "C:\Users\YQ\Desktop\小满海关数据爬取\step2.py", line 145, in get_data
    self.write2sql(sql)
  File "C:\Users\YQ\Desktop\小满海关数据爬取\step2.py", line 228, in write2sql
    cur1.execute(sql)
  File "D:\Anaconda\lib\site-packages\pymysql\cursors.py", line 170, in execute
    result = self._query(query)
  File "D:\Anaconda\lib\site-packages\pymysql\cursors.py", line 328, in _query
    conn.query(q)
  File "D:\Anaconda\lib\site-packages\pymysql\connections.py", line 516, in query
    self._affected_rows = self._read_query_result(unbuffered=unbuffered)
  File "D:\Anaconda\lib\site-packages\pymysql\connections.py", line 727, in _read_query_result
    result.read()
  File "D:\Anaconda\lib\site-packages\pymysql\connections.py", line 1066, in read
    first_packet = self.connection._read_packet()
  File "D:\Anaconda\lib\site-packages\pymysql\connections.py", line 683, in _read_packet
    packet.check_error()
  File "D:\Anaconda\lib\site-packages\pymysql\protocol.py", line 220, in check_error
    err.raise_mysql_exception(self._data)
  File "D:\Anaconda\lib\site-packages\pymysql\err.py", line 109, in raise_mysql_exception
    raise errorclass(errno, errval)
pymysql.err.InternalError: (1136, "Column count doesn't match value count at row 1")
&9e2723a07dd34d80-Traceback (most recent call last):
  File "C:\Users\YQ\Desktop\小满海关数据爬取\step2.py", line 145, in get_data
    self.write2sql(sql)
  File "C:\Users\YQ\Desktop\小满海关数据爬取\step2.py", line 228, in write2sql
    cur1.execute(sql)
  File "D:\Anaconda\lib\site-packages\pymysql\cursors.py", line 170, in execute
    result = self._query(query)
  File "D:\Anaconda\lib\site-packages\pymysql\cursors.py", line 328, in _query
    conn.query(q)
  File "D:\Anaconda\lib\site-packages\pymysql\connections.py", line 516, in query
    self._affected_rows = self._read_query_result(unbuffered=unbuffered)
  File "D:\Anaconda\lib\site-packages\pymysql\connections.py", line 727, in _read_query_result
    result.read()
  File "D:\Anaconda\lib\site-packages\pymysql\connections.py", line 1066, in read
    first_packet = self.connection._read_packet()
  File "D:\Anaconda\lib\site-packages\pymysql\connections.py", line 683, in _read_packet
    packet.check_error()
  File "D:\Anaconda\lib\site-packages\pymysql\protocol.py", line 220, in check_error
    err.raise_mysql_exception(self._data)
  File "D:\Anaconda\lib\site-packages\pymysql\err.py", line 109, in raise_mysql_exception
    raise errorclass(errno, errval)
pymysql.err.InternalError: (1136, "Column count doesn't match value count at row 1")
&