73817151d797f749-Traceback (most recent call last):
  File "C:\Users\lenovo\Desktop\小满海关数据爬取\step2.py", line 104, in get_data
    self.write2sql(sql)
  File "C:\Users\lenovo\Desktop\小满海关数据爬取\step2.py", line 228, in write2sql
    cur.execute(sql)
  File "C:\ProgramData\Anaconda3\lib\site-packages\pymysql\cursors.py", line 170, in execute
    result = self._query(query)
  File "C:\ProgramData\Anaconda3\lib\site-packages\pymysql\cursors.py", line 328, in _query
    conn.query(q)
  File "C:\ProgramData\Anaconda3\lib\site-packages\pymysql\connections.py", line 516, in query
    self._affected_rows = self._read_query_result(unbuffered=unbuffered)
  File "C:\ProgramData\Anaconda3\lib\site-packages\pymysql\connections.py", line 727, in _read_query_result
    result.read()
  File "C:\ProgramData\Anaconda3\lib\site-packages\pymysql\connections.py", line 1066, in read
    first_packet = self.connection._read_packet()
  File "C:\ProgramData\Anaconda3\lib\site-packages\pymysql\connections.py", line 683, in _read_packet
    packet.check_error()
  File "C:\ProgramData\Anaconda3\lib\site-packages\pymysql\protocol.py", line 220, in check_error
    err.raise_mysql_exception(self._data)
  File "C:\ProgramData\Anaconda3\lib\site-packages\pymysql\err.py", line 109, in raise_mysql_exception
    raise errorclass(errno, errval)
pymysql.err.ProgrammingError: (1146, "Table 'xiaoman.comp' doesn't exist")
&dezi49ac67d60e5678c36bdc99cacdab4060-Traceback (most recent call last):
  File "C:\Users\lenovo\Desktop\小满海关数据爬取\step2.py", line 104, in get_data
    self.write2sql(sql)
  File "C:\Users\lenovo\Desktop\小满海关数据爬取\step2.py", line 228, in write2sql
    cur.execute(sql)
  File "C:\ProgramData\Anaconda3\lib\site-packages\pymysql\cursors.py", line 170, in execute
    result = self._query(query)
  File "C:\ProgramData\Anaconda3\lib\site-packages\pymysql\cursors.py", line 328, in _query
    conn.query(q)
  File "C:\ProgramData\Anaconda3\lib\site-packages\pymysql\connections.py", line 516, in query
    self._affected_rows = self._read_query_result(unbuffered=unbuffered)
  File "C:\ProgramData\Anaconda3\lib\site-packages\pymysql\connections.py", line 727, in _read_query_result
    result.read()
  File "C:\ProgramData\Anaconda3\lib\site-packages\pymysql\connections.py", line 1066, in read
    first_packet = self.connection._read_packet()
  File "C:\ProgramData\Anaconda3\lib\site-packages\pymysql\connections.py", line 683, in _read_packet
    packet.check_error()
  File "C:\ProgramData\Anaconda3\lib\site-packages\pymysql\protocol.py", line 220, in check_error
    err.raise_mysql_exception(self._data)
  File "C:\ProgramData\Anaconda3\lib\site-packages\pymysql\err.py", line 109, in raise_mysql_exception
    raise errorclass(errno, errval)
pymysql.err.ProgrammingError: (1146, "Table 'xiaoman.comp' doesn't exist")
&a03306bc47ba7a4f-Traceback (most recent call last):
  File "C:\Users\lenovo\Desktop\小满海关数据爬取\step2.py", line 104, in get_data
    self.write2sql(sql)
  File "C:\Users\lenovo\Desktop\小满海关数据爬取\step2.py", line 228, in write2sql
    cur.execute(sql)
  File "C:\ProgramData\Anaconda3\lib\site-packages\pymysql\cursors.py", line 170, in execute
    result = self._query(query)
  File "C:\ProgramData\Anaconda3\lib\site-packages\pymysql\cursors.py", line 328, in _query
    conn.query(q)
  File "C:\ProgramData\Anaconda3\lib\site-packages\pymysql\connections.py", line 516, in query
    self._affected_rows = self._read_query_result(unbuffered=unbuffered)
  File "C:\ProgramData\Anaconda3\lib\site-packages\pymysql\connections.py", line 727, in _read_query_result
    result.read()
  File "C:\ProgramData\Anaconda3\lib\site-packages\pymysql\connections.py", line 1066, in read
    first_packet = self.connection._read_packet()
  File "C:\ProgramData\Anaconda3\lib\site-packages\pymysql\connections.py", line 683, in _read_packet
    packet.check_error()
  File "C:\ProgramData\Anaconda3\lib\site-packages\pymysql\protocol.py", line 220, in check_error
    err.raise_mysql_exception(self._data)
  File "C:\ProgramData\Anaconda3\lib\site-packages\pymysql\err.py", line 109, in raise_mysql_exception
    raise errorclass(errno, errval)
pymysql.err.ProgrammingError: (1146, "Table 'xiaoman.comp' doesn't exist")
&5c43012977add014-Traceback (most recent call last):
  File "C:\Users\lenovo\Desktop\小满海关数据爬取\step2.py", line 104, in get_data
    self.write2sql(sql)
  File "C:\Users\lenovo\Desktop\小满海关数据爬取\step2.py", line 228, in write2sql
    cur.execute(sql)
  File "C:\ProgramData\Anaconda3\lib\site-packages\pymysql\cursors.py", line 170, in execute
    result = self._query(query)
  File "C:\ProgramData\Anaconda3\lib\site-packages\pymysql\cursors.py", line 328, in _query
    conn.query(q)
  File "C:\ProgramData\Anaconda3\lib\site-packages\pymysql\connections.py", line 516, in query
    self._affected_rows = self._read_query_result(unbuffered=unbuffered)
  File "C:\ProgramData\Anaconda3\lib\site-packages\pymysql\connections.py", line 727, in _read_query_result
    result.read()
  File "C:\ProgramData\Anaconda3\lib\site-packages\pymysql\connections.py", line 1066, in read
    first_packet = self.connection._read_packet()
  File "C:\ProgramData\Anaconda3\lib\site-packages\pymysql\connections.py", line 683, in _read_packet
    packet.check_error()
  File "C:\ProgramData\Anaconda3\lib\site-packages\pymysql\protocol.py", line 220, in check_error
    err.raise_mysql_exception(self._data)
  File "C:\ProgramData\Anaconda3\lib\site-packages\pymysql\err.py", line 109, in raise_mysql_exception
    raise errorclass(errno, errval)
pymysql.err.ProgrammingError: (1146, "Table 'xiaoman.comp' doesn't exist")
&46bf9d3cf6cb28cb-Traceback (most recent call last):
  File "C:\Users\lenovo\Desktop\小满海关数据爬取\step2.py", line 104, in get_data
    self.write2sql(sql)
  File "C:\Users\lenovo\Desktop\小满海关数据爬取\step2.py", line 228, in write2sql
    cur.execute(sql)
  File "C:\ProgramData\Anaconda3\lib\site-packages\pymysql\cursors.py", line 170, in execute
    result = self._query(query)
  File "C:\ProgramData\Anaconda3\lib\site-packages\pymysql\cursors.py", line 328, in _query
    conn.query(q)
  File "C:\ProgramData\Anaconda3\lib\site-packages\pymysql\connections.py", line 516, in query
    self._affected_rows = self._read_query_result(unbuffered=unbuffered)
  File "C:\ProgramData\Anaconda3\lib\site-packages\pymysql\connections.py", line 727, in _read_query_result
    result.read()
  File "C:\ProgramData\Anaconda3\lib\site-packages\pymysql\connections.py", line 1066, in read
    first_packet = self.connection._read_packet()
  File "C:\ProgramData\Anaconda3\lib\site-packages\pymysql\connections.py", line 683, in _read_packet
    packet.check_error()
  File "C:\ProgramData\Anaconda3\lib\site-packages\pymysql\protocol.py", line 220, in check_error
    err.raise_mysql_exception(self._data)
  File "C:\ProgramData\Anaconda3\lib\site-packages\pymysql\err.py", line 109, in raise_mysql_exception
    raise errorclass(errno, errval)
pymysql.err.ProgrammingError: (1146, "Table 'xiaoman.comp' doesn't exist")
&4388d0d6e1ac77a2-Traceback (most recent call last):
  File "C:\Users\lenovo\Desktop\小满海关数据爬取\step2.py", line 104, in get_data
    self.write2sql(sql)
  File "C:\Users\lenovo\Desktop\小满海关数据爬取\step2.py", line 228, in write2sql
    cur.execute(sql)
  File "C:\ProgramData\Anaconda3\lib\site-packages\pymysql\cursors.py", line 170, in execute
    result = self._query(query)
  File "C:\ProgramData\Anaconda3\lib\site-packages\pymysql\cursors.py", line 328, in _query
    conn.query(q)
  File "C:\ProgramData\Anaconda3\lib\site-packages\pymysql\connections.py", line 516, in query
    self._affected_rows = self._read_query_result(unbuffered=unbuffered)
  File "C:\ProgramData\Anaconda3\lib\site-packages\pymysql\connections.py", line 727, in _read_query_result
    result.read()
  File "C:\ProgramData\Anaconda3\lib\site-packages\pymysql\connections.py", line 1066, in read
    first_packet = self.connection._read_packet()
  File "C:\ProgramData\Anaconda3\lib\site-packages\pymysql\connections.py", line 683, in _read_packet
    packet.check_error()
  File "C:\ProgramData\Anaconda3\lib\site-packages\pymysql\protocol.py", line 220, in check_error
    err.raise_mysql_exception(self._data)
  File "C:\ProgramData\Anaconda3\lib\site-packages\pymysql\err.py", line 109, in raise_mysql_exception
    raise errorclass(errno, errval)
pymysql.err.ProgrammingError: (1146, "Table 'xiaoman.comp' doesn't exist")
&03d34dba9c0edd40-Traceback (most recent call last):
  File "C:\Users\lenovo\Desktop\小满海关数据爬取\step2.py", line 104, in get_data
    self.write2sql(sql)
  File "C:\Users\lenovo\Desktop\小满海关数据爬取\step2.py", line 228, in write2sql
    cur.execute(sql)
  File "C:\ProgramData\Anaconda3\lib\site-packages\pymysql\cursors.py", line 170, in execute
    result = self._query(query)
  File "C:\ProgramData\Anaconda3\lib\site-packages\pymysql\cursors.py", line 328, in _query
    conn.query(q)
  File "C:\ProgramData\Anaconda3\lib\site-packages\pymysql\connections.py", line 516, in query
    self._affected_rows = self._read_query_result(unbuffered=unbuffered)
  File "C:\ProgramData\Anaconda3\lib\site-packages\pymysql\connections.py", line 727, in _read_query_result
    result.read()
  File "C:\ProgramData\Anaconda3\lib\site-packages\pymysql\connections.py", line 1066, in read
    first_packet = self.connection._read_packet()
  File "C:\ProgramData\Anaconda3\lib\site-packages\pymysql\connections.py", line 683, in _read_packet
    packet.check_error()
  File "C:\ProgramData\Anaconda3\lib\site-packages\pymysql\protocol.py", line 220, in check_error
    err.raise_mysql_exception(self._data)
  File "C:\ProgramData\Anaconda3\lib\site-packages\pymysql\err.py", line 109, in raise_mysql_exception
    raise errorclass(errno, errval)
pymysql.err.ProgrammingError: (1146, "Table 'xiaoman.comp' doesn't exist")
&uszi31c032375a2f93900bbd2901e2b9f3d6-Traceback (most recent call last):
  File "C:\Users\lenovo\Desktop\小满海关数据爬取\step2.py", line 104, in get_data
    self.write2sql(sql)
  File "C:\Users\lenovo\Desktop\小满海关数据爬取\step2.py", line 228, in write2sql
    cur.execute(sql)
  File "C:\ProgramData\Anaconda3\lib\site-packages\pymysql\cursors.py", line 170, in execute
    result = self._query(query)
  File "C:\ProgramData\Anaconda3\lib\site-packages\pymysql\cursors.py", line 328, in _query
    conn.query(q)
  File "C:\ProgramData\Anaconda3\lib\site-packages\pymysql\connections.py", line 516, in query
    self._affected_rows = self._read_query_result(unbuffered=unbuffered)
  File "C:\ProgramData\Anaconda3\lib\site-packages\pymysql\connections.py", line 727, in _read_query_result
    result.read()
  File "C:\ProgramData\Anaconda3\lib\site-packages\pymysql\connections.py", line 1066, in read
    first_packet = self.connection._read_packet()
  File "C:\ProgramData\Anaconda3\lib\site-packages\pymysql\connections.py", line 683, in _read_packet
    packet.check_error()
  File "C:\ProgramData\Anaconda3\lib\site-packages\pymysql\protocol.py", line 220, in check_error
    err.raise_mysql_exception(self._data)
  File "C:\ProgramData\Anaconda3\lib\site-packages\pymysql\err.py", line 109, in raise_mysql_exception
    raise errorclass(errno, errval)
pymysql.err.ProgrammingError: (1146, "Table 'xiaoman.comp' doesn't exist")
&5ea1568ee0aa778a-Traceback (most recent call last):
  File "C:\Users\lenovo\Desktop\小满海关数据爬取\step2.py", line 104, in get_data
    self.write2sql(sql)
  File "C:\Users\lenovo\Desktop\小满海关数据爬取\step2.py", line 228, in write2sql
    cur.execute(sql)
  File "C:\ProgramData\Anaconda3\lib\site-packages\pymysql\cursors.py", line 170, in execute
    result = self._query(query)
  File "C:\ProgramData\Anaconda3\lib\site-packages\pymysql\cursors.py", line 328, in _query
    conn.query(q)
  File "C:\ProgramData\Anaconda3\lib\site-packages\pymysql\connections.py", line 516, in query
    self._affected_rows = self._read_query_result(unbuffered=unbuffered)
  File "C:\ProgramData\Anaconda3\lib\site-packages\pymysql\connections.py", line 727, in _read_query_result
    result.read()
  File "C:\ProgramData\Anaconda3\lib\site-packages\pymysql\connections.py", line 1066, in read
    first_packet = self.connection._read_packet()
  File "C:\ProgramData\Anaconda3\lib\site-packages\pymysql\connections.py", line 683, in _read_packet
    packet.check_error()
  File "C:\ProgramData\Anaconda3\lib\site-packages\pymysql\protocol.py", line 220, in check_error
    err.raise_mysql_exception(self._data)
  File "C:\ProgramData\Anaconda3\lib\site-packages\pymysql\err.py", line 109, in raise_mysql_exception
    raise errorclass(errno, errval)
pymysql.err.ProgrammingError: (1146, "Table 'xiaoman.comp' doesn't exist")
&4b5f60ada6a91d2d-Traceback (most recent call last):
  File "C:\Users\lenovo\Desktop\小满海关数据爬取\step2.py", line 104, in get_data
    self.write2sql(sql)
  File "C:\Users\lenovo\Desktop\小满海关数据爬取\step2.py", line 228, in write2sql
    cur.execute(sql)
  File "C:\ProgramData\Anaconda3\lib\site-packages\pymysql\cursors.py", line 170, in execute
    result = self._query(query)
  File "C:\ProgramData\Anaconda3\lib\site-packages\pymysql\cursors.py", line 328, in _query
    conn.query(q)
  File "C:\ProgramData\Anaconda3\lib\site-packages\pymysql\connections.py", line 516, in query
    self._affected_rows = self._read_query_result(unbuffered=unbuffered)
  File "C:\ProgramData\Anaconda3\lib\site-packages\pymysql\connections.py", line 727, in _read_query_result
    result.read()
  File "C:\ProgramData\Anaconda3\lib\site-packages\pymysql\connections.py", line 1066, in read
    first_packet = self.connection._read_packet()
  File "C:\ProgramData\Anaconda3\lib\site-packages\pymysql\connections.py", line 683, in _read_packet
    packet.check_error()
  File "C:\ProgramData\Anaconda3\lib\site-packages\pymysql\protocol.py", line 220, in check_error
    err.raise_mysql_exception(self._data)
  File "C:\ProgramData\Anaconda3\lib\site-packages\pymysql\err.py", line 109, in raise_mysql_exception
    raise errorclass(errno, errval)
pymysql.err.ProgrammingError: (1146, "Table 'xiaoman.comp' doesn't exist")
&f17284c6c4385233-Traceback (most recent call last):
  File "C:\Users\lenovo\Desktop\小满海关数据爬取\step2.py", line 104, in get_data
    self.write2sql(sql)
  File "C:\Users\lenovo\Desktop\小满海关数据爬取\step2.py", line 228, in write2sql
    cur.execute(sql)
  File "C:\ProgramData\Anaconda3\lib\site-packages\pymysql\cursors.py", line 170, in execute
    result = self._query(query)
  File "C:\ProgramData\Anaconda3\lib\site-packages\pymysql\cursors.py", line 328, in _query
    conn.query(q)
  File "C:\ProgramData\Anaconda3\lib\site-packages\pymysql\connections.py", line 516, in query
    self._affected_rows = self._read_query_result(unbuffered=unbuffered)
  File "C:\ProgramData\Anaconda3\lib\site-packages\pymysql\connections.py", line 727, in _read_query_result
    result.read()
  File "C:\ProgramData\Anaconda3\lib\site-packages\pymysql\connections.py", line 1066, in read
    first_packet = self.connection._read_packet()
  File "C:\ProgramData\Anaconda3\lib\site-packages\pymysql\connections.py", line 683, in _read_packet
    packet.check_error()
  File "C:\ProgramData\Anaconda3\lib\site-packages\pymysql\protocol.py", line 220, in check_error
    err.raise_mysql_exception(self._data)
  File "C:\ProgramData\Anaconda3\lib\site-packages\pymysql\err.py", line 109, in raise_mysql_exception
    raise errorclass(errno, errval)
pymysql.err.ProgrammingError: (1146, "Table 'xiaoman.comp' doesn't exist")
&ee11d39ca2718f72-Traceback (most recent call last):
  File "C:\Users\lenovo\Desktop\小满海关数据爬取\step2.py", line 104, in get_data
    self.write2sql(sql)
  File "C:\Users\lenovo\Desktop\小满海关数据爬取\step2.py", line 228, in write2sql
    cur.execute(sql)
  File "C:\ProgramData\Anaconda3\lib\site-packages\pymysql\cursors.py", line 170, in execute
    result = self._query(query)
  File "C:\ProgramData\Anaconda3\lib\site-packages\pymysql\cursors.py", line 328, in _query
    conn.query(q)
  File "C:\ProgramData\Anaconda3\lib\site-packages\pymysql\connections.py", line 516, in query
    self._affected_rows = self._read_query_result(unbuffered=unbuffered)
  File "C:\ProgramData\Anaconda3\lib\site-packages\pymysql\connections.py", line 727, in _read_query_result
    result.read()
  File "C:\ProgramData\Anaconda3\lib\site-packages\pymysql\connections.py", line 1066, in read
    first_packet = self.connection._read_packet()
  File "C:\ProgramData\Anaconda3\lib\site-packages\pymysql\connections.py", line 683, in _read_packet
    packet.check_error()
  File "C:\ProgramData\Anaconda3\lib\site-packages\pymysql\protocol.py", line 220, in check_error
    err.raise_mysql_exception(self._data)
  File "C:\ProgramData\Anaconda3\lib\site-packages\pymysql\err.py", line 109, in raise_mysql_exception
    raise errorclass(errno, errval)
pymysql.err.ProgrammingError: (1146, "Table 'xiaoman.comp' doesn't exist")
&464f894e583e74a5-Traceback (most recent call last):
  File "C:\Users\lenovo\Desktop\小满海关数据爬取\step2.py", line 104, in get_data
    self.write2sql(sql)
  File "C:\Users\lenovo\Desktop\小满海关数据爬取\step2.py", line 228, in write2sql
    cur.execute(sql)
  File "C:\ProgramData\Anaconda3\lib\site-packages\pymysql\cursors.py", line 170, in execute
    result = self._query(query)
  File "C:\ProgramData\Anaconda3\lib\site-packages\pymysql\cursors.py", line 328, in _query
    conn.query(q)
  File "C:\ProgramData\Anaconda3\lib\site-packages\pymysql\connections.py", line 516, in query
    self._affected_rows = self._read_query_result(unbuffered=unbuffered)
  File "C:\ProgramData\Anaconda3\lib\site-packages\pymysql\connections.py", line 727, in _read_query_result
    result.read()
  File "C:\ProgramData\Anaconda3\lib\site-packages\pymysql\connections.py", line 1066, in read
    first_packet = self.connection._read_packet()
  File "C:\ProgramData\Anaconda3\lib\site-packages\pymysql\connections.py", line 683, in _read_packet
    packet.check_error()
  File "C:\ProgramData\Anaconda3\lib\site-packages\pymysql\protocol.py", line 220, in check_error
    err.raise_mysql_exception(self._data)
  File "C:\ProgramData\Anaconda3\lib\site-packages\pymysql\err.py", line 109, in raise_mysql_exception
    raise errorclass(errno, errval)
pymysql.err.ProgrammingError: (1146, "Table 'xiaoman.comp' doesn't exist")
&aa2391c848065a3b-Traceback (most recent call last):
  File "C:\Users\lenovo\Desktop\小满海关数据爬取\step2.py", line 104, in get_data
    self.write2sql(sql)
  File "C:\Users\lenovo\Desktop\小满海关数据爬取\step2.py", line 228, in write2sql
    cur.execute(sql)
  File "C:\ProgramData\Anaconda3\lib\site-packages\pymysql\cursors.py", line 170, in execute
    result = self._query(query)
  File "C:\ProgramData\Anaconda3\lib\site-packages\pymysql\cursors.py", line 328, in _query
    conn.query(q)
  File "C:\ProgramData\Anaconda3\lib\site-packages\pymysql\connections.py", line 516, in query
    self._affected_rows = self._read_query_result(unbuffered=unbuffered)
  File "C:\ProgramData\Anaconda3\lib\site-packages\pymysql\connections.py", line 727, in _read_query_result
    result.read()
  File "C:\ProgramData\Anaconda3\lib\site-packages\pymysql\connections.py", line 1066, in read
    first_packet = self.connection._read_packet()
  File "C:\ProgramData\Anaconda3\lib\site-packages\pymysql\connections.py", line 683, in _read_packet
    packet.check_error()
  File "C:\ProgramData\Anaconda3\lib\site-packages\pymysql\protocol.py", line 220, in check_error
    err.raise_mysql_exception(self._data)
  File "C:\ProgramData\Anaconda3\lib\site-packages\pymysql\err.py", line 109, in raise_mysql_exception
    raise errorclass(errno, errval)
pymysql.err.ProgrammingError: (1146, "Table 'xiaoman.comp' doesn't exist")
&4998b4062ffdc4e6-Traceback (most recent call last):
  File "C:\Users\lenovo\Desktop\小满海关数据爬取\step2.py", line 104, in get_data
    self.write2sql(sql)
  File "C:\Users\lenovo\Desktop\小满海关数据爬取\step2.py", line 228, in write2sql
    cur.execute(sql)
  File "C:\ProgramData\Anaconda3\lib\site-packages\pymysql\cursors.py", line 170, in execute
    result = self._query(query)
  File "C:\ProgramData\Anaconda3\lib\site-packages\pymysql\cursors.py", line 328, in _query
    conn.query(q)
  File "C:\ProgramData\Anaconda3\lib\site-packages\pymysql\connections.py", line 516, in query
    self._affected_rows = self._read_query_result(unbuffered=unbuffered)
  File "C:\ProgramData\Anaconda3\lib\site-packages\pymysql\connections.py", line 727, in _read_query_result
    result.read()
  File "C:\ProgramData\Anaconda3\lib\site-packages\pymysql\connections.py", line 1066, in read
    first_packet = self.connection._read_packet()
  File "C:\ProgramData\Anaconda3\lib\site-packages\pymysql\connections.py", line 683, in _read_packet
    packet.check_error()
  File "C:\ProgramData\Anaconda3\lib\site-packages\pymysql\protocol.py", line 220, in check_error
    err.raise_mysql_exception(self._data)
  File "C:\ProgramData\Anaconda3\lib\site-packages\pymysql\err.py", line 109, in raise_mysql_exception
    raise errorclass(errno, errval)
pymysql.err.ProgrammingError: (1146, "Table 'xiaoman.comp' doesn't exist")
&d730d4bc1b91f1ca-Traceback (most recent call last):
  File "C:\Users\lenovo\Desktop\小满海关数据爬取\step2.py", line 104, in get_data
    self.write2sql(sql)
  File "C:\Users\lenovo\Desktop\小满海关数据爬取\step2.py", line 228, in write2sql
    cur.execute(sql)
  File "C:\ProgramData\Anaconda3\lib\site-packages\pymysql\cursors.py", line 170, in execute
    result = self._query(query)
  File "C:\ProgramData\Anaconda3\lib\site-packages\pymysql\cursors.py", line 328, in _query
    conn.query(q)
  File "C:\ProgramData\Anaconda3\lib\site-packages\pymysql\connections.py", line 516, in query
    self._affected_rows = self._read_query_result(unbuffered=unbuffered)
  File "C:\ProgramData\Anaconda3\lib\site-packages\pymysql\connections.py", line 727, in _read_query_result
    result.read()
  File "C:\ProgramData\Anaconda3\lib\site-packages\pymysql\connections.py", line 1066, in read
    first_packet = self.connection._read_packet()
  File "C:\ProgramData\Anaconda3\lib\site-packages\pymysql\connections.py", line 683, in _read_packet
    packet.check_error()
  File "C:\ProgramData\Anaconda3\lib\site-packages\pymysql\protocol.py", line 220, in check_error
    err.raise_mysql_exception(self._data)
  File "C:\ProgramData\Anaconda3\lib\site-packages\pymysql\err.py", line 109, in raise_mysql_exception
    raise errorclass(errno, errval)
pymysql.err.ProgrammingError: (1146, "Table 'xiaoman.comp' doesn't exist")
&a451c166c4356fff-Traceback (most recent call last):
  File "C:\Users\lenovo\Desktop\小满海关数据爬取\step2.py", line 104, in get_data
    self.write2sql(sql)
  File "C:\Users\lenovo\Desktop\小满海关数据爬取\step2.py", line 228, in write2sql
    cur.execute(sql)
  File "C:\ProgramData\Anaconda3\lib\site-packages\pymysql\cursors.py", line 170, in execute
    result = self._query(query)
  File "C:\ProgramData\Anaconda3\lib\site-packages\pymysql\cursors.py", line 328, in _query
    conn.query(q)
  File "C:\ProgramData\Anaconda3\lib\site-packages\pymysql\connections.py", line 516, in query
    self._affected_rows = self._read_query_result(unbuffered=unbuffered)
  File "C:\ProgramData\Anaconda3\lib\site-packages\pymysql\connections.py", line 727, in _read_query_result
    result.read()
  File "C:\ProgramData\Anaconda3\lib\site-packages\pymysql\connections.py", line 1066, in read
    first_packet = self.connection._read_packet()
  File "C:\ProgramData\Anaconda3\lib\site-packages\pymysql\connections.py", line 683, in _read_packet
    packet.check_error()
  File "C:\ProgramData\Anaconda3\lib\site-packages\pymysql\protocol.py", line 220, in check_error
    err.raise_mysql_exception(self._data)
  File "C:\ProgramData\Anaconda3\lib\site-packages\pymysql\err.py", line 109, in raise_mysql_exception
    raise errorclass(errno, errval)
pymysql.err.ProgrammingError: (1146, "Table 'xiaoman.comp' doesn't exist")
&691a4bd4db969547-Traceback (most recent call last):
  File "C:\Users\lenovo\Desktop\小满海关数据爬取\step2.py", line 104, in get_data
    self.write2sql(sql)
  File "C:\Users\lenovo\Desktop\小满海关数据爬取\step2.py", line 228, in write2sql
    cur.execute(sql)
  File "C:\ProgramData\Anaconda3\lib\site-packages\pymysql\cursors.py", line 170, in execute
    result = self._query(query)
  File "C:\ProgramData\Anaconda3\lib\site-packages\pymysql\cursors.py", line 328, in _query
    conn.query(q)
  File "C:\ProgramData\Anaconda3\lib\site-packages\pymysql\connections.py", line 516, in query
    self._affected_rows = self._read_query_result(unbuffered=unbuffered)
  File "C:\ProgramData\Anaconda3\lib\site-packages\pymysql\connections.py", line 727, in _read_query_result
    result.read()
  File "C:\ProgramData\Anaconda3\lib\site-packages\pymysql\connections.py", line 1066, in read
    first_packet = self.connection._read_packet()
  File "C:\ProgramData\Anaconda3\lib\site-packages\pymysql\connections.py", line 683, in _read_packet
    packet.check_error()
  File "C:\ProgramData\Anaconda3\lib\site-packages\pymysql\protocol.py", line 220, in check_error
    err.raise_mysql_exception(self._data)
  File "C:\ProgramData\Anaconda3\lib\site-packages\pymysql\err.py", line 109, in raise_mysql_exception
    raise errorclass(errno, errval)
pymysql.err.ProgrammingError: (1146, "Table 'xiaoman.comp' doesn't exist")
&a7c881ace1180ca0-Traceback (most recent call last):
  File "C:\Users\lenovo\Desktop\小满海关数据爬取\step2.py", line 104, in get_data
    self.write2sql(sql)
  File "C:\Users\lenovo\Desktop\小满海关数据爬取\step2.py", line 228, in write2sql
    cur.execute(sql)
  File "C:\ProgramData\Anaconda3\lib\site-packages\pymysql\cursors.py", line 170, in execute
    result = self._query(query)
  File "C:\ProgramData\Anaconda3\lib\site-packages\pymysql\cursors.py", line 328, in _query
    conn.query(q)
  File "C:\ProgramData\Anaconda3\lib\site-packages\pymysql\connections.py", line 516, in query
    self._affected_rows = self._read_query_result(unbuffered=unbuffered)
  File "C:\ProgramData\Anaconda3\lib\site-packages\pymysql\connections.py", line 727, in _read_query_result
    result.read()
  File "C:\ProgramData\Anaconda3\lib\site-packages\pymysql\connections.py", line 1066, in read
    first_packet = self.connection._read_packet()
  File "C:\ProgramData\Anaconda3\lib\site-packages\pymysql\connections.py", line 683, in _read_packet
    packet.check_error()
  File "C:\ProgramData\Anaconda3\lib\site-packages\pymysql\protocol.py", line 220, in check_error
    err.raise_mysql_exception(self._data)
  File "C:\ProgramData\Anaconda3\lib\site-packages\pymysql\err.py", line 109, in raise_mysql_exception
    raise errorclass(errno, errval)
pymysql.err.ProgrammingError: (1146, "Table 'xiaoman.comp' doesn't exist")
&2d353c4f3678f168-Traceback (most recent call last):
  File "C:\Users\lenovo\Desktop\小满海关数据爬取\step2.py", line 104, in get_data
    self.write2sql(sql)
  File "C:\Users\lenovo\Desktop\小满海关数据爬取\step2.py", line 228, in write2sql
    cur.execute(sql)
  File "C:\ProgramData\Anaconda3\lib\site-packages\pymysql\cursors.py", line 170, in execute
    result = self._query(query)
  File "C:\ProgramData\Anaconda3\lib\site-packages\pymysql\cursors.py", line 328, in _query
    conn.query(q)
  File "C:\ProgramData\Anaconda3\lib\site-packages\pymysql\connections.py", line 516, in query
    self._affected_rows = self._read_query_result(unbuffered=unbuffered)
  File "C:\ProgramData\Anaconda3\lib\site-packages\pymysql\connections.py", line 727, in _read_query_result
    result.read()
  File "C:\ProgramData\Anaconda3\lib\site-packages\pymysql\connections.py", line 1066, in read
    first_packet = self.connection._read_packet()
  File "C:\ProgramData\Anaconda3\lib\site-packages\pymysql\connections.py", line 683, in _read_packet
    packet.check_error()
  File "C:\ProgramData\Anaconda3\lib\site-packages\pymysql\protocol.py", line 220, in check_error
    err.raise_mysql_exception(self._data)
  File "C:\ProgramData\Anaconda3\lib\site-packages\pymysql\err.py", line 109, in raise_mysql_exception
    raise errorclass(errno, errval)
pymysql.err.ProgrammingError: (1146, "Table 'xiaoman.comp' doesn't exist")
&krzi6595c53b5da9888484832995ca0ce17f-Traceback (most recent call last):
  File "C:\Users\lenovo\Desktop\小满海关数据爬取\step2.py", line 104, in get_data
    self.write2sql(sql)
  File "C:\Users\lenovo\Desktop\小满海关数据爬取\step2.py", line 228, in write2sql
    cur.execute(sql)
  File "C:\ProgramData\Anaconda3\lib\site-packages\pymysql\cursors.py", line 170, in execute
    result = self._query(query)
  File "C:\ProgramData\Anaconda3\lib\site-packages\pymysql\cursors.py", line 328, in _query
    conn.query(q)
  File "C:\ProgramData\Anaconda3\lib\site-packages\pymysql\connections.py", line 516, in query
    self._affected_rows = self._read_query_result(unbuffered=unbuffered)
  File "C:\ProgramData\Anaconda3\lib\site-packages\pymysql\connections.py", line 727, in _read_query_result
    result.read()
  File "C:\ProgramData\Anaconda3\lib\site-packages\pymysql\connections.py", line 1066, in read
    first_packet = self.connection._read_packet()
  File "C:\ProgramData\Anaconda3\lib\site-packages\pymysql\connections.py", line 683, in _read_packet
    packet.check_error()
  File "C:\ProgramData\Anaconda3\lib\site-packages\pymysql\protocol.py", line 220, in check_error
    err.raise_mysql_exception(self._data)
  File "C:\ProgramData\Anaconda3\lib\site-packages\pymysql\err.py", line 109, in raise_mysql_exception
    raise errorclass(errno, errval)
pymysql.err.ProgrammingError: (1146, "Table 'xiaoman.comp' doesn't exist")
&84b76dcf832228c0-Traceback (most recent call last):
  File "C:\Users\lenovo\Desktop\小满海关数据爬取\step2.py", line 104, in get_data
    self.write2sql(sql)
  File "C:\Users\lenovo\Desktop\小满海关数据爬取\step2.py", line 228, in write2sql
    cur.execute(sql)
  File "C:\ProgramData\Anaconda3\lib\site-packages\pymysql\cursors.py", line 170, in execute
    result = self._query(query)
  File "C:\ProgramData\Anaconda3\lib\site-packages\pymysql\cursors.py", line 328, in _query
    conn.query(q)
  File "C:\ProgramData\Anaconda3\lib\site-packages\pymysql\connections.py", line 516, in query
    self._affected_rows = self._read_query_result(unbuffered=unbuffered)
  File "C:\ProgramData\Anaconda3\lib\site-packages\pymysql\connections.py", line 727, in _read_query_result
    result.read()
  File "C:\ProgramData\Anaconda3\lib\site-packages\pymysql\connections.py", line 1066, in read
    first_packet = self.connection._read_packet()
  File "C:\ProgramData\Anaconda3\lib\site-packages\pymysql\connections.py", line 683, in _read_packet
    packet.check_error()
  File "C:\ProgramData\Anaconda3\lib\site-packages\pymysql\protocol.py", line 220, in check_error
    err.raise_mysql_exception(self._data)
  File "C:\ProgramData\Anaconda3\lib\site-packages\pymysql\err.py", line 109, in raise_mysql_exception
    raise errorclass(errno, errval)
pymysql.err.ProgrammingError: (1146, "Table 'xiaoman.comp' doesn't exist")
&b72152580c2ffa5e-Traceback (most recent call last):
  File "C:\Users\lenovo\Desktop\小满海关数据爬取\step2.py", line 104, in get_data
    self.write2sql(sql)
  File "C:\Users\lenovo\Desktop\小满海关数据爬取\step2.py", line 228, in write2sql
    cur.execute(sql)
  File "C:\ProgramData\Anaconda3\lib\site-packages\pymysql\cursors.py", line 170, in execute
    result = self._query(query)
  File "C:\ProgramData\Anaconda3\lib\site-packages\pymysql\cursors.py", line 328, in _query
    conn.query(q)
  File "C:\ProgramData\Anaconda3\lib\site-packages\pymysql\connections.py", line 516, in query
    self._affected_rows = self._read_query_result(unbuffered=unbuffered)
  File "C:\ProgramData\Anaconda3\lib\site-packages\pymysql\connections.py", line 727, in _read_query_result
    result.read()
  File "C:\ProgramData\Anaconda3\lib\site-packages\pymysql\connections.py", line 1066, in read
    first_packet = self.connection._read_packet()
  File "C:\ProgramData\Anaconda3\lib\site-packages\pymysql\connections.py", line 683, in _read_packet
    packet.check_error()
  File "C:\ProgramData\Anaconda3\lib\site-packages\pymysql\protocol.py", line 220, in check_error
    err.raise_mysql_exception(self._data)
  File "C:\ProgramData\Anaconda3\lib\site-packages\pymysql\err.py", line 109, in raise_mysql_exception
    raise errorclass(errno, errval)
pymysql.err.ProgrammingError: (1146, "Table 'xiaoman.comp' doesn't exist")
&91431fa28b841202-Traceback (most recent call last):
  File "C:\Users\lenovo\Desktop\小满海关数据爬取\step2.py", line 104, in get_data
    self.write2sql(sql)
  File "C:\Users\lenovo\Desktop\小满海关数据爬取\step2.py", line 228, in write2sql
    cur.execute(sql)
  File "C:\ProgramData\Anaconda3\lib\site-packages\pymysql\cursors.py", line 170, in execute
    result = self._query(query)
  File "C:\ProgramData\Anaconda3\lib\site-packages\pymysql\cursors.py", line 328, in _query
    conn.query(q)
  File "C:\ProgramData\Anaconda3\lib\site-packages\pymysql\connections.py", line 516, in query
    self._affected_rows = self._read_query_result(unbuffered=unbuffered)
  File "C:\ProgramData\Anaconda3\lib\site-packages\pymysql\connections.py", line 727, in _read_query_result
    result.read()
  File "C:\ProgramData\Anaconda3\lib\site-packages\pymysql\connections.py", line 1066, in read
    first_packet = self.connection._read_packet()
  File "C:\ProgramData\Anaconda3\lib\site-packages\pymysql\connections.py", line 683, in _read_packet
    packet.check_error()
  File "C:\ProgramData\Anaconda3\lib\site-packages\pymysql\protocol.py", line 220, in check_error
    err.raise_mysql_exception(self._data)
  File "C:\ProgramData\Anaconda3\lib\site-packages\pymysql\err.py", line 109, in raise_mysql_exception
    raise errorclass(errno, errval)
pymysql.err.ProgrammingError: (1146, "Table 'xiaoman.comp' doesn't exist")
&06facbc379c481ab-Traceback (most recent call last):
  File "C:\Users\lenovo\Desktop\小满海关数据爬取\step2.py", line 104, in get_data
    self.write2sql(sql)
  File "C:\Users\lenovo\Desktop\小满海关数据爬取\step2.py", line 228, in write2sql
    cur.execute(sql)
  File "C:\ProgramData\Anaconda3\lib\site-packages\pymysql\cursors.py", line 170, in execute
    result = self._query(query)
  File "C:\ProgramData\Anaconda3\lib\site-packages\pymysql\cursors.py", line 328, in _query
    conn.query(q)
  File "C:\ProgramData\Anaconda3\lib\site-packages\pymysql\connections.py", line 516, in query
    self._affected_rows = self._read_query_result(unbuffered=unbuffered)
  File "C:\ProgramData\Anaconda3\lib\site-packages\pymysql\connections.py", line 727, in _read_query_result
    result.read()
  File "C:\ProgramData\Anaconda3\lib\site-packages\pymysql\connections.py", line 1066, in read
    first_packet = self.connection._read_packet()
  File "C:\ProgramData\Anaconda3\lib\site-packages\pymysql\connections.py", line 683, in _read_packet
    packet.check_error()
  File "C:\ProgramData\Anaconda3\lib\site-packages\pymysql\protocol.py", line 220, in check_error
    err.raise_mysql_exception(self._data)
  File "C:\ProgramData\Anaconda3\lib\site-packages\pymysql\err.py", line 109, in raise_mysql_exception
    raise errorclass(errno, errval)
pymysql.err.ProgrammingError: (1146, "Table 'xiaoman.comp' doesn't exist")
&