b87ca57182256c70-Traceback (most recent call last):
  File "C:\Users\lenovo\Desktop\小满海关数据爬取\step2.py", line 104, in get_data
    self.write2sql(sql)
  File "C:\Users\lenovo\Desktop\小满海关数据爬取\step2.py", line 228, in write2sql
    cur.execute(sql)
  File "D:\ProgramData\Anaconda3\lib\site-packages\pymysql\cursors.py", line 170, in execute
    result = self._query(query)
  File "D:\ProgramData\Anaconda3\lib\site-packages\pymysql\cursors.py", line 328, in _query
    conn.query(q)
  File "D:\ProgramData\Anaconda3\lib\site-packages\pymysql\connections.py", line 516, in query
    self._affected_rows = self._read_query_result(unbuffered=unbuffered)
  File "D:\ProgramData\Anaconda3\lib\site-packages\pymysql\connections.py", line 727, in _read_query_result
    result.read()
  File "D:\ProgramData\Anaconda3\lib\site-packages\pymysql\connections.py", line 1066, in read
    first_packet = self.connection._read_packet()
  File "D:\ProgramData\Anaconda3\lib\site-packages\pymysql\connections.py", line 683, in _read_packet
    packet.check_error()
  File "D:\ProgramData\Anaconda3\lib\site-packages\pymysql\protocol.py", line 220, in check_error
    err.raise_mysql_exception(self._data)
  File "D:\ProgramData\Anaconda3\lib\site-packages\pymysql\err.py", line 109, in raise_mysql_exception
    raise errorclass(errno, errval)
pymysql.err.ProgrammingError: (1146, "Table 'xiaoman.comp' doesn't exist")
&e62c4b37f2034fba-Traceback (most recent call last):
  File "C:\Users\lenovo\Desktop\小满海关数据爬取\step2.py", line 104, in get_data
    self.write2sql(sql)
  File "C:\Users\lenovo\Desktop\小满海关数据爬取\step2.py", line 228, in write2sql
    cur.execute(sql)
  File "D:\ProgramData\Anaconda3\lib\site-packages\pymysql\cursors.py", line 170, in execute
    result = self._query(query)
  File "D:\ProgramData\Anaconda3\lib\site-packages\pymysql\cursors.py", line 328, in _query
    conn.query(q)
  File "D:\ProgramData\Anaconda3\lib\site-packages\pymysql\connections.py", line 516, in query
    self._affected_rows = self._read_query_result(unbuffered=unbuffered)
  File "D:\ProgramData\Anaconda3\lib\site-packages\pymysql\connections.py", line 727, in _read_query_result
    result.read()
  File "D:\ProgramData\Anaconda3\lib\site-packages\pymysql\connections.py", line 1066, in read
    first_packet = self.connection._read_packet()
  File "D:\ProgramData\Anaconda3\lib\site-packages\pymysql\connections.py", line 683, in _read_packet
    packet.check_error()
  File "D:\ProgramData\Anaconda3\lib\site-packages\pymysql\protocol.py", line 220, in check_error
    err.raise_mysql_exception(self._data)
  File "D:\ProgramData\Anaconda3\lib\site-packages\pymysql\err.py", line 109, in raise_mysql_exception
    raise errorclass(errno, errval)
pymysql.err.ProgrammingError: (1146, "Table 'xiaoman.comp' doesn't exist")
&988f036564abe57b-Traceback (most recent call last):
  File "C:\Users\lenovo\Desktop\小满海关数据爬取\step2.py", line 104, in get_data
    self.write2sql(sql)
  File "C:\Users\lenovo\Desktop\小满海关数据爬取\step2.py", line 228, in write2sql
    cur.execute(sql)
  File "D:\ProgramData\Anaconda3\lib\site-packages\pymysql\cursors.py", line 170, in execute
    result = self._query(query)
  File "D:\ProgramData\Anaconda3\lib\site-packages\pymysql\cursors.py", line 328, in _query
    conn.query(q)
  File "D:\ProgramData\Anaconda3\lib\site-packages\pymysql\connections.py", line 516, in query
    self._affected_rows = self._read_query_result(unbuffered=unbuffered)
  File "D:\ProgramData\Anaconda3\lib\site-packages\pymysql\connections.py", line 727, in _read_query_result
    result.read()
  File "D:\ProgramData\Anaconda3\lib\site-packages\pymysql\connections.py", line 1066, in read
    first_packet = self.connection._read_packet()
  File "D:\ProgramData\Anaconda3\lib\site-packages\pymysql\connections.py", line 683, in _read_packet
    packet.check_error()
  File "D:\ProgramData\Anaconda3\lib\site-packages\pymysql\protocol.py", line 220, in check_error
    err.raise_mysql_exception(self._data)
  File "D:\ProgramData\Anaconda3\lib\site-packages\pymysql\err.py", line 109, in raise_mysql_exception
    raise errorclass(errno, errval)
pymysql.err.ProgrammingError: (1146, "Table 'xiaoman.comp' doesn't exist")
&be3144b0735fe2fe-Traceback (most recent call last):
  File "C:\Users\lenovo\Desktop\小满海关数据爬取\step2.py", line 104, in get_data
    self.write2sql(sql)
  File "C:\Users\lenovo\Desktop\小满海关数据爬取\step2.py", line 228, in write2sql
    cur.execute(sql)
  File "D:\ProgramData\Anaconda3\lib\site-packages\pymysql\cursors.py", line 170, in execute
    result = self._query(query)
  File "D:\ProgramData\Anaconda3\lib\site-packages\pymysql\cursors.py", line 328, in _query
    conn.query(q)
  File "D:\ProgramData\Anaconda3\lib\site-packages\pymysql\connections.py", line 516, in query
    self._affected_rows = self._read_query_result(unbuffered=unbuffered)
  File "D:\ProgramData\Anaconda3\lib\site-packages\pymysql\connections.py", line 727, in _read_query_result
    result.read()
  File "D:\ProgramData\Anaconda3\lib\site-packages\pymysql\connections.py", line 1066, in read
    first_packet = self.connection._read_packet()
  File "D:\ProgramData\Anaconda3\lib\site-packages\pymysql\connections.py", line 683, in _read_packet
    packet.check_error()
  File "D:\ProgramData\Anaconda3\lib\site-packages\pymysql\protocol.py", line 220, in check_error
    err.raise_mysql_exception(self._data)
  File "D:\ProgramData\Anaconda3\lib\site-packages\pymysql\err.py", line 109, in raise_mysql_exception
    raise errorclass(errno, errval)
pymysql.err.ProgrammingError: (1146, "Table 'xiaoman.comp' doesn't exist")
&7f56eb6c44f9d6e2-Traceback (most recent call last):
  File "C:\Users\lenovo\Desktop\小满海关数据爬取\step2.py", line 104, in get_data
    self.write2sql(sql)
  File "C:\Users\lenovo\Desktop\小满海关数据爬取\step2.py", line 228, in write2sql
    cur.execute(sql)
  File "D:\ProgramData\Anaconda3\lib\site-packages\pymysql\cursors.py", line 170, in execute
    result = self._query(query)
  File "D:\ProgramData\Anaconda3\lib\site-packages\pymysql\cursors.py", line 328, in _query
    conn.query(q)
  File "D:\ProgramData\Anaconda3\lib\site-packages\pymysql\connections.py", line 516, in query
    self._affected_rows = self._read_query_result(unbuffered=unbuffered)
  File "D:\ProgramData\Anaconda3\lib\site-packages\pymysql\connections.py", line 727, in _read_query_result
    result.read()
  File "D:\ProgramData\Anaconda3\lib\site-packages\pymysql\connections.py", line 1066, in read
    first_packet = self.connection._read_packet()
  File "D:\ProgramData\Anaconda3\lib\site-packages\pymysql\connections.py", line 683, in _read_packet
    packet.check_error()
  File "D:\ProgramData\Anaconda3\lib\site-packages\pymysql\protocol.py", line 220, in check_error
    err.raise_mysql_exception(self._data)
  File "D:\ProgramData\Anaconda3\lib\site-packages\pymysql\err.py", line 109, in raise_mysql_exception
    raise errorclass(errno, errval)
pymysql.err.ProgrammingError: (1146, "Table 'xiaoman.comp' doesn't exist")
&ee155e1591e2680f-Traceback (most recent call last):
  File "C:\Users\lenovo\Desktop\小满海关数据爬取\step2.py", line 104, in get_data
    self.write2sql(sql)
  File "C:\Users\lenovo\Desktop\小满海关数据爬取\step2.py", line 228, in write2sql
    cur.execute(sql)
  File "D:\ProgramData\Anaconda3\lib\site-packages\pymysql\cursors.py", line 170, in execute
    result = self._query(query)
  File "D:\ProgramData\Anaconda3\lib\site-packages\pymysql\cursors.py", line 328, in _query
    conn.query(q)
  File "D:\ProgramData\Anaconda3\lib\site-packages\pymysql\connections.py", line 516, in query
    self._affected_rows = self._read_query_result(unbuffered=unbuffered)
  File "D:\ProgramData\Anaconda3\lib\site-packages\pymysql\connections.py", line 727, in _read_query_result
    result.read()
  File "D:\ProgramData\Anaconda3\lib\site-packages\pymysql\connections.py", line 1066, in read
    first_packet = self.connection._read_packet()
  File "D:\ProgramData\Anaconda3\lib\site-packages\pymysql\connections.py", line 683, in _read_packet
    packet.check_error()
  File "D:\ProgramData\Anaconda3\lib\site-packages\pymysql\protocol.py", line 220, in check_error
    err.raise_mysql_exception(self._data)
  File "D:\ProgramData\Anaconda3\lib\site-packages\pymysql\err.py", line 109, in raise_mysql_exception
    raise errorclass(errno, errval)
pymysql.err.ProgrammingError: (1146, "Table 'xiaoman.comp' doesn't exist")
&c7ccdd97ac02ffcb-Traceback (most recent call last):
  File "C:\Users\lenovo\Desktop\小满海关数据爬取\step2.py", line 104, in get_data
    self.write2sql(sql)
  File "C:\Users\lenovo\Desktop\小满海关数据爬取\step2.py", line 228, in write2sql
    cur.execute(sql)
  File "D:\ProgramData\Anaconda3\lib\site-packages\pymysql\cursors.py", line 170, in execute
    result = self._query(query)
  File "D:\ProgramData\Anaconda3\lib\site-packages\pymysql\cursors.py", line 328, in _query
    conn.query(q)
  File "D:\ProgramData\Anaconda3\lib\site-packages\pymysql\connections.py", line 516, in query
    self._affected_rows = self._read_query_result(unbuffered=unbuffered)
  File "D:\ProgramData\Anaconda3\lib\site-packages\pymysql\connections.py", line 727, in _read_query_result
    result.read()
  File "D:\ProgramData\Anaconda3\lib\site-packages\pymysql\connections.py", line 1066, in read
    first_packet = self.connection._read_packet()
  File "D:\ProgramData\Anaconda3\lib\site-packages\pymysql\connections.py", line 683, in _read_packet
    packet.check_error()
  File "D:\ProgramData\Anaconda3\lib\site-packages\pymysql\protocol.py", line 220, in check_error
    err.raise_mysql_exception(self._data)
  File "D:\ProgramData\Anaconda3\lib\site-packages\pymysql\err.py", line 109, in raise_mysql_exception
    raise errorclass(errno, errval)
pymysql.err.ProgrammingError: (1146, "Table 'xiaoman.comp' doesn't exist")
&uszi77322b80000e35d0a3f5dcf7471e56e3-Traceback (most recent call last):
  File "C:\Users\lenovo\Desktop\小满海关数据爬取\step2.py", line 104, in get_data
    self.write2sql(sql)
  File "C:\Users\lenovo\Desktop\小满海关数据爬取\step2.py", line 228, in write2sql
    cur.execute(sql)
  File "D:\ProgramData\Anaconda3\lib\site-packages\pymysql\cursors.py", line 170, in execute
    result = self._query(query)
  File "D:\ProgramData\Anaconda3\lib\site-packages\pymysql\cursors.py", line 328, in _query
    conn.query(q)
  File "D:\ProgramData\Anaconda3\lib\site-packages\pymysql\connections.py", line 516, in query
    self._affected_rows = self._read_query_result(unbuffered=unbuffered)
  File "D:\ProgramData\Anaconda3\lib\site-packages\pymysql\connections.py", line 727, in _read_query_result
    result.read()
  File "D:\ProgramData\Anaconda3\lib\site-packages\pymysql\connections.py", line 1066, in read
    first_packet = self.connection._read_packet()
  File "D:\ProgramData\Anaconda3\lib\site-packages\pymysql\connections.py", line 683, in _read_packet
    packet.check_error()
  File "D:\ProgramData\Anaconda3\lib\site-packages\pymysql\protocol.py", line 220, in check_error
    err.raise_mysql_exception(self._data)
  File "D:\ProgramData\Anaconda3\lib\site-packages\pymysql\err.py", line 109, in raise_mysql_exception
    raise errorclass(errno, errval)
pymysql.err.ProgrammingError: (1146, "Table 'xiaoman.comp' doesn't exist")
&12f0f5c1398e45e2-Traceback (most recent call last):
  File "C:\Users\lenovo\Desktop\小满海关数据爬取\step2.py", line 104, in get_data
    self.write2sql(sql)
  File "C:\Users\lenovo\Desktop\小满海关数据爬取\step2.py", line 228, in write2sql
    cur.execute(sql)
  File "D:\ProgramData\Anaconda3\lib\site-packages\pymysql\cursors.py", line 170, in execute
    result = self._query(query)
  File "D:\ProgramData\Anaconda3\lib\site-packages\pymysql\cursors.py", line 328, in _query
    conn.query(q)
  File "D:\ProgramData\Anaconda3\lib\site-packages\pymysql\connections.py", line 516, in query
    self._affected_rows = self._read_query_result(unbuffered=unbuffered)
  File "D:\ProgramData\Anaconda3\lib\site-packages\pymysql\connections.py", line 727, in _read_query_result
    result.read()
  File "D:\ProgramData\Anaconda3\lib\site-packages\pymysql\connections.py", line 1066, in read
    first_packet = self.connection._read_packet()
  File "D:\ProgramData\Anaconda3\lib\site-packages\pymysql\connections.py", line 683, in _read_packet
    packet.check_error()
  File "D:\ProgramData\Anaconda3\lib\site-packages\pymysql\protocol.py", line 220, in check_error
    err.raise_mysql_exception(self._data)
  File "D:\ProgramData\Anaconda3\lib\site-packages\pymysql\err.py", line 109, in raise_mysql_exception
    raise errorclass(errno, errval)
pymysql.err.ProgrammingError: (1146, "Table 'xiaoman.comp' doesn't exist")
&c879aa7c1ddab5a6-Traceback (most recent call last):
  File "C:\Users\lenovo\Desktop\小满海关数据爬取\step2.py", line 104, in get_data
    self.write2sql(sql)
  File "C:\Users\lenovo\Desktop\小满海关数据爬取\step2.py", line 228, in write2sql
    cur.execute(sql)
  File "D:\ProgramData\Anaconda3\lib\site-packages\pymysql\cursors.py", line 170, in execute
    result = self._query(query)
  File "D:\ProgramData\Anaconda3\lib\site-packages\pymysql\cursors.py", line 328, in _query
    conn.query(q)
  File "D:\ProgramData\Anaconda3\lib\site-packages\pymysql\connections.py", line 516, in query
    self._affected_rows = self._read_query_result(unbuffered=unbuffered)
  File "D:\ProgramData\Anaconda3\lib\site-packages\pymysql\connections.py", line 727, in _read_query_result
    result.read()
  File "D:\ProgramData\Anaconda3\lib\site-packages\pymysql\connections.py", line 1066, in read
    first_packet = self.connection._read_packet()
  File "D:\ProgramData\Anaconda3\lib\site-packages\pymysql\connections.py", line 683, in _read_packet
    packet.check_error()
  File "D:\ProgramData\Anaconda3\lib\site-packages\pymysql\protocol.py", line 220, in check_error
    err.raise_mysql_exception(self._data)
  File "D:\ProgramData\Anaconda3\lib\site-packages\pymysql\err.py", line 109, in raise_mysql_exception
    raise errorclass(errno, errval)
pymysql.err.ProgrammingError: (1146, "Table 'xiaoman.comp' doesn't exist")
&ce755e967b3d5a52-Traceback (most recent call last):
  File "C:\Users\lenovo\Desktop\小满海关数据爬取\step2.py", line 104, in get_data
    self.write2sql(sql)
  File "C:\Users\lenovo\Desktop\小满海关数据爬取\step2.py", line 228, in write2sql
    cur.execute(sql)
  File "D:\ProgramData\Anaconda3\lib\site-packages\pymysql\cursors.py", line 170, in execute
    result = self._query(query)
  File "D:\ProgramData\Anaconda3\lib\site-packages\pymysql\cursors.py", line 328, in _query
    conn.query(q)
  File "D:\ProgramData\Anaconda3\lib\site-packages\pymysql\connections.py", line 516, in query
    self._affected_rows = self._read_query_result(unbuffered=unbuffered)
  File "D:\ProgramData\Anaconda3\lib\site-packages\pymysql\connections.py", line 727, in _read_query_result
    result.read()
  File "D:\ProgramData\Anaconda3\lib\site-packages\pymysql\connections.py", line 1066, in read
    first_packet = self.connection._read_packet()
  File "D:\ProgramData\Anaconda3\lib\site-packages\pymysql\connections.py", line 683, in _read_packet
    packet.check_error()
  File "D:\ProgramData\Anaconda3\lib\site-packages\pymysql\protocol.py", line 220, in check_error
    err.raise_mysql_exception(self._data)
  File "D:\ProgramData\Anaconda3\lib\site-packages\pymysql\err.py", line 109, in raise_mysql_exception
    raise errorclass(errno, errval)
pymysql.err.ProgrammingError: (1146, "Table 'xiaoman.comp' doesn't exist")
&uszicccd0afaf0c1119f276c78111c356d96-Traceback (most recent call last):
  File "C:\Users\lenovo\Desktop\小满海关数据爬取\step2.py", line 104, in get_data
    self.write2sql(sql)
  File "C:\Users\lenovo\Desktop\小满海关数据爬取\step2.py", line 228, in write2sql
    cur.execute(sql)
  File "D:\ProgramData\Anaconda3\lib\site-packages\pymysql\cursors.py", line 170, in execute
    result = self._query(query)
  File "D:\ProgramData\Anaconda3\lib\site-packages\pymysql\cursors.py", line 328, in _query
    conn.query(q)
  File "D:\ProgramData\Anaconda3\lib\site-packages\pymysql\connections.py", line 516, in query
    self._affected_rows = self._read_query_result(unbuffered=unbuffered)
  File "D:\ProgramData\Anaconda3\lib\site-packages\pymysql\connections.py", line 727, in _read_query_result
    result.read()
  File "D:\ProgramData\Anaconda3\lib\site-packages\pymysql\connections.py", line 1066, in read
    first_packet = self.connection._read_packet()
  File "D:\ProgramData\Anaconda3\lib\site-packages\pymysql\connections.py", line 683, in _read_packet
    packet.check_error()
  File "D:\ProgramData\Anaconda3\lib\site-packages\pymysql\protocol.py", line 220, in check_error
    err.raise_mysql_exception(self._data)
  File "D:\ProgramData\Anaconda3\lib\site-packages\pymysql\err.py", line 109, in raise_mysql_exception
    raise errorclass(errno, errval)
pymysql.err.ProgrammingError: (1146, "Table 'xiaoman.comp' doesn't exist")
&6cd45696894f693c-Traceback (most recent call last):
  File "C:\Users\lenovo\Desktop\小满海关数据爬取\step2.py", line 104, in get_data
    self.write2sql(sql)
  File "C:\Users\lenovo\Desktop\小满海关数据爬取\step2.py", line 228, in write2sql
    cur.execute(sql)
  File "D:\ProgramData\Anaconda3\lib\site-packages\pymysql\cursors.py", line 170, in execute
    result = self._query(query)
  File "D:\ProgramData\Anaconda3\lib\site-packages\pymysql\cursors.py", line 328, in _query
    conn.query(q)
  File "D:\ProgramData\Anaconda3\lib\site-packages\pymysql\connections.py", line 516, in query
    self._affected_rows = self._read_query_result(unbuffered=unbuffered)
  File "D:\ProgramData\Anaconda3\lib\site-packages\pymysql\connections.py", line 727, in _read_query_result
    result.read()
  File "D:\ProgramData\Anaconda3\lib\site-packages\pymysql\connections.py", line 1066, in read
    first_packet = self.connection._read_packet()
  File "D:\ProgramData\Anaconda3\lib\site-packages\pymysql\connections.py", line 683, in _read_packet
    packet.check_error()
  File "D:\ProgramData\Anaconda3\lib\site-packages\pymysql\protocol.py", line 220, in check_error
    err.raise_mysql_exception(self._data)
  File "D:\ProgramData\Anaconda3\lib\site-packages\pymysql\err.py", line 109, in raise_mysql_exception
    raise errorclass(errno, errval)
pymysql.err.ProgrammingError: (1146, "Table 'xiaoman.comp' doesn't exist")
&17f1b8d44114011a-Traceback (most recent call last):
  File "C:\Users\lenovo\Desktop\小满海关数据爬取\step2.py", line 104, in get_data
    self.write2sql(sql)
  File "C:\Users\lenovo\Desktop\小满海关数据爬取\step2.py", line 228, in write2sql
    cur.execute(sql)
  File "D:\ProgramData\Anaconda3\lib\site-packages\pymysql\cursors.py", line 170, in execute
    result = self._query(query)
  File "D:\ProgramData\Anaconda3\lib\site-packages\pymysql\cursors.py", line 328, in _query
    conn.query(q)
  File "D:\ProgramData\Anaconda3\lib\site-packages\pymysql\connections.py", line 516, in query
    self._affected_rows = self._read_query_result(unbuffered=unbuffered)
  File "D:\ProgramData\Anaconda3\lib\site-packages\pymysql\connections.py", line 727, in _read_query_result
    result.read()
  File "D:\ProgramData\Anaconda3\lib\site-packages\pymysql\connections.py", line 1066, in read
    first_packet = self.connection._read_packet()
  File "D:\ProgramData\Anaconda3\lib\site-packages\pymysql\connections.py", line 683, in _read_packet
    packet.check_error()
  File "D:\ProgramData\Anaconda3\lib\site-packages\pymysql\protocol.py", line 220, in check_error
    err.raise_mysql_exception(self._data)
  File "D:\ProgramData\Anaconda3\lib\site-packages\pymysql\err.py", line 109, in raise_mysql_exception
    raise errorclass(errno, errval)
pymysql.err.ProgrammingError: (1146, "Table 'xiaoman.comp' doesn't exist")
&9b49010fa2a33623-Traceback (most recent call last):
  File "C:\Users\lenovo\Desktop\小满海关数据爬取\step2.py", line 104, in get_data
    self.write2sql(sql)
  File "C:\Users\lenovo\Desktop\小满海关数据爬取\step2.py", line 228, in write2sql
    cur.execute(sql)
  File "D:\ProgramData\Anaconda3\lib\site-packages\pymysql\cursors.py", line 170, in execute
    result = self._query(query)
  File "D:\ProgramData\Anaconda3\lib\site-packages\pymysql\cursors.py", line 328, in _query
    conn.query(q)
  File "D:\ProgramData\Anaconda3\lib\site-packages\pymysql\connections.py", line 516, in query
    self._affected_rows = self._read_query_result(unbuffered=unbuffered)
  File "D:\ProgramData\Anaconda3\lib\site-packages\pymysql\connections.py", line 727, in _read_query_result
    result.read()
  File "D:\ProgramData\Anaconda3\lib\site-packages\pymysql\connections.py", line 1066, in read
    first_packet = self.connection._read_packet()
  File "D:\ProgramData\Anaconda3\lib\site-packages\pymysql\connections.py", line 683, in _read_packet
    packet.check_error()
  File "D:\ProgramData\Anaconda3\lib\site-packages\pymysql\protocol.py", line 220, in check_error
    err.raise_mysql_exception(self._data)
  File "D:\ProgramData\Anaconda3\lib\site-packages\pymysql\err.py", line 109, in raise_mysql_exception
    raise errorclass(errno, errval)
pymysql.err.ProgrammingError: (1146, "Table 'xiaoman.comp' doesn't exist")
&bd02b8199ae40282-Traceback (most recent call last):
  File "C:\Users\lenovo\Desktop\小满海关数据爬取\step2.py", line 104, in get_data
    self.write2sql(sql)
  File "C:\Users\lenovo\Desktop\小满海关数据爬取\step2.py", line 228, in write2sql
    cur.execute(sql)
  File "D:\ProgramData\Anaconda3\lib\site-packages\pymysql\cursors.py", line 170, in execute
    result = self._query(query)
  File "D:\ProgramData\Anaconda3\lib\site-packages\pymysql\cursors.py", line 328, in _query
    conn.query(q)
  File "D:\ProgramData\Anaconda3\lib\site-packages\pymysql\connections.py", line 516, in query
    self._affected_rows = self._read_query_result(unbuffered=unbuffered)
  File "D:\ProgramData\Anaconda3\lib\site-packages\pymysql\connections.py", line 727, in _read_query_result
    result.read()
  File "D:\ProgramData\Anaconda3\lib\site-packages\pymysql\connections.py", line 1066, in read
    first_packet = self.connection._read_packet()
  File "D:\ProgramData\Anaconda3\lib\site-packages\pymysql\connections.py", line 683, in _read_packet
    packet.check_error()
  File "D:\ProgramData\Anaconda3\lib\site-packages\pymysql\protocol.py", line 220, in check_error
    err.raise_mysql_exception(self._data)
  File "D:\ProgramData\Anaconda3\lib\site-packages\pymysql\err.py", line 109, in raise_mysql_exception
    raise errorclass(errno, errval)
pymysql.err.ProgrammingError: (1146, "Table 'xiaoman.comp' doesn't exist")
&16bbf29cdd0d8c21-Traceback (most recent call last):
  File "C:\Users\lenovo\Desktop\小满海关数据爬取\step2.py", line 104, in get_data
    self.write2sql(sql)
  File "C:\Users\lenovo\Desktop\小满海关数据爬取\step2.py", line 228, in write2sql
    cur.execute(sql)
  File "D:\ProgramData\Anaconda3\lib\site-packages\pymysql\cursors.py", line 170, in execute
    result = self._query(query)
  File "D:\ProgramData\Anaconda3\lib\site-packages\pymysql\cursors.py", line 328, in _query
    conn.query(q)
  File "D:\ProgramData\Anaconda3\lib\site-packages\pymysql\connections.py", line 516, in query
    self._affected_rows = self._read_query_result(unbuffered=unbuffered)
  File "D:\ProgramData\Anaconda3\lib\site-packages\pymysql\connections.py", line 727, in _read_query_result
    result.read()
  File "D:\ProgramData\Anaconda3\lib\site-packages\pymysql\connections.py", line 1066, in read
    first_packet = self.connection._read_packet()
  File "D:\ProgramData\Anaconda3\lib\site-packages\pymysql\connections.py", line 683, in _read_packet
    packet.check_error()
  File "D:\ProgramData\Anaconda3\lib\site-packages\pymysql\protocol.py", line 220, in check_error
    err.raise_mysql_exception(self._data)
  File "D:\ProgramData\Anaconda3\lib\site-packages\pymysql\err.py", line 109, in raise_mysql_exception
    raise errorclass(errno, errval)
pymysql.err.ProgrammingError: (1146, "Table 'xiaoman.comp' doesn't exist")
&c274681f798bb0c1-Traceback (most recent call last):
  File "C:\Users\lenovo\Desktop\小满海关数据爬取\step2.py", line 104, in get_data
    self.write2sql(sql)
  File "C:\Users\lenovo\Desktop\小满海关数据爬取\step2.py", line 228, in write2sql
    cur.execute(sql)
  File "D:\ProgramData\Anaconda3\lib\site-packages\pymysql\cursors.py", line 170, in execute
    result = self._query(query)
  File "D:\ProgramData\Anaconda3\lib\site-packages\pymysql\cursors.py", line 328, in _query
    conn.query(q)
  File "D:\ProgramData\Anaconda3\lib\site-packages\pymysql\connections.py", line 516, in query
    self._affected_rows = self._read_query_result(unbuffered=unbuffered)
  File "D:\ProgramData\Anaconda3\lib\site-packages\pymysql\connections.py", line 727, in _read_query_result
    result.read()
  File "D:\ProgramData\Anaconda3\lib\site-packages\pymysql\connections.py", line 1066, in read
    first_packet = self.connection._read_packet()
  File "D:\ProgramData\Anaconda3\lib\site-packages\pymysql\connections.py", line 683, in _read_packet
    packet.check_error()
  File "D:\ProgramData\Anaconda3\lib\site-packages\pymysql\protocol.py", line 220, in check_error
    err.raise_mysql_exception(self._data)
  File "D:\ProgramData\Anaconda3\lib\site-packages\pymysql\err.py", line 109, in raise_mysql_exception
    raise errorclass(errno, errval)
pymysql.err.ProgrammingError: (1146, "Table 'xiaoman.comp' doesn't exist")
&909a6b974e710a8f-Traceback (most recent call last):
  File "C:\Users\lenovo\Desktop\小满海关数据爬取\step2.py", line 104, in get_data
    self.write2sql(sql)
  File "C:\Users\lenovo\Desktop\小满海关数据爬取\step2.py", line 228, in write2sql
    cur.execute(sql)
  File "D:\ProgramData\Anaconda3\lib\site-packages\pymysql\cursors.py", line 170, in execute
    result = self._query(query)
  File "D:\ProgramData\Anaconda3\lib\site-packages\pymysql\cursors.py", line 328, in _query
    conn.query(q)
  File "D:\ProgramData\Anaconda3\lib\site-packages\pymysql\connections.py", line 516, in query
    self._affected_rows = self._read_query_result(unbuffered=unbuffered)
  File "D:\ProgramData\Anaconda3\lib\site-packages\pymysql\connections.py", line 727, in _read_query_result
    result.read()
  File "D:\ProgramData\Anaconda3\lib\site-packages\pymysql\connections.py", line 1066, in read
    first_packet = self.connection._read_packet()
  File "D:\ProgramData\Anaconda3\lib\site-packages\pymysql\connections.py", line 683, in _read_packet
    packet.check_error()
  File "D:\ProgramData\Anaconda3\lib\site-packages\pymysql\protocol.py", line 220, in check_error
    err.raise_mysql_exception(self._data)
  File "D:\ProgramData\Anaconda3\lib\site-packages\pymysql\err.py", line 109, in raise_mysql_exception
    raise errorclass(errno, errval)
pymysql.err.ProgrammingError: (1146, "Table 'xiaoman.comp' doesn't exist")
&27384154fadbdbc4-Traceback (most recent call last):
  File "C:\Users\lenovo\Desktop\小满海关数据爬取\step2.py", line 104, in get_data
    self.write2sql(sql)
  File "C:\Users\lenovo\Desktop\小满海关数据爬取\step2.py", line 228, in write2sql
    cur.execute(sql)
  File "D:\ProgramData\Anaconda3\lib\site-packages\pymysql\cursors.py", line 170, in execute
    result = self._query(query)
  File "D:\ProgramData\Anaconda3\lib\site-packages\pymysql\cursors.py", line 328, in _query
    conn.query(q)
  File "D:\ProgramData\Anaconda3\lib\site-packages\pymysql\connections.py", line 516, in query
    self._affected_rows = self._read_query_result(unbuffered=unbuffered)
  File "D:\ProgramData\Anaconda3\lib\site-packages\pymysql\connections.py", line 727, in _read_query_result
    result.read()
  File "D:\ProgramData\Anaconda3\lib\site-packages\pymysql\connections.py", line 1066, in read
    first_packet = self.connection._read_packet()
  File "D:\ProgramData\Anaconda3\lib\site-packages\pymysql\connections.py", line 683, in _read_packet
    packet.check_error()
  File "D:\ProgramData\Anaconda3\lib\site-packages\pymysql\protocol.py", line 220, in check_error
    err.raise_mysql_exception(self._data)
  File "D:\ProgramData\Anaconda3\lib\site-packages\pymysql\err.py", line 109, in raise_mysql_exception
    raise errorclass(errno, errval)
pymysql.err.ProgrammingError: (1146, "Table 'xiaoman.comp' doesn't exist")
&7ed75b8e3b1c701b-Traceback (most recent call last):
  File "C:\Users\lenovo\Desktop\小满海关数据爬取\step2.py", line 104, in get_data
    self.write2sql(sql)
  File "C:\Users\lenovo\Desktop\小满海关数据爬取\step2.py", line 228, in write2sql
    cur.execute(sql)
  File "D:\ProgramData\Anaconda3\lib\site-packages\pymysql\cursors.py", line 170, in execute
    result = self._query(query)
  File "D:\ProgramData\Anaconda3\lib\site-packages\pymysql\cursors.py", line 328, in _query
    conn.query(q)
  File "D:\ProgramData\Anaconda3\lib\site-packages\pymysql\connections.py", line 516, in query
    self._affected_rows = self._read_query_result(unbuffered=unbuffered)
  File "D:\ProgramData\Anaconda3\lib\site-packages\pymysql\connections.py", line 727, in _read_query_result
    result.read()
  File "D:\ProgramData\Anaconda3\lib\site-packages\pymysql\connections.py", line 1066, in read
    first_packet = self.connection._read_packet()
  File "D:\ProgramData\Anaconda3\lib\site-packages\pymysql\connections.py", line 683, in _read_packet
    packet.check_error()
  File "D:\ProgramData\Anaconda3\lib\site-packages\pymysql\protocol.py", line 220, in check_error
    err.raise_mysql_exception(self._data)
  File "D:\ProgramData\Anaconda3\lib\site-packages\pymysql\err.py", line 109, in raise_mysql_exception
    raise errorclass(errno, errval)
pymysql.err.ProgrammingError: (1146, "Table 'xiaoman.comp' doesn't exist")
&48d1ee0b96986e40-Traceback (most recent call last):
  File "C:\Users\lenovo\Desktop\小满海关数据爬取\step2.py", line 104, in get_data
    self.write2sql(sql)
  File "C:\Users\lenovo\Desktop\小满海关数据爬取\step2.py", line 228, in write2sql
    cur.execute(sql)
  File "D:\ProgramData\Anaconda3\lib\site-packages\pymysql\cursors.py", line 170, in execute
    result = self._query(query)
  File "D:\ProgramData\Anaconda3\lib\site-packages\pymysql\cursors.py", line 328, in _query
    conn.query(q)
  File "D:\ProgramData\Anaconda3\lib\site-packages\pymysql\connections.py", line 516, in query
    self._affected_rows = self._read_query_result(unbuffered=unbuffered)
  File "D:\ProgramData\Anaconda3\lib\site-packages\pymysql\connections.py", line 727, in _read_query_result
    result.read()
  File "D:\ProgramData\Anaconda3\lib\site-packages\pymysql\connections.py", line 1066, in read
    first_packet = self.connection._read_packet()
  File "D:\ProgramData\Anaconda3\lib\site-packages\pymysql\connections.py", line 683, in _read_packet
    packet.check_error()
  File "D:\ProgramData\Anaconda3\lib\site-packages\pymysql\protocol.py", line 220, in check_error
    err.raise_mysql_exception(self._data)
  File "D:\ProgramData\Anaconda3\lib\site-packages\pymysql\err.py", line 109, in raise_mysql_exception
    raise errorclass(errno, errval)
pymysql.err.ProgrammingError: (1146, "Table 'xiaoman.comp' doesn't exist")
&d4b3ab661a5da643-Traceback (most recent call last):
  File "C:\Users\lenovo\Desktop\小满海关数据爬取\step2.py", line 104, in get_data
    self.write2sql(sql)
  File "C:\Users\lenovo\Desktop\小满海关数据爬取\step2.py", line 228, in write2sql
    cur.execute(sql)
  File "D:\ProgramData\Anaconda3\lib\site-packages\pymysql\cursors.py", line 170, in execute
    result = self._query(query)
  File "D:\ProgramData\Anaconda3\lib\site-packages\pymysql\cursors.py", line 328, in _query
    conn.query(q)
  File "D:\ProgramData\Anaconda3\lib\site-packages\pymysql\connections.py", line 516, in query
    self._affected_rows = self._read_query_result(unbuffered=unbuffered)
  File "D:\ProgramData\Anaconda3\lib\site-packages\pymysql\connections.py", line 727, in _read_query_result
    result.read()
  File "D:\ProgramData\Anaconda3\lib\site-packages\pymysql\connections.py", line 1066, in read
    first_packet = self.connection._read_packet()
  File "D:\ProgramData\Anaconda3\lib\site-packages\pymysql\connections.py", line 683, in _read_packet
    packet.check_error()
  File "D:\ProgramData\Anaconda3\lib\site-packages\pymysql\protocol.py", line 220, in check_error
    err.raise_mysql_exception(self._data)
  File "D:\ProgramData\Anaconda3\lib\site-packages\pymysql\err.py", line 109, in raise_mysql_exception
    raise errorclass(errno, errval)
pymysql.err.ProgrammingError: (1146, "Table 'xiaoman.comp' doesn't exist")
&9c40b0ed78f5162a-Traceback (most recent call last):
  File "C:\Users\lenovo\Desktop\小满海关数据爬取\step2.py", line 104, in get_data
    self.write2sql(sql)
  File "C:\Users\lenovo\Desktop\小满海关数据爬取\step2.py", line 228, in write2sql
    cur.execute(sql)
  File "D:\ProgramData\Anaconda3\lib\site-packages\pymysql\cursors.py", line 170, in execute
    result = self._query(query)
  File "D:\ProgramData\Anaconda3\lib\site-packages\pymysql\cursors.py", line 328, in _query
    conn.query(q)
  File "D:\ProgramData\Anaconda3\lib\site-packages\pymysql\connections.py", line 516, in query
    self._affected_rows = self._read_query_result(unbuffered=unbuffered)
  File "D:\ProgramData\Anaconda3\lib\site-packages\pymysql\connections.py", line 727, in _read_query_result
    result.read()
  File "D:\ProgramData\Anaconda3\lib\site-packages\pymysql\connections.py", line 1066, in read
    first_packet = self.connection._read_packet()
  File "D:\ProgramData\Anaconda3\lib\site-packages\pymysql\connections.py", line 683, in _read_packet
    packet.check_error()
  File "D:\ProgramData\Anaconda3\lib\site-packages\pymysql\protocol.py", line 220, in check_error
    err.raise_mysql_exception(self._data)
  File "D:\ProgramData\Anaconda3\lib\site-packages\pymysql\err.py", line 109, in raise_mysql_exception
    raise errorclass(errno, errval)
pymysql.err.ProgrammingError: (1146, "Table 'xiaoman.comp' doesn't exist")
&a52094c3636d92d2-Traceback (most recent call last):
  File "C:\Users\lenovo\Desktop\小满海关数据爬取\step2.py", line 104, in get_data
    self.write2sql(sql)
  File "C:\Users\lenovo\Desktop\小满海关数据爬取\step2.py", line 228, in write2sql
    cur.execute(sql)
  File "D:\ProgramData\Anaconda3\lib\site-packages\pymysql\cursors.py", line 170, in execute
    result = self._query(query)
  File "D:\ProgramData\Anaconda3\lib\site-packages\pymysql\cursors.py", line 328, in _query
    conn.query(q)
  File "D:\ProgramData\Anaconda3\lib\site-packages\pymysql\connections.py", line 516, in query
    self._affected_rows = self._read_query_result(unbuffered=unbuffered)
  File "D:\ProgramData\Anaconda3\lib\site-packages\pymysql\connections.py", line 727, in _read_query_result
    result.read()
  File "D:\ProgramData\Anaconda3\lib\site-packages\pymysql\connections.py", line 1066, in read
    first_packet = self.connection._read_packet()
  File "D:\ProgramData\Anaconda3\lib\site-packages\pymysql\connections.py", line 683, in _read_packet
    packet.check_error()
  File "D:\ProgramData\Anaconda3\lib\site-packages\pymysql\protocol.py", line 220, in check_error
    err.raise_mysql_exception(self._data)
  File "D:\ProgramData\Anaconda3\lib\site-packages\pymysql\err.py", line 109, in raise_mysql_exception
    raise errorclass(errno, errval)
pymysql.err.ProgrammingError: (1146, "Table 'xiaoman.comp' doesn't exist")
&