bbd2177b0fad5c4e-Traceback (most recent call last):
  File "C:\Users\lenovo\Desktop\小满海关数据爬取\step2.py", line 104, in get_data
    self.write2sql(sql)
  File "C:\Users\lenovo\Desktop\小满海关数据爬取\step2.py", line 228, in write2sql
    cur.execute(sql)
  File "D:\ProgramData\Anaconda3\lib\site-packages\pymysql\cursors.py", line 170, in execute
    result = self._query(query)
  File "D:\ProgramData\Anaconda3\lib\site-packages\pymysql\cursors.py", line 328, in _query
    conn.query(q)
  File "D:\ProgramData\Anaconda3\lib\site-packages\pymysql\connections.py", line 516, in query
    self._affected_rows = self._read_query_result(unbuffered=unbuffered)
  File "D:\ProgramData\Anaconda3\lib\site-packages\pymysql\connections.py", line 727, in _read_query_result
    result.read()
  File "D:\ProgramData\Anaconda3\lib\site-packages\pymysql\connections.py", line 1066, in read
    first_packet = self.connection._read_packet()
  File "D:\ProgramData\Anaconda3\lib\site-packages\pymysql\connections.py", line 683, in _read_packet
    packet.check_error()
  File "D:\ProgramData\Anaconda3\lib\site-packages\pymysql\protocol.py", line 220, in check_error
    err.raise_mysql_exception(self._data)
  File "D:\ProgramData\Anaconda3\lib\site-packages\pymysql\err.py", line 109, in raise_mysql_exception
    raise errorclass(errno, errval)
pymysql.err.ProgrammingError: (1146, "Table 'xiaoman.comp' doesn't exist")
&9d99aef514286faf-Traceback (most recent call last):
  File "C:\Users\lenovo\Desktop\小满海关数据爬取\step2.py", line 104, in get_data
    self.write2sql(sql)
  File "C:\Users\lenovo\Desktop\小满海关数据爬取\step2.py", line 228, in write2sql
    cur.execute(sql)
  File "D:\ProgramData\Anaconda3\lib\site-packages\pymysql\cursors.py", line 170, in execute
    result = self._query(query)
  File "D:\ProgramData\Anaconda3\lib\site-packages\pymysql\cursors.py", line 328, in _query
    conn.query(q)
  File "D:\ProgramData\Anaconda3\lib\site-packages\pymysql\connections.py", line 516, in query
    self._affected_rows = self._read_query_result(unbuffered=unbuffered)
  File "D:\ProgramData\Anaconda3\lib\site-packages\pymysql\connections.py", line 727, in _read_query_result
    result.read()
  File "D:\ProgramData\Anaconda3\lib\site-packages\pymysql\connections.py", line 1066, in read
    first_packet = self.connection._read_packet()
  File "D:\ProgramData\Anaconda3\lib\site-packages\pymysql\connections.py", line 683, in _read_packet
    packet.check_error()
  File "D:\ProgramData\Anaconda3\lib\site-packages\pymysql\protocol.py", line 220, in check_error
    err.raise_mysql_exception(self._data)
  File "D:\ProgramData\Anaconda3\lib\site-packages\pymysql\err.py", line 109, in raise_mysql_exception
    raise errorclass(errno, errval)
pymysql.err.ProgrammingError: (1146, "Table 'xiaoman.comp' doesn't exist")
&idzi4abbe0e389bd4f2ac04727eb4b16a443-Traceback (most recent call last):
  File "C:\Users\lenovo\Desktop\小满海关数据爬取\step2.py", line 104, in get_data
    self.write2sql(sql)
  File "C:\Users\lenovo\Desktop\小满海关数据爬取\step2.py", line 228, in write2sql
    cur.execute(sql)
  File "D:\ProgramData\Anaconda3\lib\site-packages\pymysql\cursors.py", line 170, in execute
    result = self._query(query)
  File "D:\ProgramData\Anaconda3\lib\site-packages\pymysql\cursors.py", line 328, in _query
    conn.query(q)
  File "D:\ProgramData\Anaconda3\lib\site-packages\pymysql\connections.py", line 516, in query
    self._affected_rows = self._read_query_result(unbuffered=unbuffered)
  File "D:\ProgramData\Anaconda3\lib\site-packages\pymysql\connections.py", line 727, in _read_query_result
    result.read()
  File "D:\ProgramData\Anaconda3\lib\site-packages\pymysql\connections.py", line 1066, in read
    first_packet = self.connection._read_packet()
  File "D:\ProgramData\Anaconda3\lib\site-packages\pymysql\connections.py", line 683, in _read_packet
    packet.check_error()
  File "D:\ProgramData\Anaconda3\lib\site-packages\pymysql\protocol.py", line 220, in check_error
    err.raise_mysql_exception(self._data)
  File "D:\ProgramData\Anaconda3\lib\site-packages\pymysql\err.py", line 109, in raise_mysql_exception
    raise errorclass(errno, errval)
pymysql.err.ProgrammingError: (1146, "Table 'xiaoman.comp' doesn't exist")
&512effea19da1da7-Traceback (most recent call last):
  File "C:\Users\lenovo\Desktop\小满海关数据爬取\step2.py", line 104, in get_data
    self.write2sql(sql)
  File "C:\Users\lenovo\Desktop\小满海关数据爬取\step2.py", line 228, in write2sql
    cur.execute(sql)
  File "D:\ProgramData\Anaconda3\lib\site-packages\pymysql\cursors.py", line 170, in execute
    result = self._query(query)
  File "D:\ProgramData\Anaconda3\lib\site-packages\pymysql\cursors.py", line 328, in _query
    conn.query(q)
  File "D:\ProgramData\Anaconda3\lib\site-packages\pymysql\connections.py", line 516, in query
    self._affected_rows = self._read_query_result(unbuffered=unbuffered)
  File "D:\ProgramData\Anaconda3\lib\site-packages\pymysql\connections.py", line 727, in _read_query_result
    result.read()
  File "D:\ProgramData\Anaconda3\lib\site-packages\pymysql\connections.py", line 1066, in read
    first_packet = self.connection._read_packet()
  File "D:\ProgramData\Anaconda3\lib\site-packages\pymysql\connections.py", line 683, in _read_packet
    packet.check_error()
  File "D:\ProgramData\Anaconda3\lib\site-packages\pymysql\protocol.py", line 220, in check_error
    err.raise_mysql_exception(self._data)
  File "D:\ProgramData\Anaconda3\lib\site-packages\pymysql\err.py", line 109, in raise_mysql_exception
    raise errorclass(errno, errval)
pymysql.err.ProgrammingError: (1146, "Table 'xiaoman.comp' doesn't exist")
&355cdc689be1ab1c-Traceback (most recent call last):
  File "C:\Users\lenovo\Desktop\小满海关数据爬取\step2.py", line 104, in get_data
    self.write2sql(sql)
  File "C:\Users\lenovo\Desktop\小满海关数据爬取\step2.py", line 228, in write2sql
    cur.execute(sql)
  File "D:\ProgramData\Anaconda3\lib\site-packages\pymysql\cursors.py", line 170, in execute
    result = self._query(query)
  File "D:\ProgramData\Anaconda3\lib\site-packages\pymysql\cursors.py", line 328, in _query
    conn.query(q)
  File "D:\ProgramData\Anaconda3\lib\site-packages\pymysql\connections.py", line 516, in query
    self._affected_rows = self._read_query_result(unbuffered=unbuffered)
  File "D:\ProgramData\Anaconda3\lib\site-packages\pymysql\connections.py", line 727, in _read_query_result
    result.read()
  File "D:\ProgramData\Anaconda3\lib\site-packages\pymysql\connections.py", line 1066, in read
    first_packet = self.connection._read_packet()
  File "D:\ProgramData\Anaconda3\lib\site-packages\pymysql\connections.py", line 683, in _read_packet
    packet.check_error()
  File "D:\ProgramData\Anaconda3\lib\site-packages\pymysql\protocol.py", line 220, in check_error
    err.raise_mysql_exception(self._data)
  File "D:\ProgramData\Anaconda3\lib\site-packages\pymysql\err.py", line 109, in raise_mysql_exception
    raise errorclass(errno, errval)
pymysql.err.ProgrammingError: (1146, "Table 'xiaoman.comp' doesn't exist")
&b36730315c0dcc39-Traceback (most recent call last):
  File "C:\Users\lenovo\Desktop\小满海关数据爬取\step2.py", line 104, in get_data
    self.write2sql(sql)
  File "C:\Users\lenovo\Desktop\小满海关数据爬取\step2.py", line 228, in write2sql
    cur.execute(sql)
  File "D:\ProgramData\Anaconda3\lib\site-packages\pymysql\cursors.py", line 170, in execute
    result = self._query(query)
  File "D:\ProgramData\Anaconda3\lib\site-packages\pymysql\cursors.py", line 328, in _query
    conn.query(q)
  File "D:\ProgramData\Anaconda3\lib\site-packages\pymysql\connections.py", line 516, in query
    self._affected_rows = self._read_query_result(unbuffered=unbuffered)
  File "D:\ProgramData\Anaconda3\lib\site-packages\pymysql\connections.py", line 727, in _read_query_result
    result.read()
  File "D:\ProgramData\Anaconda3\lib\site-packages\pymysql\connections.py", line 1066, in read
    first_packet = self.connection._read_packet()
  File "D:\ProgramData\Anaconda3\lib\site-packages\pymysql\connections.py", line 683, in _read_packet
    packet.check_error()
  File "D:\ProgramData\Anaconda3\lib\site-packages\pymysql\protocol.py", line 220, in check_error
    err.raise_mysql_exception(self._data)
  File "D:\ProgramData\Anaconda3\lib\site-packages\pymysql\err.py", line 109, in raise_mysql_exception
    raise errorclass(errno, errval)
pymysql.err.ProgrammingError: (1146, "Table 'xiaoman.comp' doesn't exist")
&a45e77b609a071e4-Traceback (most recent call last):
  File "C:\Users\lenovo\Desktop\小满海关数据爬取\step2.py", line 104, in get_data
    self.write2sql(sql)
  File "C:\Users\lenovo\Desktop\小满海关数据爬取\step2.py", line 228, in write2sql
    cur.execute(sql)
  File "D:\ProgramData\Anaconda3\lib\site-packages\pymysql\cursors.py", line 170, in execute
    result = self._query(query)
  File "D:\ProgramData\Anaconda3\lib\site-packages\pymysql\cursors.py", line 328, in _query
    conn.query(q)
  File "D:\ProgramData\Anaconda3\lib\site-packages\pymysql\connections.py", line 516, in query
    self._affected_rows = self._read_query_result(unbuffered=unbuffered)
  File "D:\ProgramData\Anaconda3\lib\site-packages\pymysql\connections.py", line 727, in _read_query_result
    result.read()
  File "D:\ProgramData\Anaconda3\lib\site-packages\pymysql\connections.py", line 1066, in read
    first_packet = self.connection._read_packet()
  File "D:\ProgramData\Anaconda3\lib\site-packages\pymysql\connections.py", line 683, in _read_packet
    packet.check_error()
  File "D:\ProgramData\Anaconda3\lib\site-packages\pymysql\protocol.py", line 220, in check_error
    err.raise_mysql_exception(self._data)
  File "D:\ProgramData\Anaconda3\lib\site-packages\pymysql\err.py", line 109, in raise_mysql_exception
    raise errorclass(errno, errval)
pymysql.err.ProgrammingError: (1146, "Table 'xiaoman.comp' doesn't exist")
&3f29c885acecf798-Traceback (most recent call last):
  File "C:\Users\lenovo\Desktop\小满海关数据爬取\step2.py", line 104, in get_data
    self.write2sql(sql)
  File "C:\Users\lenovo\Desktop\小满海关数据爬取\step2.py", line 228, in write2sql
    cur.execute(sql)
  File "D:\ProgramData\Anaconda3\lib\site-packages\pymysql\cursors.py", line 170, in execute
    result = self._query(query)
  File "D:\ProgramData\Anaconda3\lib\site-packages\pymysql\cursors.py", line 328, in _query
    conn.query(q)
  File "D:\ProgramData\Anaconda3\lib\site-packages\pymysql\connections.py", line 516, in query
    self._affected_rows = self._read_query_result(unbuffered=unbuffered)
  File "D:\ProgramData\Anaconda3\lib\site-packages\pymysql\connections.py", line 727, in _read_query_result
    result.read()
  File "D:\ProgramData\Anaconda3\lib\site-packages\pymysql\connections.py", line 1066, in read
    first_packet = self.connection._read_packet()
  File "D:\ProgramData\Anaconda3\lib\site-packages\pymysql\connections.py", line 683, in _read_packet
    packet.check_error()
  File "D:\ProgramData\Anaconda3\lib\site-packages\pymysql\protocol.py", line 220, in check_error
    err.raise_mysql_exception(self._data)
  File "D:\ProgramData\Anaconda3\lib\site-packages\pymysql\err.py", line 109, in raise_mysql_exception
    raise errorclass(errno, errval)
pymysql.err.ProgrammingError: (1146, "Table 'xiaoman.comp' doesn't exist")
&f8499c8a6472ab8b-Traceback (most recent call last):
  File "C:\Users\lenovo\Desktop\小满海关数据爬取\step2.py", line 104, in get_data
    self.write2sql(sql)
  File "C:\Users\lenovo\Desktop\小满海关数据爬取\step2.py", line 228, in write2sql
    cur.execute(sql)
  File "D:\ProgramData\Anaconda3\lib\site-packages\pymysql\cursors.py", line 170, in execute
    result = self._query(query)
  File "D:\ProgramData\Anaconda3\lib\site-packages\pymysql\cursors.py", line 328, in _query
    conn.query(q)
  File "D:\ProgramData\Anaconda3\lib\site-packages\pymysql\connections.py", line 516, in query
    self._affected_rows = self._read_query_result(unbuffered=unbuffered)
  File "D:\ProgramData\Anaconda3\lib\site-packages\pymysql\connections.py", line 727, in _read_query_result
    result.read()
  File "D:\ProgramData\Anaconda3\lib\site-packages\pymysql\connections.py", line 1066, in read
    first_packet = self.connection._read_packet()
  File "D:\ProgramData\Anaconda3\lib\site-packages\pymysql\connections.py", line 683, in _read_packet
    packet.check_error()
  File "D:\ProgramData\Anaconda3\lib\site-packages\pymysql\protocol.py", line 220, in check_error
    err.raise_mysql_exception(self._data)
  File "D:\ProgramData\Anaconda3\lib\site-packages\pymysql\err.py", line 109, in raise_mysql_exception
    raise errorclass(errno, errval)
pymysql.err.ProgrammingError: (1146, "Table 'xiaoman.comp' doesn't exist")
&dd6f363091ad8dc1-Traceback (most recent call last):
  File "C:\Users\lenovo\Desktop\小满海关数据爬取\step2.py", line 104, in get_data
    self.write2sql(sql)
  File "C:\Users\lenovo\Desktop\小满海关数据爬取\step2.py", line 228, in write2sql
    cur.execute(sql)
  File "D:\ProgramData\Anaconda3\lib\site-packages\pymysql\cursors.py", line 170, in execute
    result = self._query(query)
  File "D:\ProgramData\Anaconda3\lib\site-packages\pymysql\cursors.py", line 328, in _query
    conn.query(q)
  File "D:\ProgramData\Anaconda3\lib\site-packages\pymysql\connections.py", line 516, in query
    self._affected_rows = self._read_query_result(unbuffered=unbuffered)
  File "D:\ProgramData\Anaconda3\lib\site-packages\pymysql\connections.py", line 727, in _read_query_result
    result.read()
  File "D:\ProgramData\Anaconda3\lib\site-packages\pymysql\connections.py", line 1066, in read
    first_packet = self.connection._read_packet()
  File "D:\ProgramData\Anaconda3\lib\site-packages\pymysql\connections.py", line 683, in _read_packet
    packet.check_error()
  File "D:\ProgramData\Anaconda3\lib\site-packages\pymysql\protocol.py", line 220, in check_error
    err.raise_mysql_exception(self._data)
  File "D:\ProgramData\Anaconda3\lib\site-packages\pymysql\err.py", line 109, in raise_mysql_exception
    raise errorclass(errno, errval)
pymysql.err.ProgrammingError: (1146, "Table 'xiaoman.comp' doesn't exist")
&aa4f6c12b2ac9fe5-Traceback (most recent call last):
  File "C:\Users\lenovo\Desktop\小满海关数据爬取\step2.py", line 104, in get_data
    self.write2sql(sql)
  File "C:\Users\lenovo\Desktop\小满海关数据爬取\step2.py", line 228, in write2sql
    cur.execute(sql)
  File "D:\ProgramData\Anaconda3\lib\site-packages\pymysql\cursors.py", line 170, in execute
    result = self._query(query)
  File "D:\ProgramData\Anaconda3\lib\site-packages\pymysql\cursors.py", line 328, in _query
    conn.query(q)
  File "D:\ProgramData\Anaconda3\lib\site-packages\pymysql\connections.py", line 516, in query
    self._affected_rows = self._read_query_result(unbuffered=unbuffered)
  File "D:\ProgramData\Anaconda3\lib\site-packages\pymysql\connections.py", line 727, in _read_query_result
    result.read()
  File "D:\ProgramData\Anaconda3\lib\site-packages\pymysql\connections.py", line 1066, in read
    first_packet = self.connection._read_packet()
  File "D:\ProgramData\Anaconda3\lib\site-packages\pymysql\connections.py", line 683, in _read_packet
    packet.check_error()
  File "D:\ProgramData\Anaconda3\lib\site-packages\pymysql\protocol.py", line 220, in check_error
    err.raise_mysql_exception(self._data)
  File "D:\ProgramData\Anaconda3\lib\site-packages\pymysql\err.py", line 109, in raise_mysql_exception
    raise errorclass(errno, errval)
pymysql.err.ProgrammingError: (1146, "Table 'xiaoman.comp' doesn't exist")
&671681b298836ba6-Traceback (most recent call last):
  File "C:\Users\lenovo\Desktop\小满海关数据爬取\step2.py", line 104, in get_data
    self.write2sql(sql)
  File "C:\Users\lenovo\Desktop\小满海关数据爬取\step2.py", line 228, in write2sql
    cur.execute(sql)
  File "D:\ProgramData\Anaconda3\lib\site-packages\pymysql\cursors.py", line 170, in execute
    result = self._query(query)
  File "D:\ProgramData\Anaconda3\lib\site-packages\pymysql\cursors.py", line 328, in _query
    conn.query(q)
  File "D:\ProgramData\Anaconda3\lib\site-packages\pymysql\connections.py", line 516, in query
    self._affected_rows = self._read_query_result(unbuffered=unbuffered)
  File "D:\ProgramData\Anaconda3\lib\site-packages\pymysql\connections.py", line 727, in _read_query_result
    result.read()
  File "D:\ProgramData\Anaconda3\lib\site-packages\pymysql\connections.py", line 1066, in read
    first_packet = self.connection._read_packet()
  File "D:\ProgramData\Anaconda3\lib\site-packages\pymysql\connections.py", line 683, in _read_packet
    packet.check_error()
  File "D:\ProgramData\Anaconda3\lib\site-packages\pymysql\protocol.py", line 220, in check_error
    err.raise_mysql_exception(self._data)
  File "D:\ProgramData\Anaconda3\lib\site-packages\pymysql\err.py", line 109, in raise_mysql_exception
    raise errorclass(errno, errval)
pymysql.err.ProgrammingError: (1146, "Table 'xiaoman.comp' doesn't exist")
&b20b9aff2076b841-Traceback (most recent call last):
  File "C:\Users\lenovo\Desktop\小满海关数据爬取\step2.py", line 104, in get_data
    self.write2sql(sql)
  File "C:\Users\lenovo\Desktop\小满海关数据爬取\step2.py", line 228, in write2sql
    cur.execute(sql)
  File "D:\ProgramData\Anaconda3\lib\site-packages\pymysql\cursors.py", line 170, in execute
    result = self._query(query)
  File "D:\ProgramData\Anaconda3\lib\site-packages\pymysql\cursors.py", line 328, in _query
    conn.query(q)
  File "D:\ProgramData\Anaconda3\lib\site-packages\pymysql\connections.py", line 516, in query
    self._affected_rows = self._read_query_result(unbuffered=unbuffered)
  File "D:\ProgramData\Anaconda3\lib\site-packages\pymysql\connections.py", line 727, in _read_query_result
    result.read()
  File "D:\ProgramData\Anaconda3\lib\site-packages\pymysql\connections.py", line 1066, in read
    first_packet = self.connection._read_packet()
  File "D:\ProgramData\Anaconda3\lib\site-packages\pymysql\connections.py", line 683, in _read_packet
    packet.check_error()
  File "D:\ProgramData\Anaconda3\lib\site-packages\pymysql\protocol.py", line 220, in check_error
    err.raise_mysql_exception(self._data)
  File "D:\ProgramData\Anaconda3\lib\site-packages\pymysql\err.py", line 109, in raise_mysql_exception
    raise errorclass(errno, errval)
pymysql.err.ProgrammingError: (1146, "Table 'xiaoman.comp' doesn't exist")
&49e12cabe6c5c94b-Traceback (most recent call last):
  File "C:\Users\lenovo\Desktop\小满海关数据爬取\step2.py", line 104, in get_data
    self.write2sql(sql)
  File "C:\Users\lenovo\Desktop\小满海关数据爬取\step2.py", line 228, in write2sql
    cur.execute(sql)
  File "D:\ProgramData\Anaconda3\lib\site-packages\pymysql\cursors.py", line 170, in execute
    result = self._query(query)
  File "D:\ProgramData\Anaconda3\lib\site-packages\pymysql\cursors.py", line 328, in _query
    conn.query(q)
  File "D:\ProgramData\Anaconda3\lib\site-packages\pymysql\connections.py", line 516, in query
    self._affected_rows = self._read_query_result(unbuffered=unbuffered)
  File "D:\ProgramData\Anaconda3\lib\site-packages\pymysql\connections.py", line 727, in _read_query_result
    result.read()
  File "D:\ProgramData\Anaconda3\lib\site-packages\pymysql\connections.py", line 1066, in read
    first_packet = self.connection._read_packet()
  File "D:\ProgramData\Anaconda3\lib\site-packages\pymysql\connections.py", line 683, in _read_packet
    packet.check_error()
  File "D:\ProgramData\Anaconda3\lib\site-packages\pymysql\protocol.py", line 220, in check_error
    err.raise_mysql_exception(self._data)
  File "D:\ProgramData\Anaconda3\lib\site-packages\pymysql\err.py", line 109, in raise_mysql_exception
    raise errorclass(errno, errval)
pymysql.err.ProgrammingError: (1146, "Table 'xiaoman.comp' doesn't exist")
&84b76d0bfc913da1-Traceback (most recent call last):
  File "C:\Users\lenovo\Desktop\小满海关数据爬取\step2.py", line 104, in get_data
    self.write2sql(sql)
  File "C:\Users\lenovo\Desktop\小满海关数据爬取\step2.py", line 228, in write2sql
    cur.execute(sql)
  File "D:\ProgramData\Anaconda3\lib\site-packages\pymysql\cursors.py", line 170, in execute
    result = self._query(query)
  File "D:\ProgramData\Anaconda3\lib\site-packages\pymysql\cursors.py", line 328, in _query
    conn.query(q)
  File "D:\ProgramData\Anaconda3\lib\site-packages\pymysql\connections.py", line 516, in query
    self._affected_rows = self._read_query_result(unbuffered=unbuffered)
  File "D:\ProgramData\Anaconda3\lib\site-packages\pymysql\connections.py", line 727, in _read_query_result
    result.read()
  File "D:\ProgramData\Anaconda3\lib\site-packages\pymysql\connections.py", line 1066, in read
    first_packet = self.connection._read_packet()
  File "D:\ProgramData\Anaconda3\lib\site-packages\pymysql\connections.py", line 683, in _read_packet
    packet.check_error()
  File "D:\ProgramData\Anaconda3\lib\site-packages\pymysql\protocol.py", line 220, in check_error
    err.raise_mysql_exception(self._data)
  File "D:\ProgramData\Anaconda3\lib\site-packages\pymysql\err.py", line 109, in raise_mysql_exception
    raise errorclass(errno, errval)
pymysql.err.ProgrammingError: (1146, "Table 'xiaoman.comp' doesn't exist")
&f3c38b0fe0ccebe7-Traceback (most recent call last):
  File "C:\Users\lenovo\Desktop\小满海关数据爬取\step2.py", line 104, in get_data
    self.write2sql(sql)
  File "C:\Users\lenovo\Desktop\小满海关数据爬取\step2.py", line 228, in write2sql
    cur.execute(sql)
  File "D:\ProgramData\Anaconda3\lib\site-packages\pymysql\cursors.py", line 170, in execute
    result = self._query(query)
  File "D:\ProgramData\Anaconda3\lib\site-packages\pymysql\cursors.py", line 328, in _query
    conn.query(q)
  File "D:\ProgramData\Anaconda3\lib\site-packages\pymysql\connections.py", line 516, in query
    self._affected_rows = self._read_query_result(unbuffered=unbuffered)
  File "D:\ProgramData\Anaconda3\lib\site-packages\pymysql\connections.py", line 727, in _read_query_result
    result.read()
  File "D:\ProgramData\Anaconda3\lib\site-packages\pymysql\connections.py", line 1066, in read
    first_packet = self.connection._read_packet()
  File "D:\ProgramData\Anaconda3\lib\site-packages\pymysql\connections.py", line 683, in _read_packet
    packet.check_error()
  File "D:\ProgramData\Anaconda3\lib\site-packages\pymysql\protocol.py", line 220, in check_error
    err.raise_mysql_exception(self._data)
  File "D:\ProgramData\Anaconda3\lib\site-packages\pymysql\err.py", line 109, in raise_mysql_exception
    raise errorclass(errno, errval)
pymysql.err.ProgrammingError: (1146, "Table 'xiaoman.comp' doesn't exist")
&2190201252020fab-Traceback (most recent call last):
  File "C:\Users\lenovo\Desktop\小满海关数据爬取\step2.py", line 104, in get_data
    self.write2sql(sql)
  File "C:\Users\lenovo\Desktop\小满海关数据爬取\step2.py", line 228, in write2sql
    cur.execute(sql)
  File "D:\ProgramData\Anaconda3\lib\site-packages\pymysql\cursors.py", line 170, in execute
    result = self._query(query)
  File "D:\ProgramData\Anaconda3\lib\site-packages\pymysql\cursors.py", line 328, in _query
    conn.query(q)
  File "D:\ProgramData\Anaconda3\lib\site-packages\pymysql\connections.py", line 516, in query
    self._affected_rows = self._read_query_result(unbuffered=unbuffered)
  File "D:\ProgramData\Anaconda3\lib\site-packages\pymysql\connections.py", line 727, in _read_query_result
    result.read()
  File "D:\ProgramData\Anaconda3\lib\site-packages\pymysql\connections.py", line 1066, in read
    first_packet = self.connection._read_packet()
  File "D:\ProgramData\Anaconda3\lib\site-packages\pymysql\connections.py", line 683, in _read_packet
    packet.check_error()
  File "D:\ProgramData\Anaconda3\lib\site-packages\pymysql\protocol.py", line 220, in check_error
    err.raise_mysql_exception(self._data)
  File "D:\ProgramData\Anaconda3\lib\site-packages\pymysql\err.py", line 109, in raise_mysql_exception
    raise errorclass(errno, errval)
pymysql.err.ProgrammingError: (1146, "Table 'xiaoman.comp' doesn't exist")
&jpzief1328da905010965bf47ac9d37466bd-Traceback (most recent call last):
  File "C:\Users\lenovo\Desktop\小满海关数据爬取\step2.py", line 104, in get_data
    self.write2sql(sql)
  File "C:\Users\lenovo\Desktop\小满海关数据爬取\step2.py", line 228, in write2sql
    cur.execute(sql)
  File "D:\ProgramData\Anaconda3\lib\site-packages\pymysql\cursors.py", line 170, in execute
    result = self._query(query)
  File "D:\ProgramData\Anaconda3\lib\site-packages\pymysql\cursors.py", line 328, in _query
    conn.query(q)
  File "D:\ProgramData\Anaconda3\lib\site-packages\pymysql\connections.py", line 516, in query
    self._affected_rows = self._read_query_result(unbuffered=unbuffered)
  File "D:\ProgramData\Anaconda3\lib\site-packages\pymysql\connections.py", line 727, in _read_query_result
    result.read()
  File "D:\ProgramData\Anaconda3\lib\site-packages\pymysql\connections.py", line 1066, in read
    first_packet = self.connection._read_packet()
  File "D:\ProgramData\Anaconda3\lib\site-packages\pymysql\connections.py", line 683, in _read_packet
    packet.check_error()
  File "D:\ProgramData\Anaconda3\lib\site-packages\pymysql\protocol.py", line 220, in check_error
    err.raise_mysql_exception(self._data)
  File "D:\ProgramData\Anaconda3\lib\site-packages\pymysql\err.py", line 109, in raise_mysql_exception
    raise errorclass(errno, errval)
pymysql.err.ProgrammingError: (1146, "Table 'xiaoman.comp' doesn't exist")
&945d1b05a132cf59-Traceback (most recent call last):
  File "C:\Users\lenovo\Desktop\小满海关数据爬取\step2.py", line 104, in get_data
    self.write2sql(sql)
  File "C:\Users\lenovo\Desktop\小满海关数据爬取\step2.py", line 228, in write2sql
    cur.execute(sql)
  File "D:\ProgramData\Anaconda3\lib\site-packages\pymysql\cursors.py", line 170, in execute
    result = self._query(query)
  File "D:\ProgramData\Anaconda3\lib\site-packages\pymysql\cursors.py", line 328, in _query
    conn.query(q)
  File "D:\ProgramData\Anaconda3\lib\site-packages\pymysql\connections.py", line 516, in query
    self._affected_rows = self._read_query_result(unbuffered=unbuffered)
  File "D:\ProgramData\Anaconda3\lib\site-packages\pymysql\connections.py", line 727, in _read_query_result
    result.read()
  File "D:\ProgramData\Anaconda3\lib\site-packages\pymysql\connections.py", line 1066, in read
    first_packet = self.connection._read_packet()
  File "D:\ProgramData\Anaconda3\lib\site-packages\pymysql\connections.py", line 683, in _read_packet
    packet.check_error()
  File "D:\ProgramData\Anaconda3\lib\site-packages\pymysql\protocol.py", line 220, in check_error
    err.raise_mysql_exception(self._data)
  File "D:\ProgramData\Anaconda3\lib\site-packages\pymysql\err.py", line 109, in raise_mysql_exception
    raise errorclass(errno, errval)
pymysql.err.ProgrammingError: (1146, "Table 'xiaoman.comp' doesn't exist")
&838dfe2a28696c31-Traceback (most recent call last):
  File "C:\Users\lenovo\Desktop\小满海关数据爬取\step2.py", line 104, in get_data
    self.write2sql(sql)
  File "C:\Users\lenovo\Desktop\小满海关数据爬取\step2.py", line 228, in write2sql
    cur.execute(sql)
  File "D:\ProgramData\Anaconda3\lib\site-packages\pymysql\cursors.py", line 170, in execute
    result = self._query(query)
  File "D:\ProgramData\Anaconda3\lib\site-packages\pymysql\cursors.py", line 328, in _query
    conn.query(q)
  File "D:\ProgramData\Anaconda3\lib\site-packages\pymysql\connections.py", line 516, in query
    self._affected_rows = self._read_query_result(unbuffered=unbuffered)
  File "D:\ProgramData\Anaconda3\lib\site-packages\pymysql\connections.py", line 727, in _read_query_result
    result.read()
  File "D:\ProgramData\Anaconda3\lib\site-packages\pymysql\connections.py", line 1066, in read
    first_packet = self.connection._read_packet()
  File "D:\ProgramData\Anaconda3\lib\site-packages\pymysql\connections.py", line 683, in _read_packet
    packet.check_error()
  File "D:\ProgramData\Anaconda3\lib\site-packages\pymysql\protocol.py", line 220, in check_error
    err.raise_mysql_exception(self._data)
  File "D:\ProgramData\Anaconda3\lib\site-packages\pymysql\err.py", line 109, in raise_mysql_exception
    raise errorclass(errno, errval)
pymysql.err.ProgrammingError: (1146, "Table 'xiaoman.comp' doesn't exist")
&krzi6dc4a080a8f3f7ab09c9545638ce3ad-Traceback (most recent call last):
  File "C:\Users\lenovo\Desktop\小满海关数据爬取\step2.py", line 104, in get_data
    self.write2sql(sql)
  File "C:\Users\lenovo\Desktop\小满海关数据爬取\step2.py", line 228, in write2sql
    cur.execute(sql)
  File "D:\ProgramData\Anaconda3\lib\site-packages\pymysql\cursors.py", line 170, in execute
    result = self._query(query)
  File "D:\ProgramData\Anaconda3\lib\site-packages\pymysql\cursors.py", line 328, in _query
    conn.query(q)
  File "D:\ProgramData\Anaconda3\lib\site-packages\pymysql\connections.py", line 516, in query
    self._affected_rows = self._read_query_result(unbuffered=unbuffered)
  File "D:\ProgramData\Anaconda3\lib\site-packages\pymysql\connections.py", line 727, in _read_query_result
    result.read()
  File "D:\ProgramData\Anaconda3\lib\site-packages\pymysql\connections.py", line 1066, in read
    first_packet = self.connection._read_packet()
  File "D:\ProgramData\Anaconda3\lib\site-packages\pymysql\connections.py", line 683, in _read_packet
    packet.check_error()
  File "D:\ProgramData\Anaconda3\lib\site-packages\pymysql\protocol.py", line 220, in check_error
    err.raise_mysql_exception(self._data)
  File "D:\ProgramData\Anaconda3\lib\site-packages\pymysql\err.py", line 109, in raise_mysql_exception
    raise errorclass(errno, errval)
pymysql.err.ProgrammingError: (1146, "Table 'xiaoman.comp' doesn't exist")
&64c3e5fe05ffa854-Traceback (most recent call last):
  File "C:\Users\lenovo\Desktop\小满海关数据爬取\step2.py", line 104, in get_data
    self.write2sql(sql)
  File "C:\Users\lenovo\Desktop\小满海关数据爬取\step2.py", line 228, in write2sql
    cur.execute(sql)
  File "D:\ProgramData\Anaconda3\lib\site-packages\pymysql\cursors.py", line 170, in execute
    result = self._query(query)
  File "D:\ProgramData\Anaconda3\lib\site-packages\pymysql\cursors.py", line 328, in _query
    conn.query(q)
  File "D:\ProgramData\Anaconda3\lib\site-packages\pymysql\connections.py", line 516, in query
    self._affected_rows = self._read_query_result(unbuffered=unbuffered)
  File "D:\ProgramData\Anaconda3\lib\site-packages\pymysql\connections.py", line 727, in _read_query_result
    result.read()
  File "D:\ProgramData\Anaconda3\lib\site-packages\pymysql\connections.py", line 1066, in read
    first_packet = self.connection._read_packet()
  File "D:\ProgramData\Anaconda3\lib\site-packages\pymysql\connections.py", line 683, in _read_packet
    packet.check_error()
  File "D:\ProgramData\Anaconda3\lib\site-packages\pymysql\protocol.py", line 220, in check_error
    err.raise_mysql_exception(self._data)
  File "D:\ProgramData\Anaconda3\lib\site-packages\pymysql\err.py", line 109, in raise_mysql_exception
    raise errorclass(errno, errval)
pymysql.err.ProgrammingError: (1146, "Table 'xiaoman.comp' doesn't exist")
&luziefcc55167dd47e27db92199aaf601491-Traceback (most recent call last):
  File "C:\Users\lenovo\Desktop\小满海关数据爬取\step2.py", line 104, in get_data
    self.write2sql(sql)
  File "C:\Users\lenovo\Desktop\小满海关数据爬取\step2.py", line 228, in write2sql
    cur.execute(sql)
  File "D:\ProgramData\Anaconda3\lib\site-packages\pymysql\cursors.py", line 170, in execute
    result = self._query(query)
  File "D:\ProgramData\Anaconda3\lib\site-packages\pymysql\cursors.py", line 328, in _query
    conn.query(q)
  File "D:\ProgramData\Anaconda3\lib\site-packages\pymysql\connections.py", line 516, in query
    self._affected_rows = self._read_query_result(unbuffered=unbuffered)
  File "D:\ProgramData\Anaconda3\lib\site-packages\pymysql\connections.py", line 727, in _read_query_result
    result.read()
  File "D:\ProgramData\Anaconda3\lib\site-packages\pymysql\connections.py", line 1066, in read
    first_packet = self.connection._read_packet()
  File "D:\ProgramData\Anaconda3\lib\site-packages\pymysql\connections.py", line 683, in _read_packet
    packet.check_error()
  File "D:\ProgramData\Anaconda3\lib\site-packages\pymysql\protocol.py", line 220, in check_error
    err.raise_mysql_exception(self._data)
  File "D:\ProgramData\Anaconda3\lib\site-packages\pymysql\err.py", line 109, in raise_mysql_exception
    raise errorclass(errno, errval)
pymysql.err.ProgrammingError: (1146, "Table 'xiaoman.comp' doesn't exist")
&jpzif4bb9d17bb380e27fdd6ea20d0296d6a-Traceback (most recent call last):
  File "C:\Users\lenovo\Desktop\小满海关数据爬取\step2.py", line 104, in get_data
    self.write2sql(sql)
  File "C:\Users\lenovo\Desktop\小满海关数据爬取\step2.py", line 228, in write2sql
    cur.execute(sql)
  File "D:\ProgramData\Anaconda3\lib\site-packages\pymysql\cursors.py", line 170, in execute
    result = self._query(query)
  File "D:\ProgramData\Anaconda3\lib\site-packages\pymysql\cursors.py", line 328, in _query
    conn.query(q)
  File "D:\ProgramData\Anaconda3\lib\site-packages\pymysql\connections.py", line 516, in query
    self._affected_rows = self._read_query_result(unbuffered=unbuffered)
  File "D:\ProgramData\Anaconda3\lib\site-packages\pymysql\connections.py", line 727, in _read_query_result
    result.read()
  File "D:\ProgramData\Anaconda3\lib\site-packages\pymysql\connections.py", line 1066, in read
    first_packet = self.connection._read_packet()
  File "D:\ProgramData\Anaconda3\lib\site-packages\pymysql\connections.py", line 683, in _read_packet
    packet.check_error()
  File "D:\ProgramData\Anaconda3\lib\site-packages\pymysql\protocol.py", line 220, in check_error
    err.raise_mysql_exception(self._data)
  File "D:\ProgramData\Anaconda3\lib\site-packages\pymysql\err.py", line 109, in raise_mysql_exception
    raise errorclass(errno, errval)
pymysql.err.ProgrammingError: (1146, "Table 'xiaoman.comp' doesn't exist")
&frzi7c3701c38c2805c67635b2f532ba7147-Traceback (most recent call last):
  File "C:\Users\lenovo\Desktop\小满海关数据爬取\step2.py", line 104, in get_data
    self.write2sql(sql)
  File "C:\Users\lenovo\Desktop\小满海关数据爬取\step2.py", line 228, in write2sql
    cur.execute(sql)
  File "D:\ProgramData\Anaconda3\lib\site-packages\pymysql\cursors.py", line 170, in execute
    result = self._query(query)
  File "D:\ProgramData\Anaconda3\lib\site-packages\pymysql\cursors.py", line 328, in _query
    conn.query(q)
  File "D:\ProgramData\Anaconda3\lib\site-packages\pymysql\connections.py", line 516, in query
    self._affected_rows = self._read_query_result(unbuffered=unbuffered)
  File "D:\ProgramData\Anaconda3\lib\site-packages\pymysql\connections.py", line 727, in _read_query_result
    result.read()
  File "D:\ProgramData\Anaconda3\lib\site-packages\pymysql\connections.py", line 1066, in read
    first_packet = self.connection._read_packet()
  File "D:\ProgramData\Anaconda3\lib\site-packages\pymysql\connections.py", line 683, in _read_packet
    packet.check_error()
  File "D:\ProgramData\Anaconda3\lib\site-packages\pymysql\protocol.py", line 220, in check_error
    err.raise_mysql_exception(self._data)
  File "D:\ProgramData\Anaconda3\lib\site-packages\pymysql\err.py", line 109, in raise_mysql_exception
    raise errorclass(errno, errval)
pymysql.err.ProgrammingError: (1146, "Table 'xiaoman.comp' doesn't exist")
&