c97b79e6baf74fe6-Traceback (most recent call last):
  File "C:\Users\lenovo\Desktop\小满海关数据爬取\step2.py", line 104, in get_data
    self.write2sql(sql)
  File "C:\Users\lenovo\Desktop\小满海关数据爬取\step2.py", line 228, in write2sql
    cur.execute(sql)
  File "D:\ProgramData\Anaconda3\lib\site-packages\pymysql\cursors.py", line 170, in execute
    result = self._query(query)
  File "D:\ProgramData\Anaconda3\lib\site-packages\pymysql\cursors.py", line 328, in _query
    conn.query(q)
  File "D:\ProgramData\Anaconda3\lib\site-packages\pymysql\connections.py", line 516, in query
    self._affected_rows = self._read_query_result(unbuffered=unbuffered)
  File "D:\ProgramData\Anaconda3\lib\site-packages\pymysql\connections.py", line 727, in _read_query_result
    result.read()
  File "D:\ProgramData\Anaconda3\lib\site-packages\pymysql\connections.py", line 1066, in read
    first_packet = self.connection._read_packet()
  File "D:\ProgramData\Anaconda3\lib\site-packages\pymysql\connections.py", line 683, in _read_packet
    packet.check_error()
  File "D:\ProgramData\Anaconda3\lib\site-packages\pymysql\protocol.py", line 220, in check_error
    err.raise_mysql_exception(self._data)
  File "D:\ProgramData\Anaconda3\lib\site-packages\pymysql\err.py", line 109, in raise_mysql_exception
    raise errorclass(errno, errval)
pymysql.err.ProgrammingError: (1146, "Table 'xiaoman.comp' doesn't exist")
&9a5f582192a87833-Traceback (most recent call last):
  File "C:\Users\lenovo\Desktop\小满海关数据爬取\step2.py", line 104, in get_data
    self.write2sql(sql)
  File "C:\Users\lenovo\Desktop\小满海关数据爬取\step2.py", line 228, in write2sql
    cur.execute(sql)
  File "D:\ProgramData\Anaconda3\lib\site-packages\pymysql\cursors.py", line 170, in execute
    result = self._query(query)
  File "D:\ProgramData\Anaconda3\lib\site-packages\pymysql\cursors.py", line 328, in _query
    conn.query(q)
  File "D:\ProgramData\Anaconda3\lib\site-packages\pymysql\connections.py", line 516, in query
    self._affected_rows = self._read_query_result(unbuffered=unbuffered)
  File "D:\ProgramData\Anaconda3\lib\site-packages\pymysql\connections.py", line 727, in _read_query_result
    result.read()
  File "D:\ProgramData\Anaconda3\lib\site-packages\pymysql\connections.py", line 1066, in read
    first_packet = self.connection._read_packet()
  File "D:\ProgramData\Anaconda3\lib\site-packages\pymysql\connections.py", line 683, in _read_packet
    packet.check_error()
  File "D:\ProgramData\Anaconda3\lib\site-packages\pymysql\protocol.py", line 220, in check_error
    err.raise_mysql_exception(self._data)
  File "D:\ProgramData\Anaconda3\lib\site-packages\pymysql\err.py", line 109, in raise_mysql_exception
    raise errorclass(errno, errval)
pymysql.err.ProgrammingError: (1146, "Table 'xiaoman.comp' doesn't exist")
&6ffa031177996421-Traceback (most recent call last):
  File "C:\Users\lenovo\Desktop\小满海关数据爬取\step2.py", line 104, in get_data
    self.write2sql(sql)
  File "C:\Users\lenovo\Desktop\小满海关数据爬取\step2.py", line 228, in write2sql
    cur.execute(sql)
  File "D:\ProgramData\Anaconda3\lib\site-packages\pymysql\cursors.py", line 170, in execute
    result = self._query(query)
  File "D:\ProgramData\Anaconda3\lib\site-packages\pymysql\cursors.py", line 328, in _query
    conn.query(q)
  File "D:\ProgramData\Anaconda3\lib\site-packages\pymysql\connections.py", line 516, in query
    self._affected_rows = self._read_query_result(unbuffered=unbuffered)
  File "D:\ProgramData\Anaconda3\lib\site-packages\pymysql\connections.py", line 727, in _read_query_result
    result.read()
  File "D:\ProgramData\Anaconda3\lib\site-packages\pymysql\connections.py", line 1066, in read
    first_packet = self.connection._read_packet()
  File "D:\ProgramData\Anaconda3\lib\site-packages\pymysql\connections.py", line 683, in _read_packet
    packet.check_error()
  File "D:\ProgramData\Anaconda3\lib\site-packages\pymysql\protocol.py", line 220, in check_error
    err.raise_mysql_exception(self._data)
  File "D:\ProgramData\Anaconda3\lib\site-packages\pymysql\err.py", line 109, in raise_mysql_exception
    raise errorclass(errno, errval)
pymysql.err.ProgrammingError: (1146, "Table 'xiaoman.comp' doesn't exist")
&7ba8446aa8e4819c-Traceback (most recent call last):
  File "C:\Users\lenovo\Desktop\小满海关数据爬取\step2.py", line 104, in get_data
    self.write2sql(sql)
  File "C:\Users\lenovo\Desktop\小满海关数据爬取\step2.py", line 228, in write2sql
    cur.execute(sql)
  File "D:\ProgramData\Anaconda3\lib\site-packages\pymysql\cursors.py", line 170, in execute
    result = self._query(query)
  File "D:\ProgramData\Anaconda3\lib\site-packages\pymysql\cursors.py", line 328, in _query
    conn.query(q)
  File "D:\ProgramData\Anaconda3\lib\site-packages\pymysql\connections.py", line 516, in query
    self._affected_rows = self._read_query_result(unbuffered=unbuffered)
  File "D:\ProgramData\Anaconda3\lib\site-packages\pymysql\connections.py", line 727, in _read_query_result
    result.read()
  File "D:\ProgramData\Anaconda3\lib\site-packages\pymysql\connections.py", line 1066, in read
    first_packet = self.connection._read_packet()
  File "D:\ProgramData\Anaconda3\lib\site-packages\pymysql\connections.py", line 683, in _read_packet
    packet.check_error()
  File "D:\ProgramData\Anaconda3\lib\site-packages\pymysql\protocol.py", line 220, in check_error
    err.raise_mysql_exception(self._data)
  File "D:\ProgramData\Anaconda3\lib\site-packages\pymysql\err.py", line 109, in raise_mysql_exception
    raise errorclass(errno, errval)
pymysql.err.ProgrammingError: (1146, "Table 'xiaoman.comp' doesn't exist")
&74cadeaeeb43660f-Traceback (most recent call last):
  File "C:\Users\lenovo\Desktop\小满海关数据爬取\step2.py", line 104, in get_data
    self.write2sql(sql)
  File "C:\Users\lenovo\Desktop\小满海关数据爬取\step2.py", line 228, in write2sql
    cur.execute(sql)
  File "D:\ProgramData\Anaconda3\lib\site-packages\pymysql\cursors.py", line 170, in execute
    result = self._query(query)
  File "D:\ProgramData\Anaconda3\lib\site-packages\pymysql\cursors.py", line 328, in _query
    conn.query(q)
  File "D:\ProgramData\Anaconda3\lib\site-packages\pymysql\connections.py", line 516, in query
    self._affected_rows = self._read_query_result(unbuffered=unbuffered)
  File "D:\ProgramData\Anaconda3\lib\site-packages\pymysql\connections.py", line 727, in _read_query_result
    result.read()
  File "D:\ProgramData\Anaconda3\lib\site-packages\pymysql\connections.py", line 1066, in read
    first_packet = self.connection._read_packet()
  File "D:\ProgramData\Anaconda3\lib\site-packages\pymysql\connections.py", line 683, in _read_packet
    packet.check_error()
  File "D:\ProgramData\Anaconda3\lib\site-packages\pymysql\protocol.py", line 220, in check_error
    err.raise_mysql_exception(self._data)
  File "D:\ProgramData\Anaconda3\lib\site-packages\pymysql\err.py", line 109, in raise_mysql_exception
    raise errorclass(errno, errval)
pymysql.err.ProgrammingError: (1146, "Table 'xiaoman.comp' doesn't exist")
&8ec1dd87e2bc4469-Traceback (most recent call last):
  File "C:\Users\lenovo\Desktop\小满海关数据爬取\step2.py", line 104, in get_data
    self.write2sql(sql)
  File "C:\Users\lenovo\Desktop\小满海关数据爬取\step2.py", line 228, in write2sql
    cur.execute(sql)
  File "D:\ProgramData\Anaconda3\lib\site-packages\pymysql\cursors.py", line 170, in execute
    result = self._query(query)
  File "D:\ProgramData\Anaconda3\lib\site-packages\pymysql\cursors.py", line 328, in _query
    conn.query(q)
  File "D:\ProgramData\Anaconda3\lib\site-packages\pymysql\connections.py", line 516, in query
    self._affected_rows = self._read_query_result(unbuffered=unbuffered)
  File "D:\ProgramData\Anaconda3\lib\site-packages\pymysql\connections.py", line 727, in _read_query_result
    result.read()
  File "D:\ProgramData\Anaconda3\lib\site-packages\pymysql\connections.py", line 1066, in read
    first_packet = self.connection._read_packet()
  File "D:\ProgramData\Anaconda3\lib\site-packages\pymysql\connections.py", line 683, in _read_packet
    packet.check_error()
  File "D:\ProgramData\Anaconda3\lib\site-packages\pymysql\protocol.py", line 220, in check_error
    err.raise_mysql_exception(self._data)
  File "D:\ProgramData\Anaconda3\lib\site-packages\pymysql\err.py", line 109, in raise_mysql_exception
    raise errorclass(errno, errval)
pymysql.err.ProgrammingError: (1146, "Table 'xiaoman.comp' doesn't exist")
&063176029d1b4b64-Traceback (most recent call last):
  File "C:\Users\lenovo\Desktop\小满海关数据爬取\step2.py", line 104, in get_data
    self.write2sql(sql)
  File "C:\Users\lenovo\Desktop\小满海关数据爬取\step2.py", line 228, in write2sql
    cur.execute(sql)
  File "D:\ProgramData\Anaconda3\lib\site-packages\pymysql\cursors.py", line 170, in execute
    result = self._query(query)
  File "D:\ProgramData\Anaconda3\lib\site-packages\pymysql\cursors.py", line 328, in _query
    conn.query(q)
  File "D:\ProgramData\Anaconda3\lib\site-packages\pymysql\connections.py", line 516, in query
    self._affected_rows = self._read_query_result(unbuffered=unbuffered)
  File "D:\ProgramData\Anaconda3\lib\site-packages\pymysql\connections.py", line 727, in _read_query_result
    result.read()
  File "D:\ProgramData\Anaconda3\lib\site-packages\pymysql\connections.py", line 1066, in read
    first_packet = self.connection._read_packet()
  File "D:\ProgramData\Anaconda3\lib\site-packages\pymysql\connections.py", line 683, in _read_packet
    packet.check_error()
  File "D:\ProgramData\Anaconda3\lib\site-packages\pymysql\protocol.py", line 220, in check_error
    err.raise_mysql_exception(self._data)
  File "D:\ProgramData\Anaconda3\lib\site-packages\pymysql\err.py", line 109, in raise_mysql_exception
    raise errorclass(errno, errval)
pymysql.err.ProgrammingError: (1146, "Table 'xiaoman.comp' doesn't exist")
&12e854b014cd6fe2-Traceback (most recent call last):
  File "C:\Users\lenovo\Desktop\小满海关数据爬取\step2.py", line 104, in get_data
    self.write2sql(sql)
  File "C:\Users\lenovo\Desktop\小满海关数据爬取\step2.py", line 228, in write2sql
    cur.execute(sql)
  File "D:\ProgramData\Anaconda3\lib\site-packages\pymysql\cursors.py", line 170, in execute
    result = self._query(query)
  File "D:\ProgramData\Anaconda3\lib\site-packages\pymysql\cursors.py", line 328, in _query
    conn.query(q)
  File "D:\ProgramData\Anaconda3\lib\site-packages\pymysql\connections.py", line 516, in query
    self._affected_rows = self._read_query_result(unbuffered=unbuffered)
  File "D:\ProgramData\Anaconda3\lib\site-packages\pymysql\connections.py", line 727, in _read_query_result
    result.read()
  File "D:\ProgramData\Anaconda3\lib\site-packages\pymysql\connections.py", line 1066, in read
    first_packet = self.connection._read_packet()
  File "D:\ProgramData\Anaconda3\lib\site-packages\pymysql\connections.py", line 683, in _read_packet
    packet.check_error()
  File "D:\ProgramData\Anaconda3\lib\site-packages\pymysql\protocol.py", line 220, in check_error
    err.raise_mysql_exception(self._data)
  File "D:\ProgramData\Anaconda3\lib\site-packages\pymysql\err.py", line 109, in raise_mysql_exception
    raise errorclass(errno, errval)
pymysql.err.ProgrammingError: (1146, "Table 'xiaoman.comp' doesn't exist")
&49476c08af5f877b-Traceback (most recent call last):
  File "C:\Users\lenovo\Desktop\小满海关数据爬取\step2.py", line 104, in get_data
    self.write2sql(sql)
  File "C:\Users\lenovo\Desktop\小满海关数据爬取\step2.py", line 228, in write2sql
    cur.execute(sql)
  File "D:\ProgramData\Anaconda3\lib\site-packages\pymysql\cursors.py", line 170, in execute
    result = self._query(query)
  File "D:\ProgramData\Anaconda3\lib\site-packages\pymysql\cursors.py", line 328, in _query
    conn.query(q)
  File "D:\ProgramData\Anaconda3\lib\site-packages\pymysql\connections.py", line 516, in query
    self._affected_rows = self._read_query_result(unbuffered=unbuffered)
  File "D:\ProgramData\Anaconda3\lib\site-packages\pymysql\connections.py", line 727, in _read_query_result
    result.read()
  File "D:\ProgramData\Anaconda3\lib\site-packages\pymysql\connections.py", line 1066, in read
    first_packet = self.connection._read_packet()
  File "D:\ProgramData\Anaconda3\lib\site-packages\pymysql\connections.py", line 683, in _read_packet
    packet.check_error()
  File "D:\ProgramData\Anaconda3\lib\site-packages\pymysql\protocol.py", line 220, in check_error
    err.raise_mysql_exception(self._data)
  File "D:\ProgramData\Anaconda3\lib\site-packages\pymysql\err.py", line 109, in raise_mysql_exception
    raise errorclass(errno, errval)
pymysql.err.ProgrammingError: (1146, "Table 'xiaoman.comp' doesn't exist")
&5ae98890e3f19592-Traceback (most recent call last):
  File "C:\Users\lenovo\Desktop\小满海关数据爬取\step2.py", line 104, in get_data
    self.write2sql(sql)
  File "C:\Users\lenovo\Desktop\小满海关数据爬取\step2.py", line 228, in write2sql
    cur.execute(sql)
  File "D:\ProgramData\Anaconda3\lib\site-packages\pymysql\cursors.py", line 170, in execute
    result = self._query(query)
  File "D:\ProgramData\Anaconda3\lib\site-packages\pymysql\cursors.py", line 328, in _query
    conn.query(q)
  File "D:\ProgramData\Anaconda3\lib\site-packages\pymysql\connections.py", line 516, in query
    self._affected_rows = self._read_query_result(unbuffered=unbuffered)
  File "D:\ProgramData\Anaconda3\lib\site-packages\pymysql\connections.py", line 727, in _read_query_result
    result.read()
  File "D:\ProgramData\Anaconda3\lib\site-packages\pymysql\connections.py", line 1066, in read
    first_packet = self.connection._read_packet()
  File "D:\ProgramData\Anaconda3\lib\site-packages\pymysql\connections.py", line 683, in _read_packet
    packet.check_error()
  File "D:\ProgramData\Anaconda3\lib\site-packages\pymysql\protocol.py", line 220, in check_error
    err.raise_mysql_exception(self._data)
  File "D:\ProgramData\Anaconda3\lib\site-packages\pymysql\err.py", line 109, in raise_mysql_exception
    raise errorclass(errno, errval)
pymysql.err.ProgrammingError: (1146, "Table 'xiaoman.comp' doesn't exist")
&6024d89b36584ff9-Traceback (most recent call last):
  File "C:\Users\lenovo\Desktop\小满海关数据爬取\step2.py", line 104, in get_data
    self.write2sql(sql)
  File "C:\Users\lenovo\Desktop\小满海关数据爬取\step2.py", line 228, in write2sql
    cur.execute(sql)
  File "D:\ProgramData\Anaconda3\lib\site-packages\pymysql\cursors.py", line 170, in execute
    result = self._query(query)
  File "D:\ProgramData\Anaconda3\lib\site-packages\pymysql\cursors.py", line 328, in _query
    conn.query(q)
  File "D:\ProgramData\Anaconda3\lib\site-packages\pymysql\connections.py", line 516, in query
    self._affected_rows = self._read_query_result(unbuffered=unbuffered)
  File "D:\ProgramData\Anaconda3\lib\site-packages\pymysql\connections.py", line 727, in _read_query_result
    result.read()
  File "D:\ProgramData\Anaconda3\lib\site-packages\pymysql\connections.py", line 1066, in read
    first_packet = self.connection._read_packet()
  File "D:\ProgramData\Anaconda3\lib\site-packages\pymysql\connections.py", line 683, in _read_packet
    packet.check_error()
  File "D:\ProgramData\Anaconda3\lib\site-packages\pymysql\protocol.py", line 220, in check_error
    err.raise_mysql_exception(self._data)
  File "D:\ProgramData\Anaconda3\lib\site-packages\pymysql\err.py", line 109, in raise_mysql_exception
    raise errorclass(errno, errval)
pymysql.err.ProgrammingError: (1146, "Table 'xiaoman.comp' doesn't exist")
&5d917e9958f09b40-Traceback (most recent call last):
  File "C:\Users\lenovo\Desktop\小满海关数据爬取\step2.py", line 104, in get_data
    self.write2sql(sql)
  File "C:\Users\lenovo\Desktop\小满海关数据爬取\step2.py", line 228, in write2sql
    cur.execute(sql)
  File "D:\ProgramData\Anaconda3\lib\site-packages\pymysql\cursors.py", line 170, in execute
    result = self._query(query)
  File "D:\ProgramData\Anaconda3\lib\site-packages\pymysql\cursors.py", line 328, in _query
    conn.query(q)
  File "D:\ProgramData\Anaconda3\lib\site-packages\pymysql\connections.py", line 516, in query
    self._affected_rows = self._read_query_result(unbuffered=unbuffered)
  File "D:\ProgramData\Anaconda3\lib\site-packages\pymysql\connections.py", line 727, in _read_query_result
    result.read()
  File "D:\ProgramData\Anaconda3\lib\site-packages\pymysql\connections.py", line 1066, in read
    first_packet = self.connection._read_packet()
  File "D:\ProgramData\Anaconda3\lib\site-packages\pymysql\connections.py", line 683, in _read_packet
    packet.check_error()
  File "D:\ProgramData\Anaconda3\lib\site-packages\pymysql\protocol.py", line 220, in check_error
    err.raise_mysql_exception(self._data)
  File "D:\ProgramData\Anaconda3\lib\site-packages\pymysql\err.py", line 109, in raise_mysql_exception
    raise errorclass(errno, errval)
pymysql.err.ProgrammingError: (1146, "Table 'xiaoman.comp' doesn't exist")
&559ccf56891d142c-Traceback (most recent call last):
  File "C:\Users\lenovo\Desktop\小满海关数据爬取\step2.py", line 104, in get_data
    self.write2sql(sql)
  File "C:\Users\lenovo\Desktop\小满海关数据爬取\step2.py", line 228, in write2sql
    cur.execute(sql)
  File "D:\ProgramData\Anaconda3\lib\site-packages\pymysql\cursors.py", line 170, in execute
    result = self._query(query)
  File "D:\ProgramData\Anaconda3\lib\site-packages\pymysql\cursors.py", line 328, in _query
    conn.query(q)
  File "D:\ProgramData\Anaconda3\lib\site-packages\pymysql\connections.py", line 516, in query
    self._affected_rows = self._read_query_result(unbuffered=unbuffered)
  File "D:\ProgramData\Anaconda3\lib\site-packages\pymysql\connections.py", line 727, in _read_query_result
    result.read()
  File "D:\ProgramData\Anaconda3\lib\site-packages\pymysql\connections.py", line 1066, in read
    first_packet = self.connection._read_packet()
  File "D:\ProgramData\Anaconda3\lib\site-packages\pymysql\connections.py", line 683, in _read_packet
    packet.check_error()
  File "D:\ProgramData\Anaconda3\lib\site-packages\pymysql\protocol.py", line 220, in check_error
    err.raise_mysql_exception(self._data)
  File "D:\ProgramData\Anaconda3\lib\site-packages\pymysql\err.py", line 109, in raise_mysql_exception
    raise errorclass(errno, errval)
pymysql.err.ProgrammingError: (1146, "Table 'xiaoman.comp' doesn't exist")
&f3a80ba17201ce33-Traceback (most recent call last):
  File "C:\Users\lenovo\Desktop\小满海关数据爬取\step2.py", line 104, in get_data
    self.write2sql(sql)
  File "C:\Users\lenovo\Desktop\小满海关数据爬取\step2.py", line 228, in write2sql
    cur.execute(sql)
  File "D:\ProgramData\Anaconda3\lib\site-packages\pymysql\cursors.py", line 170, in execute
    result = self._query(query)
  File "D:\ProgramData\Anaconda3\lib\site-packages\pymysql\cursors.py", line 328, in _query
    conn.query(q)
  File "D:\ProgramData\Anaconda3\lib\site-packages\pymysql\connections.py", line 516, in query
    self._affected_rows = self._read_query_result(unbuffered=unbuffered)
  File "D:\ProgramData\Anaconda3\lib\site-packages\pymysql\connections.py", line 727, in _read_query_result
    result.read()
  File "D:\ProgramData\Anaconda3\lib\site-packages\pymysql\connections.py", line 1066, in read
    first_packet = self.connection._read_packet()
  File "D:\ProgramData\Anaconda3\lib\site-packages\pymysql\connections.py", line 683, in _read_packet
    packet.check_error()
  File "D:\ProgramData\Anaconda3\lib\site-packages\pymysql\protocol.py", line 220, in check_error
    err.raise_mysql_exception(self._data)
  File "D:\ProgramData\Anaconda3\lib\site-packages\pymysql\err.py", line 109, in raise_mysql_exception
    raise errorclass(errno, errval)
pymysql.err.ProgrammingError: (1146, "Table 'xiaoman.comp' doesn't exist")
&5cb4fa500073bb3c-Traceback (most recent call last):
  File "C:\Users\lenovo\Desktop\小满海关数据爬取\step2.py", line 104, in get_data
    self.write2sql(sql)
  File "C:\Users\lenovo\Desktop\小满海关数据爬取\step2.py", line 228, in write2sql
    cur.execute(sql)
  File "D:\ProgramData\Anaconda3\lib\site-packages\pymysql\cursors.py", line 170, in execute
    result = self._query(query)
  File "D:\ProgramData\Anaconda3\lib\site-packages\pymysql\cursors.py", line 328, in _query
    conn.query(q)
  File "D:\ProgramData\Anaconda3\lib\site-packages\pymysql\connections.py", line 516, in query
    self._affected_rows = self._read_query_result(unbuffered=unbuffered)
  File "D:\ProgramData\Anaconda3\lib\site-packages\pymysql\connections.py", line 727, in _read_query_result
    result.read()
  File "D:\ProgramData\Anaconda3\lib\site-packages\pymysql\connections.py", line 1066, in read
    first_packet = self.connection._read_packet()
  File "D:\ProgramData\Anaconda3\lib\site-packages\pymysql\connections.py", line 683, in _read_packet
    packet.check_error()
  File "D:\ProgramData\Anaconda3\lib\site-packages\pymysql\protocol.py", line 220, in check_error
    err.raise_mysql_exception(self._data)
  File "D:\ProgramData\Anaconda3\lib\site-packages\pymysql\err.py", line 109, in raise_mysql_exception
    raise errorclass(errno, errval)
pymysql.err.ProgrammingError: (1146, "Table 'xiaoman.comp' doesn't exist")
&dezid6414197d4a4434a52b5c58e929d947c-Traceback (most recent call last):
  File "C:\Users\lenovo\Desktop\小满海关数据爬取\step2.py", line 104, in get_data
    self.write2sql(sql)
  File "C:\Users\lenovo\Desktop\小满海关数据爬取\step2.py", line 228, in write2sql
    cur.execute(sql)
  File "D:\ProgramData\Anaconda3\lib\site-packages\pymysql\cursors.py", line 170, in execute
    result = self._query(query)
  File "D:\ProgramData\Anaconda3\lib\site-packages\pymysql\cursors.py", line 328, in _query
    conn.query(q)
  File "D:\ProgramData\Anaconda3\lib\site-packages\pymysql\connections.py", line 516, in query
    self._affected_rows = self._read_query_result(unbuffered=unbuffered)
  File "D:\ProgramData\Anaconda3\lib\site-packages\pymysql\connections.py", line 727, in _read_query_result
    result.read()
  File "D:\ProgramData\Anaconda3\lib\site-packages\pymysql\connections.py", line 1066, in read
    first_packet = self.connection._read_packet()
  File "D:\ProgramData\Anaconda3\lib\site-packages\pymysql\connections.py", line 683, in _read_packet
    packet.check_error()
  File "D:\ProgramData\Anaconda3\lib\site-packages\pymysql\protocol.py", line 220, in check_error
    err.raise_mysql_exception(self._data)
  File "D:\ProgramData\Anaconda3\lib\site-packages\pymysql\err.py", line 109, in raise_mysql_exception
    raise errorclass(errno, errval)
pymysql.err.ProgrammingError: (1146, "Table 'xiaoman.comp' doesn't exist")
&inzi2c0eda92dbcdbe76114f557a548c9313-Traceback (most recent call last):
  File "C:\Users\lenovo\Desktop\小满海关数据爬取\step2.py", line 104, in get_data
    self.write2sql(sql)
  File "C:\Users\lenovo\Desktop\小满海关数据爬取\step2.py", line 228, in write2sql
    cur.execute(sql)
  File "D:\ProgramData\Anaconda3\lib\site-packages\pymysql\cursors.py", line 170, in execute
    result = self._query(query)
  File "D:\ProgramData\Anaconda3\lib\site-packages\pymysql\cursors.py", line 328, in _query
    conn.query(q)
  File "D:\ProgramData\Anaconda3\lib\site-packages\pymysql\connections.py", line 516, in query
    self._affected_rows = self._read_query_result(unbuffered=unbuffered)
  File "D:\ProgramData\Anaconda3\lib\site-packages\pymysql\connections.py", line 727, in _read_query_result
    result.read()
  File "D:\ProgramData\Anaconda3\lib\site-packages\pymysql\connections.py", line 1066, in read
    first_packet = self.connection._read_packet()
  File "D:\ProgramData\Anaconda3\lib\site-packages\pymysql\connections.py", line 683, in _read_packet
    packet.check_error()
  File "D:\ProgramData\Anaconda3\lib\site-packages\pymysql\protocol.py", line 220, in check_error
    err.raise_mysql_exception(self._data)
  File "D:\ProgramData\Anaconda3\lib\site-packages\pymysql\err.py", line 109, in raise_mysql_exception
    raise errorclass(errno, errval)
pymysql.err.ProgrammingError: (1146, "Table 'xiaoman.comp' doesn't exist")
&c86c3aad44794cda-Traceback (most recent call last):
  File "C:\Users\lenovo\Desktop\小满海关数据爬取\step2.py", line 104, in get_data
    self.write2sql(sql)
  File "C:\Users\lenovo\Desktop\小满海关数据爬取\step2.py", line 228, in write2sql
    cur.execute(sql)
  File "D:\ProgramData\Anaconda3\lib\site-packages\pymysql\cursors.py", line 170, in execute
    result = self._query(query)
  File "D:\ProgramData\Anaconda3\lib\site-packages\pymysql\cursors.py", line 328, in _query
    conn.query(q)
  File "D:\ProgramData\Anaconda3\lib\site-packages\pymysql\connections.py", line 516, in query
    self._affected_rows = self._read_query_result(unbuffered=unbuffered)
  File "D:\ProgramData\Anaconda3\lib\site-packages\pymysql\connections.py", line 727, in _read_query_result
    result.read()
  File "D:\ProgramData\Anaconda3\lib\site-packages\pymysql\connections.py", line 1066, in read
    first_packet = self.connection._read_packet()
  File "D:\ProgramData\Anaconda3\lib\site-packages\pymysql\connections.py", line 683, in _read_packet
    packet.check_error()
  File "D:\ProgramData\Anaconda3\lib\site-packages\pymysql\protocol.py", line 220, in check_error
    err.raise_mysql_exception(self._data)
  File "D:\ProgramData\Anaconda3\lib\site-packages\pymysql\err.py", line 109, in raise_mysql_exception
    raise errorclass(errno, errval)
pymysql.err.ProgrammingError: (1146, "Table 'xiaoman.comp' doesn't exist")
&790fa33e4f10a502-Traceback (most recent call last):
  File "C:\Users\lenovo\Desktop\小满海关数据爬取\step2.py", line 104, in get_data
    self.write2sql(sql)
  File "C:\Users\lenovo\Desktop\小满海关数据爬取\step2.py", line 228, in write2sql
    cur.execute(sql)
  File "D:\ProgramData\Anaconda3\lib\site-packages\pymysql\cursors.py", line 170, in execute
    result = self._query(query)
  File "D:\ProgramData\Anaconda3\lib\site-packages\pymysql\cursors.py", line 328, in _query
    conn.query(q)
  File "D:\ProgramData\Anaconda3\lib\site-packages\pymysql\connections.py", line 516, in query
    self._affected_rows = self._read_query_result(unbuffered=unbuffered)
  File "D:\ProgramData\Anaconda3\lib\site-packages\pymysql\connections.py", line 727, in _read_query_result
    result.read()
  File "D:\ProgramData\Anaconda3\lib\site-packages\pymysql\connections.py", line 1066, in read
    first_packet = self.connection._read_packet()
  File "D:\ProgramData\Anaconda3\lib\site-packages\pymysql\connections.py", line 683, in _read_packet
    packet.check_error()
  File "D:\ProgramData\Anaconda3\lib\site-packages\pymysql\protocol.py", line 220, in check_error
    err.raise_mysql_exception(self._data)
  File "D:\ProgramData\Anaconda3\lib\site-packages\pymysql\err.py", line 109, in raise_mysql_exception
    raise errorclass(errno, errval)
pymysql.err.ProgrammingError: (1146, "Table 'xiaoman.comp' doesn't exist")
&jpzi5a81fc1014621e181eb59434eb154556-Traceback (most recent call last):
  File "C:\Users\lenovo\Desktop\小满海关数据爬取\step2.py", line 104, in get_data
    self.write2sql(sql)
  File "C:\Users\lenovo\Desktop\小满海关数据爬取\step2.py", line 228, in write2sql
    cur.execute(sql)
  File "D:\ProgramData\Anaconda3\lib\site-packages\pymysql\cursors.py", line 170, in execute
    result = self._query(query)
  File "D:\ProgramData\Anaconda3\lib\site-packages\pymysql\cursors.py", line 328, in _query
    conn.query(q)
  File "D:\ProgramData\Anaconda3\lib\site-packages\pymysql\connections.py", line 516, in query
    self._affected_rows = self._read_query_result(unbuffered=unbuffered)
  File "D:\ProgramData\Anaconda3\lib\site-packages\pymysql\connections.py", line 727, in _read_query_result
    result.read()
  File "D:\ProgramData\Anaconda3\lib\site-packages\pymysql\connections.py", line 1066, in read
    first_packet = self.connection._read_packet()
  File "D:\ProgramData\Anaconda3\lib\site-packages\pymysql\connections.py", line 683, in _read_packet
    packet.check_error()
  File "D:\ProgramData\Anaconda3\lib\site-packages\pymysql\protocol.py", line 220, in check_error
    err.raise_mysql_exception(self._data)
  File "D:\ProgramData\Anaconda3\lib\site-packages\pymysql\err.py", line 109, in raise_mysql_exception
    raise errorclass(errno, errval)
pymysql.err.ProgrammingError: (1146, "Table 'xiaoman.comp' doesn't exist")
&sgzi940b400230d9b1e5aab171c68a5f99ed-Traceback (most recent call last):
  File "C:\Users\lenovo\Desktop\小满海关数据爬取\step2.py", line 104, in get_data
    self.write2sql(sql)
  File "C:\Users\lenovo\Desktop\小满海关数据爬取\step2.py", line 228, in write2sql
    cur.execute(sql)
  File "D:\ProgramData\Anaconda3\lib\site-packages\pymysql\cursors.py", line 170, in execute
    result = self._query(query)
  File "D:\ProgramData\Anaconda3\lib\site-packages\pymysql\cursors.py", line 328, in _query
    conn.query(q)
  File "D:\ProgramData\Anaconda3\lib\site-packages\pymysql\connections.py", line 516, in query
    self._affected_rows = self._read_query_result(unbuffered=unbuffered)
  File "D:\ProgramData\Anaconda3\lib\site-packages\pymysql\connections.py", line 727, in _read_query_result
    result.read()
  File "D:\ProgramData\Anaconda3\lib\site-packages\pymysql\connections.py", line 1066, in read
    first_packet = self.connection._read_packet()
  File "D:\ProgramData\Anaconda3\lib\site-packages\pymysql\connections.py", line 683, in _read_packet
    packet.check_error()
  File "D:\ProgramData\Anaconda3\lib\site-packages\pymysql\protocol.py", line 220, in check_error
    err.raise_mysql_exception(self._data)
  File "D:\ProgramData\Anaconda3\lib\site-packages\pymysql\err.py", line 109, in raise_mysql_exception
    raise errorclass(errno, errval)
pymysql.err.ProgrammingError: (1146, "Table 'xiaoman.comp' doesn't exist")
&cfdec05ab563edd2-Traceback (most recent call last):
  File "C:\Users\lenovo\Desktop\小满海关数据爬取\step2.py", line 104, in get_data
    self.write2sql(sql)
  File "C:\Users\lenovo\Desktop\小满海关数据爬取\step2.py", line 228, in write2sql
    cur.execute(sql)
  File "D:\ProgramData\Anaconda3\lib\site-packages\pymysql\cursors.py", line 170, in execute
    result = self._query(query)
  File "D:\ProgramData\Anaconda3\lib\site-packages\pymysql\cursors.py", line 328, in _query
    conn.query(q)
  File "D:\ProgramData\Anaconda3\lib\site-packages\pymysql\connections.py", line 516, in query
    self._affected_rows = self._read_query_result(unbuffered=unbuffered)
  File "D:\ProgramData\Anaconda3\lib\site-packages\pymysql\connections.py", line 727, in _read_query_result
    result.read()
  File "D:\ProgramData\Anaconda3\lib\site-packages\pymysql\connections.py", line 1066, in read
    first_packet = self.connection._read_packet()
  File "D:\ProgramData\Anaconda3\lib\site-packages\pymysql\connections.py", line 683, in _read_packet
    packet.check_error()
  File "D:\ProgramData\Anaconda3\lib\site-packages\pymysql\protocol.py", line 220, in check_error
    err.raise_mysql_exception(self._data)
  File "D:\ProgramData\Anaconda3\lib\site-packages\pymysql\err.py", line 109, in raise_mysql_exception
    raise errorclass(errno, errval)
pymysql.err.ProgrammingError: (1146, "Table 'xiaoman.comp' doesn't exist")
&d1ed94a80344fb5c-Traceback (most recent call last):
  File "C:\Users\lenovo\Desktop\小满海关数据爬取\step2.py", line 104, in get_data
    self.write2sql(sql)
  File "C:\Users\lenovo\Desktop\小满海关数据爬取\step2.py", line 228, in write2sql
    cur.execute(sql)
  File "D:\ProgramData\Anaconda3\lib\site-packages\pymysql\cursors.py", line 170, in execute
    result = self._query(query)
  File "D:\ProgramData\Anaconda3\lib\site-packages\pymysql\cursors.py", line 328, in _query
    conn.query(q)
  File "D:\ProgramData\Anaconda3\lib\site-packages\pymysql\connections.py", line 516, in query
    self._affected_rows = self._read_query_result(unbuffered=unbuffered)
  File "D:\ProgramData\Anaconda3\lib\site-packages\pymysql\connections.py", line 727, in _read_query_result
    result.read()
  File "D:\ProgramData\Anaconda3\lib\site-packages\pymysql\connections.py", line 1066, in read
    first_packet = self.connection._read_packet()
  File "D:\ProgramData\Anaconda3\lib\site-packages\pymysql\connections.py", line 683, in _read_packet
    packet.check_error()
  File "D:\ProgramData\Anaconda3\lib\site-packages\pymysql\protocol.py", line 220, in check_error
    err.raise_mysql_exception(self._data)
  File "D:\ProgramData\Anaconda3\lib\site-packages\pymysql\err.py", line 109, in raise_mysql_exception
    raise errorclass(errno, errval)
pymysql.err.ProgrammingError: (1146, "Table 'xiaoman.comp' doesn't exist")
&2f0111d4890339a7-Traceback (most recent call last):
  File "C:\Users\lenovo\Desktop\小满海关数据爬取\step2.py", line 104, in get_data
    self.write2sql(sql)
  File "C:\Users\lenovo\Desktop\小满海关数据爬取\step2.py", line 228, in write2sql
    cur.execute(sql)
  File "D:\ProgramData\Anaconda3\lib\site-packages\pymysql\cursors.py", line 170, in execute
    result = self._query(query)
  File "D:\ProgramData\Anaconda3\lib\site-packages\pymysql\cursors.py", line 328, in _query
    conn.query(q)
  File "D:\ProgramData\Anaconda3\lib\site-packages\pymysql\connections.py", line 516, in query
    self._affected_rows = self._read_query_result(unbuffered=unbuffered)
  File "D:\ProgramData\Anaconda3\lib\site-packages\pymysql\connections.py", line 727, in _read_query_result
    result.read()
  File "D:\ProgramData\Anaconda3\lib\site-packages\pymysql\connections.py", line 1066, in read
    first_packet = self.connection._read_packet()
  File "D:\ProgramData\Anaconda3\lib\site-packages\pymysql\connections.py", line 683, in _read_packet
    packet.check_error()
  File "D:\ProgramData\Anaconda3\lib\site-packages\pymysql\protocol.py", line 220, in check_error
    err.raise_mysql_exception(self._data)
  File "D:\ProgramData\Anaconda3\lib\site-packages\pymysql\err.py", line 109, in raise_mysql_exception
    raise errorclass(errno, errval)
pymysql.err.ProgrammingError: (1146, "Table 'xiaoman.comp' doesn't exist")
&955544af4cee9fad-Traceback (most recent call last):
  File "C:\Users\lenovo\Desktop\小满海关数据爬取\step2.py", line 104, in get_data
    self.write2sql(sql)
  File "C:\Users\lenovo\Desktop\小满海关数据爬取\step2.py", line 228, in write2sql
    cur.execute(sql)
  File "D:\ProgramData\Anaconda3\lib\site-packages\pymysql\cursors.py", line 170, in execute
    result = self._query(query)
  File "D:\ProgramData\Anaconda3\lib\site-packages\pymysql\cursors.py", line 328, in _query
    conn.query(q)
  File "D:\ProgramData\Anaconda3\lib\site-packages\pymysql\connections.py", line 516, in query
    self._affected_rows = self._read_query_result(unbuffered=unbuffered)
  File "D:\ProgramData\Anaconda3\lib\site-packages\pymysql\connections.py", line 727, in _read_query_result
    result.read()
  File "D:\ProgramData\Anaconda3\lib\site-packages\pymysql\connections.py", line 1066, in read
    first_packet = self.connection._read_packet()
  File "D:\ProgramData\Anaconda3\lib\site-packages\pymysql\connections.py", line 683, in _read_packet
    packet.check_error()
  File "D:\ProgramData\Anaconda3\lib\site-packages\pymysql\protocol.py", line 220, in check_error
    err.raise_mysql_exception(self._data)
  File "D:\ProgramData\Anaconda3\lib\site-packages\pymysql\err.py", line 109, in raise_mysql_exception
    raise errorclass(errno, errval)
pymysql.err.ProgrammingError: (1146, "Table 'xiaoman.comp' doesn't exist")
&