f9f29d176af05c19-Traceback (most recent call last):
  File "D:\Anaconda\lib\site-packages\pymysql\connections.py", line 690, in _read_bytes
    data = self._rfile.read(num_bytes)
  File "D:\Anaconda\lib\socket.py", line 586, in readinto
    return self._sock.recv_into(b)
ConnectionAbortedError: [WinError 10053] 你的主机中的软件中止了一个已建立的连接。

During handling of the above exception, another exception occurred:

Traceback (most recent call last):
  File "C:\Users\YQ\Desktop\小满海关数据爬取\step2.py", line 116, in get_data
    self.write2sql(sql)
  File "C:\Users\YQ\Desktop\小满海关数据爬取\step2.py", line 245, in write2sql
    cur.execute(sql)
  File "D:\Anaconda\lib\site-packages\pymysql\cursors.py", line 170, in execute
    result = self._query(query)
  File "D:\Anaconda\lib\site-packages\pymysql\cursors.py", line 328, in _query
    conn.query(q)
  File "D:\Anaconda\lib\site-packages\pymysql\connections.py", line 516, in query
    self._affected_rows = self._read_query_result(unbuffered=unbuffered)
  File "D:\Anaconda\lib\site-packages\pymysql\connections.py", line 727, in _read_query_result
    result.read()
  File "D:\Anaconda\lib\site-packages\pymysql\connections.py", line 1066, in read
    first_packet = self.connection._read_packet()
  File "D:\Anaconda\lib\site-packages\pymysql\connections.py", line 656, in _read_packet
    packet_header = self._read_bytes(4)
  File "D:\Anaconda\lib\site-packages\pymysql\connections.py", line 698, in _read_bytes
    "Lost connection to MySQL server during query (%s)" % (e,))
pymysql.err.OperationalError: (2013, 'Lost connection to MySQL server during query ([WinError 10053] 你的主机中的软件中止了一个已建立的连接。)')
&9018d921af4437b2-Traceback (most recent call last):
  File "C:\Users\YQ\Desktop\小满海关数据爬取\step2.py", line 116, in get_data
    self.write2sql(sql)
  File "C:\Users\YQ\Desktop\小满海关数据爬取\step2.py", line 245, in write2sql
    cur.execute(sql)
  File "D:\Anaconda\lib\site-packages\pymysql\cursors.py", line 170, in execute
    result = self._query(query)
  File "D:\Anaconda\lib\site-packages\pymysql\cursors.py", line 328, in _query
    conn.query(q)
  File "D:\Anaconda\lib\site-packages\pymysql\connections.py", line 515, in query
    self._execute_command(COMMAND.COM_QUERY, sql)
  File "D:\Anaconda\lib\site-packages\pymysql\connections.py", line 745, in _execute_command
    raise err.InterfaceError("(0, '')")
pymysql.err.InterfaceError: (0, '')
&a300672d3ecbcbb8-Traceback (most recent call last):
  File "C:\Users\YQ\Desktop\小满海关数据爬取\step2.py", line 116, in get_data
    self.write2sql(sql)
  File "C:\Users\YQ\Desktop\小满海关数据爬取\step2.py", line 245, in write2sql
    cur.execute(sql)
  File "D:\Anaconda\lib\site-packages\pymysql\cursors.py", line 170, in execute
    result = self._query(query)
  File "D:\Anaconda\lib\site-packages\pymysql\cursors.py", line 328, in _query
    conn.query(q)
  File "D:\Anaconda\lib\site-packages\pymysql\connections.py", line 515, in query
    self._execute_command(COMMAND.COM_QUERY, sql)
  File "D:\Anaconda\lib\site-packages\pymysql\connections.py", line 745, in _execute_command
    raise err.InterfaceError("(0, '')")
pymysql.err.InterfaceError: (0, '')
&7d65b443389f16ca-Traceback (most recent call last):
  File "C:\Users\YQ\Desktop\小满海关数据爬取\step2.py", line 116, in get_data
    self.write2sql(sql)
  File "C:\Users\YQ\Desktop\小满海关数据爬取\step2.py", line 245, in write2sql
    cur.execute(sql)
  File "D:\Anaconda\lib\site-packages\pymysql\cursors.py", line 170, in execute
    result = self._query(query)
  File "D:\Anaconda\lib\site-packages\pymysql\cursors.py", line 328, in _query
    conn.query(q)
  File "D:\Anaconda\lib\site-packages\pymysql\connections.py", line 515, in query
    self._execute_command(COMMAND.COM_QUERY, sql)
  File "D:\Anaconda\lib\site-packages\pymysql\connections.py", line 745, in _execute_command
    raise err.InterfaceError("(0, '')")
pymysql.err.InterfaceError: (0, '')
&cazi32271deca355dc3834bc6baae34e57aa-Traceback (most recent call last):
  File "C:\Users\YQ\Desktop\小满海关数据爬取\step2.py", line 116, in get_data
    self.write2sql(sql)
  File "C:\Users\YQ\Desktop\小满海关数据爬取\step2.py", line 245, in write2sql
    cur.execute(sql)
  File "D:\Anaconda\lib\site-packages\pymysql\cursors.py", line 170, in execute
    result = self._query(query)
  File "D:\Anaconda\lib\site-packages\pymysql\cursors.py", line 328, in _query
    conn.query(q)
  File "D:\Anaconda\lib\site-packages\pymysql\connections.py", line 515, in query
    self._execute_command(COMMAND.COM_QUERY, sql)
  File "D:\Anaconda\lib\site-packages\pymysql\connections.py", line 745, in _execute_command
    raise err.InterfaceError("(0, '')")
pymysql.err.InterfaceError: (0, '')
&079def2cd3ee9df4-Traceback (most recent call last):
  File "C:\Users\YQ\Desktop\小满海关数据爬取\step2.py", line 116, in get_data
    self.write2sql(sql)
  File "C:\Users\YQ\Desktop\小满海关数据爬取\step2.py", line 245, in write2sql
    cur.execute(sql)
  File "D:\Anaconda\lib\site-packages\pymysql\cursors.py", line 170, in execute
    result = self._query(query)
  File "D:\Anaconda\lib\site-packages\pymysql\cursors.py", line 328, in _query
    conn.query(q)
  File "D:\Anaconda\lib\site-packages\pymysql\connections.py", line 515, in query
    self._execute_command(COMMAND.COM_QUERY, sql)
  File "D:\Anaconda\lib\site-packages\pymysql\connections.py", line 745, in _execute_command
    raise err.InterfaceError("(0, '')")
pymysql.err.InterfaceError: (0, '')
&9f05952460c89c5e-Traceback (most recent call last):
  File "C:\Users\YQ\Desktop\小满海关数据爬取\step2.py", line 116, in get_data
    self.write2sql(sql)
  File "C:\Users\YQ\Desktop\小满海关数据爬取\step2.py", line 245, in write2sql
    cur.execute(sql)
  File "D:\Anaconda\lib\site-packages\pymysql\cursors.py", line 170, in execute
    result = self._query(query)
  File "D:\Anaconda\lib\site-packages\pymysql\cursors.py", line 328, in _query
    conn.query(q)
  File "D:\Anaconda\lib\site-packages\pymysql\connections.py", line 515, in query
    self._execute_command(COMMAND.COM_QUERY, sql)
  File "D:\Anaconda\lib\site-packages\pymysql\connections.py", line 745, in _execute_command
    raise err.InterfaceError("(0, '')")
pymysql.err.InterfaceError: (0, '')
&46f056a5d09bb4f9-Traceback (most recent call last):
  File "C:\Users\YQ\Desktop\小满海关数据爬取\step2.py", line 116, in get_data
    self.write2sql(sql)
  File "C:\Users\YQ\Desktop\小满海关数据爬取\step2.py", line 245, in write2sql
    cur.execute(sql)
  File "D:\Anaconda\lib\site-packages\pymysql\cursors.py", line 170, in execute
    result = self._query(query)
  File "D:\Anaconda\lib\site-packages\pymysql\cursors.py", line 328, in _query
    conn.query(q)
  File "D:\Anaconda\lib\site-packages\pymysql\connections.py", line 515, in query
    self._execute_command(COMMAND.COM_QUERY, sql)
  File "D:\Anaconda\lib\site-packages\pymysql\connections.py", line 745, in _execute_command
    raise err.InterfaceError("(0, '')")
pymysql.err.InterfaceError: (0, '')
&c8c1e76b85cd9b83-Traceback (most recent call last):
  File "C:\Users\YQ\Desktop\小满海关数据爬取\step2.py", line 116, in get_data
    self.write2sql(sql)
  File "C:\Users\YQ\Desktop\小满海关数据爬取\step2.py", line 245, in write2sql
    cur.execute(sql)
  File "D:\Anaconda\lib\site-packages\pymysql\cursors.py", line 170, in execute
    result = self._query(query)
  File "D:\Anaconda\lib\site-packages\pymysql\cursors.py", line 328, in _query
    conn.query(q)
  File "D:\Anaconda\lib\site-packages\pymysql\connections.py", line 515, in query
    self._execute_command(COMMAND.COM_QUERY, sql)
  File "D:\Anaconda\lib\site-packages\pymysql\connections.py", line 745, in _execute_command
    raise err.InterfaceError("(0, '')")
pymysql.err.InterfaceError: (0, '')
&1294bc2eb85f89c5-Traceback (most recent call last):
  File "C:\Users\YQ\Desktop\小满海关数据爬取\step2.py", line 116, in get_data
    self.write2sql(sql)
  File "C:\Users\YQ\Desktop\小满海关数据爬取\step2.py", line 245, in write2sql
    cur.execute(sql)
  File "D:\Anaconda\lib\site-packages\pymysql\cursors.py", line 170, in execute
    result = self._query(query)
  File "D:\Anaconda\lib\site-packages\pymysql\cursors.py", line 328, in _query
    conn.query(q)
  File "D:\Anaconda\lib\site-packages\pymysql\connections.py", line 515, in query
    self._execute_command(COMMAND.COM_QUERY, sql)
  File "D:\Anaconda\lib\site-packages\pymysql\connections.py", line 745, in _execute_command
    raise err.InterfaceError("(0, '')")
pymysql.err.InterfaceError: (0, '')
&00d6995cad12d278-Traceback (most recent call last):
  File "C:\Users\YQ\Desktop\小满海关数据爬取\step2.py", line 116, in get_data
    self.write2sql(sql)
  File "C:\Users\YQ\Desktop\小满海关数据爬取\step2.py", line 245, in write2sql
    cur.execute(sql)
  File "D:\Anaconda\lib\site-packages\pymysql\cursors.py", line 170, in execute
    result = self._query(query)
  File "D:\Anaconda\lib\site-packages\pymysql\cursors.py", line 328, in _query
    conn.query(q)
  File "D:\Anaconda\lib\site-packages\pymysql\connections.py", line 515, in query
    self._execute_command(COMMAND.COM_QUERY, sql)
  File "D:\Anaconda\lib\site-packages\pymysql\connections.py", line 745, in _execute_command
    raise err.InterfaceError("(0, '')")
pymysql.err.InterfaceError: (0, '')
&dc0ebd64ff133a42-Traceback (most recent call last):
  File "C:\Users\YQ\Desktop\小满海关数据爬取\step2.py", line 116, in get_data
    self.write2sql(sql)
  File "C:\Users\YQ\Desktop\小满海关数据爬取\step2.py", line 245, in write2sql
    cur.execute(sql)
  File "D:\Anaconda\lib\site-packages\pymysql\cursors.py", line 170, in execute
    result = self._query(query)
  File "D:\Anaconda\lib\site-packages\pymysql\cursors.py", line 328, in _query
    conn.query(q)
  File "D:\Anaconda\lib\site-packages\pymysql\connections.py", line 515, in query
    self._execute_command(COMMAND.COM_QUERY, sql)
  File "D:\Anaconda\lib\site-packages\pymysql\connections.py", line 745, in _execute_command
    raise err.InterfaceError("(0, '')")
pymysql.err.InterfaceError: (0, '')
&a77cfda2e5617a76-Traceback (most recent call last):
  File "C:\Users\YQ\Desktop\小满海关数据爬取\step2.py", line 116, in get_data
    self.write2sql(sql)
  File "C:\Users\YQ\Desktop\小满海关数据爬取\step2.py", line 245, in write2sql
    cur.execute(sql)
  File "D:\Anaconda\lib\site-packages\pymysql\cursors.py", line 170, in execute
    result = self._query(query)
  File "D:\Anaconda\lib\site-packages\pymysql\cursors.py", line 328, in _query
    conn.query(q)
  File "D:\Anaconda\lib\site-packages\pymysql\connections.py", line 515, in query
    self._execute_command(COMMAND.COM_QUERY, sql)
  File "D:\Anaconda\lib\site-packages\pymysql\connections.py", line 745, in _execute_command
    raise err.InterfaceError("(0, '')")
pymysql.err.InterfaceError: (0, '')
&14061140e4bd64e9-Traceback (most recent call last):
  File "C:\Users\YQ\Desktop\小满海关数据爬取\step2.py", line 116, in get_data
    self.write2sql(sql)
  File "C:\Users\YQ\Desktop\小满海关数据爬取\step2.py", line 245, in write2sql
    cur.execute(sql)
  File "D:\Anaconda\lib\site-packages\pymysql\cursors.py", line 170, in execute
    result = self._query(query)
  File "D:\Anaconda\lib\site-packages\pymysql\cursors.py", line 328, in _query
    conn.query(q)
  File "D:\Anaconda\lib\site-packages\pymysql\connections.py", line 515, in query
    self._execute_command(COMMAND.COM_QUERY, sql)
  File "D:\Anaconda\lib\site-packages\pymysql\connections.py", line 745, in _execute_command
    raise err.InterfaceError("(0, '')")
pymysql.err.InterfaceError: (0, '')
&eszidf16ebbdd121823df30c65303f93e6ad-Traceback (most recent call last):
  File "C:\Users\YQ\Desktop\小满海关数据爬取\step2.py", line 116, in get_data
    self.write2sql(sql)
  File "C:\Users\YQ\Desktop\小满海关数据爬取\step2.py", line 245, in write2sql
    cur.execute(sql)
  File "D:\Anaconda\lib\site-packages\pymysql\cursors.py", line 170, in execute
    result = self._query(query)
  File "D:\Anaconda\lib\site-packages\pymysql\cursors.py", line 328, in _query
    conn.query(q)
  File "D:\Anaconda\lib\site-packages\pymysql\connections.py", line 515, in query
    self._execute_command(COMMAND.COM_QUERY, sql)
  File "D:\Anaconda\lib\site-packages\pymysql\connections.py", line 745, in _execute_command
    raise err.InterfaceError("(0, '')")
pymysql.err.InterfaceError: (0, '')
&e2b5176049cc8291-Traceback (most recent call last):
  File "C:\Users\YQ\Desktop\小满海关数据爬取\step2.py", line 116, in get_data
    self.write2sql(sql)
  File "C:\Users\YQ\Desktop\小满海关数据爬取\step2.py", line 245, in write2sql
    cur.execute(sql)
  File "D:\Anaconda\lib\site-packages\pymysql\cursors.py", line 170, in execute
    result = self._query(query)
  File "D:\Anaconda\lib\site-packages\pymysql\cursors.py", line 328, in _query
    conn.query(q)
  File "D:\Anaconda\lib\site-packages\pymysql\connections.py", line 515, in query
    self._execute_command(COMMAND.COM_QUERY, sql)
  File "D:\Anaconda\lib\site-packages\pymysql\connections.py", line 745, in _execute_command
    raise err.InterfaceError("(0, '')")
pymysql.err.InterfaceError: (0, '')
&9dd8e46dfe9d97ac-Traceback (most recent call last):
  File "C:\Users\YQ\Desktop\小满海关数据爬取\step2.py", line 116, in get_data
    self.write2sql(sql)
  File "C:\Users\YQ\Desktop\小满海关数据爬取\step2.py", line 245, in write2sql
    cur.execute(sql)
  File "D:\Anaconda\lib\site-packages\pymysql\cursors.py", line 170, in execute
    result = self._query(query)
  File "D:\Anaconda\lib\site-packages\pymysql\cursors.py", line 328, in _query
    conn.query(q)
  File "D:\Anaconda\lib\site-packages\pymysql\connections.py", line 515, in query
    self._execute_command(COMMAND.COM_QUERY, sql)
  File "D:\Anaconda\lib\site-packages\pymysql\connections.py", line 745, in _execute_command
    raise err.InterfaceError("(0, '')")
pymysql.err.InterfaceError: (0, '')
&984fd0a766d57297-Traceback (most recent call last):
  File "C:\Users\YQ\Desktop\小满海关数据爬取\step2.py", line 116, in get_data
    self.write2sql(sql)
  File "C:\Users\YQ\Desktop\小满海关数据爬取\step2.py", line 245, in write2sql
    cur.execute(sql)
  File "D:\Anaconda\lib\site-packages\pymysql\cursors.py", line 170, in execute
    result = self._query(query)
  File "D:\Anaconda\lib\site-packages\pymysql\cursors.py", line 328, in _query
    conn.query(q)
  File "D:\Anaconda\lib\site-packages\pymysql\connections.py", line 515, in query
    self._execute_command(COMMAND.COM_QUERY, sql)
  File "D:\Anaconda\lib\site-packages\pymysql\connections.py", line 745, in _execute_command
    raise err.InterfaceError("(0, '')")
pymysql.err.InterfaceError: (0, '')
&6811bf8da18c80d0-Traceback (most recent call last):
  File "C:\Users\YQ\Desktop\小满海关数据爬取\step2.py", line 116, in get_data
    self.write2sql(sql)
  File "C:\Users\YQ\Desktop\小满海关数据爬取\step2.py", line 245, in write2sql
    cur.execute(sql)
  File "D:\Anaconda\lib\site-packages\pymysql\cursors.py", line 170, in execute
    result = self._query(query)
  File "D:\Anaconda\lib\site-packages\pymysql\cursors.py", line 328, in _query
    conn.query(q)
  File "D:\Anaconda\lib\site-packages\pymysql\connections.py", line 515, in query
    self._execute_command(COMMAND.COM_QUERY, sql)
  File "D:\Anaconda\lib\site-packages\pymysql\connections.py", line 745, in _execute_command
    raise err.InterfaceError("(0, '')")
pymysql.err.InterfaceError: (0, '')
&48b3bc48668f16eb-Traceback (most recent call last):
  File "C:\Users\YQ\Desktop\小满海关数据爬取\step2.py", line 116, in get_data
    self.write2sql(sql)
  File "C:\Users\YQ\Desktop\小满海关数据爬取\step2.py", line 245, in write2sql
    cur.execute(sql)
  File "D:\Anaconda\lib\site-packages\pymysql\cursors.py", line 170, in execute
    result = self._query(query)
  File "D:\Anaconda\lib\site-packages\pymysql\cursors.py", line 328, in _query
    conn.query(q)
  File "D:\Anaconda\lib\site-packages\pymysql\connections.py", line 515, in query
    self._execute_command(COMMAND.COM_QUERY, sql)
  File "D:\Anaconda\lib\site-packages\pymysql\connections.py", line 745, in _execute_command
    raise err.InterfaceError("(0, '')")
pymysql.err.InterfaceError: (0, '')
&da9bba37673dcebf-Traceback (most recent call last):
  File "C:\Users\YQ\Desktop\小满海关数据爬取\step2.py", line 116, in get_data
    self.write2sql(sql)
  File "C:\Users\YQ\Desktop\小满海关数据爬取\step2.py", line 245, in write2sql
    cur.execute(sql)
  File "D:\Anaconda\lib\site-packages\pymysql\cursors.py", line 170, in execute
    result = self._query(query)
  File "D:\Anaconda\lib\site-packages\pymysql\cursors.py", line 328, in _query
    conn.query(q)
  File "D:\Anaconda\lib\site-packages\pymysql\connections.py", line 515, in query
    self._execute_command(COMMAND.COM_QUERY, sql)
  File "D:\Anaconda\lib\site-packages\pymysql\connections.py", line 745, in _execute_command
    raise err.InterfaceError("(0, '')")
pymysql.err.InterfaceError: (0, '')
&36570dce0c934453-Traceback (most recent call last):
  File "C:\Users\YQ\Desktop\小满海关数据爬取\step2.py", line 116, in get_data
    self.write2sql(sql)
  File "C:\Users\YQ\Desktop\小满海关数据爬取\step2.py", line 245, in write2sql
    cur.execute(sql)
  File "D:\Anaconda\lib\site-packages\pymysql\cursors.py", line 170, in execute
    result = self._query(query)
  File "D:\Anaconda\lib\site-packages\pymysql\cursors.py", line 328, in _query
    conn.query(q)
  File "D:\Anaconda\lib\site-packages\pymysql\connections.py", line 515, in query
    self._execute_command(COMMAND.COM_QUERY, sql)
  File "D:\Anaconda\lib\site-packages\pymysql\connections.py", line 745, in _execute_command
    raise err.InterfaceError("(0, '')")
pymysql.err.InterfaceError: (0, '')
&501c55dcb8e5937d-Traceback (most recent call last):
  File "C:\Users\YQ\Desktop\小满海关数据爬取\step2.py", line 116, in get_data
    self.write2sql(sql)
  File "C:\Users\YQ\Desktop\小满海关数据爬取\step2.py", line 245, in write2sql
    cur.execute(sql)
  File "D:\Anaconda\lib\site-packages\pymysql\cursors.py", line 170, in execute
    result = self._query(query)
  File "D:\Anaconda\lib\site-packages\pymysql\cursors.py", line 328, in _query
    conn.query(q)
  File "D:\Anaconda\lib\site-packages\pymysql\connections.py", line 515, in query
    self._execute_command(COMMAND.COM_QUERY, sql)
  File "D:\Anaconda\lib\site-packages\pymysql\connections.py", line 745, in _execute_command
    raise err.InterfaceError("(0, '')")
pymysql.err.InterfaceError: (0, '')
&c000eb729b5e9fc3-Traceback (most recent call last):
  File "C:\Users\YQ\Desktop\小满海关数据爬取\step2.py", line 116, in get_data
    self.write2sql(sql)
  File "C:\Users\YQ\Desktop\小满海关数据爬取\step2.py", line 245, in write2sql
    cur.execute(sql)
  File "D:\Anaconda\lib\site-packages\pymysql\cursors.py", line 170, in execute
    result = self._query(query)
  File "D:\Anaconda\lib\site-packages\pymysql\cursors.py", line 328, in _query
    conn.query(q)
  File "D:\Anaconda\lib\site-packages\pymysql\connections.py", line 515, in query
    self._execute_command(COMMAND.COM_QUERY, sql)
  File "D:\Anaconda\lib\site-packages\pymysql\connections.py", line 745, in _execute_command
    raise err.InterfaceError("(0, '')")
pymysql.err.InterfaceError: (0, '')
&2b591c9aedeb130a-Traceback (most recent call last):
  File "C:\Users\YQ\Desktop\小满海关数据爬取\step2.py", line 116, in get_data
    self.write2sql(sql)
  File "C:\Users\YQ\Desktop\小满海关数据爬取\step2.py", line 245, in write2sql
    cur.execute(sql)
  File "D:\Anaconda\lib\site-packages\pymysql\cursors.py", line 170, in execute
    result = self._query(query)
  File "D:\Anaconda\lib\site-packages\pymysql\cursors.py", line 328, in _query
    conn.query(q)
  File "D:\Anaconda\lib\site-packages\pymysql\connections.py", line 515, in query
    self._execute_command(COMMAND.COM_QUERY, sql)
  File "D:\Anaconda\lib\site-packages\pymysql\connections.py", line 745, in _execute_command
    raise err.InterfaceError("(0, '')")
pymysql.err.InterfaceError: (0, '')
&