uszi8aabac0e6a392747c7b54f6aae983ee7-Traceback (most recent call last):
  File "C:\Users\lenovo\Desktop\小满海关数据爬取\step2.py", line 104, in get_data
    self.write2sql(sql)
  File "C:\Users\lenovo\Desktop\小满海关数据爬取\step2.py", line 228, in write2sql
    cur.execute(sql)
  File "D:\ProgramData\Anaconda3\lib\site-packages\pymysql\cursors.py", line 170, in execute
    result = self._query(query)
  File "D:\ProgramData\Anaconda3\lib\site-packages\pymysql\cursors.py", line 328, in _query
    conn.query(q)
  File "D:\ProgramData\Anaconda3\lib\site-packages\pymysql\connections.py", line 516, in query
    self._affected_rows = self._read_query_result(unbuffered=unbuffered)
  File "D:\ProgramData\Anaconda3\lib\site-packages\pymysql\connections.py", line 727, in _read_query_result
    result.read()
  File "D:\ProgramData\Anaconda3\lib\site-packages\pymysql\connections.py", line 1066, in read
    first_packet = self.connection._read_packet()
  File "D:\ProgramData\Anaconda3\lib\site-packages\pymysql\connections.py", line 683, in _read_packet
    packet.check_error()
  File "D:\ProgramData\Anaconda3\lib\site-packages\pymysql\protocol.py", line 220, in check_error
    err.raise_mysql_exception(self._data)
  File "D:\ProgramData\Anaconda3\lib\site-packages\pymysql\err.py", line 109, in raise_mysql_exception
    raise errorclass(errno, errval)
pymysql.err.ProgrammingError: (1146, "Table 'xiaoman.comp' doesn't exist")
&jpzi3ffc4ede4cd5cd30b84803f06fc41aff-Traceback (most recent call last):
  File "C:\Users\lenovo\Desktop\小满海关数据爬取\step2.py", line 104, in get_data
    self.write2sql(sql)
  File "C:\Users\lenovo\Desktop\小满海关数据爬取\step2.py", line 228, in write2sql
    cur.execute(sql)
  File "D:\ProgramData\Anaconda3\lib\site-packages\pymysql\cursors.py", line 170, in execute
    result = self._query(query)
  File "D:\ProgramData\Anaconda3\lib\site-packages\pymysql\cursors.py", line 328, in _query
    conn.query(q)
  File "D:\ProgramData\Anaconda3\lib\site-packages\pymysql\connections.py", line 516, in query
    self._affected_rows = self._read_query_result(unbuffered=unbuffered)
  File "D:\ProgramData\Anaconda3\lib\site-packages\pymysql\connections.py", line 727, in _read_query_result
    result.read()
  File "D:\ProgramData\Anaconda3\lib\site-packages\pymysql\connections.py", line 1066, in read
    first_packet = self.connection._read_packet()
  File "D:\ProgramData\Anaconda3\lib\site-packages\pymysql\connections.py", line 683, in _read_packet
    packet.check_error()
  File "D:\ProgramData\Anaconda3\lib\site-packages\pymysql\protocol.py", line 220, in check_error
    err.raise_mysql_exception(self._data)
  File "D:\ProgramData\Anaconda3\lib\site-packages\pymysql\err.py", line 109, in raise_mysql_exception
    raise errorclass(errno, errval)
pymysql.err.ProgrammingError: (1146, "Table 'xiaoman.comp' doesn't exist")
&a2d186c7bd1445ab-Traceback (most recent call last):
  File "C:\Users\lenovo\Desktop\小满海关数据爬取\step2.py", line 104, in get_data
    self.write2sql(sql)
  File "C:\Users\lenovo\Desktop\小满海关数据爬取\step2.py", line 228, in write2sql
    cur.execute(sql)
  File "D:\ProgramData\Anaconda3\lib\site-packages\pymysql\cursors.py", line 170, in execute
    result = self._query(query)
  File "D:\ProgramData\Anaconda3\lib\site-packages\pymysql\cursors.py", line 328, in _query
    conn.query(q)
  File "D:\ProgramData\Anaconda3\lib\site-packages\pymysql\connections.py", line 516, in query
    self._affected_rows = self._read_query_result(unbuffered=unbuffered)
  File "D:\ProgramData\Anaconda3\lib\site-packages\pymysql\connections.py", line 727, in _read_query_result
    result.read()
  File "D:\ProgramData\Anaconda3\lib\site-packages\pymysql\connections.py", line 1066, in read
    first_packet = self.connection._read_packet()
  File "D:\ProgramData\Anaconda3\lib\site-packages\pymysql\connections.py", line 683, in _read_packet
    packet.check_error()
  File "D:\ProgramData\Anaconda3\lib\site-packages\pymysql\protocol.py", line 220, in check_error
    err.raise_mysql_exception(self._data)
  File "D:\ProgramData\Anaconda3\lib\site-packages\pymysql\err.py", line 109, in raise_mysql_exception
    raise errorclass(errno, errval)
pymysql.err.ProgrammingError: (1146, "Table 'xiaoman.comp' doesn't exist")
&3b27569ac03b7a66-Traceback (most recent call last):
  File "C:\Users\lenovo\Desktop\小满海关数据爬取\step2.py", line 104, in get_data
    self.write2sql(sql)
  File "C:\Users\lenovo\Desktop\小满海关数据爬取\step2.py", line 228, in write2sql
    cur.execute(sql)
  File "D:\ProgramData\Anaconda3\lib\site-packages\pymysql\cursors.py", line 170, in execute
    result = self._query(query)
  File "D:\ProgramData\Anaconda3\lib\site-packages\pymysql\cursors.py", line 328, in _query
    conn.query(q)
  File "D:\ProgramData\Anaconda3\lib\site-packages\pymysql\connections.py", line 516, in query
    self._affected_rows = self._read_query_result(unbuffered=unbuffered)
  File "D:\ProgramData\Anaconda3\lib\site-packages\pymysql\connections.py", line 727, in _read_query_result
    result.read()
  File "D:\ProgramData\Anaconda3\lib\site-packages\pymysql\connections.py", line 1066, in read
    first_packet = self.connection._read_packet()
  File "D:\ProgramData\Anaconda3\lib\site-packages\pymysql\connections.py", line 683, in _read_packet
    packet.check_error()
  File "D:\ProgramData\Anaconda3\lib\site-packages\pymysql\protocol.py", line 220, in check_error
    err.raise_mysql_exception(self._data)
  File "D:\ProgramData\Anaconda3\lib\site-packages\pymysql\err.py", line 109, in raise_mysql_exception
    raise errorclass(errno, errval)
pymysql.err.ProgrammingError: (1146, "Table 'xiaoman.comp' doesn't exist")
&90d2cdf2b111a338-Traceback (most recent call last):
  File "C:\Users\lenovo\Desktop\小满海关数据爬取\step2.py", line 104, in get_data
    self.write2sql(sql)
  File "C:\Users\lenovo\Desktop\小满海关数据爬取\step2.py", line 228, in write2sql
    cur.execute(sql)
  File "D:\ProgramData\Anaconda3\lib\site-packages\pymysql\cursors.py", line 170, in execute
    result = self._query(query)
  File "D:\ProgramData\Anaconda3\lib\site-packages\pymysql\cursors.py", line 328, in _query
    conn.query(q)
  File "D:\ProgramData\Anaconda3\lib\site-packages\pymysql\connections.py", line 516, in query
    self._affected_rows = self._read_query_result(unbuffered=unbuffered)
  File "D:\ProgramData\Anaconda3\lib\site-packages\pymysql\connections.py", line 727, in _read_query_result
    result.read()
  File "D:\ProgramData\Anaconda3\lib\site-packages\pymysql\connections.py", line 1066, in read
    first_packet = self.connection._read_packet()
  File "D:\ProgramData\Anaconda3\lib\site-packages\pymysql\connections.py", line 683, in _read_packet
    packet.check_error()
  File "D:\ProgramData\Anaconda3\lib\site-packages\pymysql\protocol.py", line 220, in check_error
    err.raise_mysql_exception(self._data)
  File "D:\ProgramData\Anaconda3\lib\site-packages\pymysql\err.py", line 109, in raise_mysql_exception
    raise errorclass(errno, errval)
pymysql.err.ProgrammingError: (1146, "Table 'xiaoman.comp' doesn't exist")
&jpzia304dc63c26d7e40f9b301271272566e-Traceback (most recent call last):
  File "C:\Users\lenovo\Desktop\小满海关数据爬取\step2.py", line 104, in get_data
    self.write2sql(sql)
  File "C:\Users\lenovo\Desktop\小满海关数据爬取\step2.py", line 228, in write2sql
    cur.execute(sql)
  File "D:\ProgramData\Anaconda3\lib\site-packages\pymysql\cursors.py", line 170, in execute
    result = self._query(query)
  File "D:\ProgramData\Anaconda3\lib\site-packages\pymysql\cursors.py", line 328, in _query
    conn.query(q)
  File "D:\ProgramData\Anaconda3\lib\site-packages\pymysql\connections.py", line 516, in query
    self._affected_rows = self._read_query_result(unbuffered=unbuffered)
  File "D:\ProgramData\Anaconda3\lib\site-packages\pymysql\connections.py", line 727, in _read_query_result
    result.read()
  File "D:\ProgramData\Anaconda3\lib\site-packages\pymysql\connections.py", line 1066, in read
    first_packet = self.connection._read_packet()
  File "D:\ProgramData\Anaconda3\lib\site-packages\pymysql\connections.py", line 683, in _read_packet
    packet.check_error()
  File "D:\ProgramData\Anaconda3\lib\site-packages\pymysql\protocol.py", line 220, in check_error
    err.raise_mysql_exception(self._data)
  File "D:\ProgramData\Anaconda3\lib\site-packages\pymysql\err.py", line 109, in raise_mysql_exception
    raise errorclass(errno, errval)
pymysql.err.ProgrammingError: (1146, "Table 'xiaoman.comp' doesn't exist")
&8f31f2082424369a-Traceback (most recent call last):
  File "C:\Users\lenovo\Desktop\小满海关数据爬取\step2.py", line 104, in get_data
    self.write2sql(sql)
  File "C:\Users\lenovo\Desktop\小满海关数据爬取\step2.py", line 228, in write2sql
    cur.execute(sql)
  File "D:\ProgramData\Anaconda3\lib\site-packages\pymysql\cursors.py", line 170, in execute
    result = self._query(query)
  File "D:\ProgramData\Anaconda3\lib\site-packages\pymysql\cursors.py", line 328, in _query
    conn.query(q)
  File "D:\ProgramData\Anaconda3\lib\site-packages\pymysql\connections.py", line 516, in query
    self._affected_rows = self._read_query_result(unbuffered=unbuffered)
  File "D:\ProgramData\Anaconda3\lib\site-packages\pymysql\connections.py", line 727, in _read_query_result
    result.read()
  File "D:\ProgramData\Anaconda3\lib\site-packages\pymysql\connections.py", line 1066, in read
    first_packet = self.connection._read_packet()
  File "D:\ProgramData\Anaconda3\lib\site-packages\pymysql\connections.py", line 683, in _read_packet
    packet.check_error()
  File "D:\ProgramData\Anaconda3\lib\site-packages\pymysql\protocol.py", line 220, in check_error
    err.raise_mysql_exception(self._data)
  File "D:\ProgramData\Anaconda3\lib\site-packages\pymysql\err.py", line 109, in raise_mysql_exception
    raise errorclass(errno, errval)
pymysql.err.ProgrammingError: (1146, "Table 'xiaoman.comp' doesn't exist")
&11578c80a15da7fa-Traceback (most recent call last):
  File "C:\Users\lenovo\Desktop\小满海关数据爬取\step2.py", line 104, in get_data
    self.write2sql(sql)
  File "C:\Users\lenovo\Desktop\小满海关数据爬取\step2.py", line 228, in write2sql
    cur.execute(sql)
  File "D:\ProgramData\Anaconda3\lib\site-packages\pymysql\cursors.py", line 170, in execute
    result = self._query(query)
  File "D:\ProgramData\Anaconda3\lib\site-packages\pymysql\cursors.py", line 328, in _query
    conn.query(q)
  File "D:\ProgramData\Anaconda3\lib\site-packages\pymysql\connections.py", line 516, in query
    self._affected_rows = self._read_query_result(unbuffered=unbuffered)
  File "D:\ProgramData\Anaconda3\lib\site-packages\pymysql\connections.py", line 727, in _read_query_result
    result.read()
  File "D:\ProgramData\Anaconda3\lib\site-packages\pymysql\connections.py", line 1066, in read
    first_packet = self.connection._read_packet()
  File "D:\ProgramData\Anaconda3\lib\site-packages\pymysql\connections.py", line 683, in _read_packet
    packet.check_error()
  File "D:\ProgramData\Anaconda3\lib\site-packages\pymysql\protocol.py", line 220, in check_error
    err.raise_mysql_exception(self._data)
  File "D:\ProgramData\Anaconda3\lib\site-packages\pymysql\err.py", line 109, in raise_mysql_exception
    raise errorclass(errno, errval)
pymysql.err.ProgrammingError: (1146, "Table 'xiaoman.comp' doesn't exist")
&8040fa78ee7cb75d-Traceback (most recent call last):
  File "C:\Users\lenovo\Desktop\小满海关数据爬取\step2.py", line 104, in get_data
    self.write2sql(sql)
  File "C:\Users\lenovo\Desktop\小满海关数据爬取\step2.py", line 228, in write2sql
    cur.execute(sql)
  File "D:\ProgramData\Anaconda3\lib\site-packages\pymysql\cursors.py", line 170, in execute
    result = self._query(query)
  File "D:\ProgramData\Anaconda3\lib\site-packages\pymysql\cursors.py", line 328, in _query
    conn.query(q)
  File "D:\ProgramData\Anaconda3\lib\site-packages\pymysql\connections.py", line 516, in query
    self._affected_rows = self._read_query_result(unbuffered=unbuffered)
  File "D:\ProgramData\Anaconda3\lib\site-packages\pymysql\connections.py", line 727, in _read_query_result
    result.read()
  File "D:\ProgramData\Anaconda3\lib\site-packages\pymysql\connections.py", line 1066, in read
    first_packet = self.connection._read_packet()
  File "D:\ProgramData\Anaconda3\lib\site-packages\pymysql\connections.py", line 683, in _read_packet
    packet.check_error()
  File "D:\ProgramData\Anaconda3\lib\site-packages\pymysql\protocol.py", line 220, in check_error
    err.raise_mysql_exception(self._data)
  File "D:\ProgramData\Anaconda3\lib\site-packages\pymysql\err.py", line 109, in raise_mysql_exception
    raise errorclass(errno, errval)
pymysql.err.ProgrammingError: (1146, "Table 'xiaoman.comp' doesn't exist")
&1bc03d59c18e8810-Traceback (most recent call last):
  File "C:\Users\lenovo\Desktop\小满海关数据爬取\step2.py", line 104, in get_data
    self.write2sql(sql)
  File "C:\Users\lenovo\Desktop\小满海关数据爬取\step2.py", line 228, in write2sql
    cur.execute(sql)
  File "D:\ProgramData\Anaconda3\lib\site-packages\pymysql\cursors.py", line 170, in execute
    result = self._query(query)
  File "D:\ProgramData\Anaconda3\lib\site-packages\pymysql\cursors.py", line 328, in _query
    conn.query(q)
  File "D:\ProgramData\Anaconda3\lib\site-packages\pymysql\connections.py", line 516, in query
    self._affected_rows = self._read_query_result(unbuffered=unbuffered)
  File "D:\ProgramData\Anaconda3\lib\site-packages\pymysql\connections.py", line 727, in _read_query_result
    result.read()
  File "D:\ProgramData\Anaconda3\lib\site-packages\pymysql\connections.py", line 1066, in read
    first_packet = self.connection._read_packet()
  File "D:\ProgramData\Anaconda3\lib\site-packages\pymysql\connections.py", line 683, in _read_packet
    packet.check_error()
  File "D:\ProgramData\Anaconda3\lib\site-packages\pymysql\protocol.py", line 220, in check_error
    err.raise_mysql_exception(self._data)
  File "D:\ProgramData\Anaconda3\lib\site-packages\pymysql\err.py", line 109, in raise_mysql_exception
    raise errorclass(errno, errval)
pymysql.err.ProgrammingError: (1146, "Table 'xiaoman.comp' doesn't exist")
&2f90a50247708af4-Traceback (most recent call last):
  File "C:\Users\lenovo\Desktop\小满海关数据爬取\step2.py", line 104, in get_data
    self.write2sql(sql)
  File "C:\Users\lenovo\Desktop\小满海关数据爬取\step2.py", line 228, in write2sql
    cur.execute(sql)
  File "D:\ProgramData\Anaconda3\lib\site-packages\pymysql\cursors.py", line 170, in execute
    result = self._query(query)
  File "D:\ProgramData\Anaconda3\lib\site-packages\pymysql\cursors.py", line 328, in _query
    conn.query(q)
  File "D:\ProgramData\Anaconda3\lib\site-packages\pymysql\connections.py", line 516, in query
    self._affected_rows = self._read_query_result(unbuffered=unbuffered)
  File "D:\ProgramData\Anaconda3\lib\site-packages\pymysql\connections.py", line 727, in _read_query_result
    result.read()
  File "D:\ProgramData\Anaconda3\lib\site-packages\pymysql\connections.py", line 1066, in read
    first_packet = self.connection._read_packet()
  File "D:\ProgramData\Anaconda3\lib\site-packages\pymysql\connections.py", line 683, in _read_packet
    packet.check_error()
  File "D:\ProgramData\Anaconda3\lib\site-packages\pymysql\protocol.py", line 220, in check_error
    err.raise_mysql_exception(self._data)
  File "D:\ProgramData\Anaconda3\lib\site-packages\pymysql\err.py", line 109, in raise_mysql_exception
    raise errorclass(errno, errval)
pymysql.err.ProgrammingError: (1146, "Table 'xiaoman.comp' doesn't exist")
&b22dd133cc08e2b5-Traceback (most recent call last):
  File "C:\Users\lenovo\Desktop\小满海关数据爬取\step2.py", line 104, in get_data
    self.write2sql(sql)
  File "C:\Users\lenovo\Desktop\小满海关数据爬取\step2.py", line 228, in write2sql
    cur.execute(sql)
  File "D:\ProgramData\Anaconda3\lib\site-packages\pymysql\cursors.py", line 170, in execute
    result = self._query(query)
  File "D:\ProgramData\Anaconda3\lib\site-packages\pymysql\cursors.py", line 328, in _query
    conn.query(q)
  File "D:\ProgramData\Anaconda3\lib\site-packages\pymysql\connections.py", line 516, in query
    self._affected_rows = self._read_query_result(unbuffered=unbuffered)
  File "D:\ProgramData\Anaconda3\lib\site-packages\pymysql\connections.py", line 727, in _read_query_result
    result.read()
  File "D:\ProgramData\Anaconda3\lib\site-packages\pymysql\connections.py", line 1066, in read
    first_packet = self.connection._read_packet()
  File "D:\ProgramData\Anaconda3\lib\site-packages\pymysql\connections.py", line 683, in _read_packet
    packet.check_error()
  File "D:\ProgramData\Anaconda3\lib\site-packages\pymysql\protocol.py", line 220, in check_error
    err.raise_mysql_exception(self._data)
  File "D:\ProgramData\Anaconda3\lib\site-packages\pymysql\err.py", line 109, in raise_mysql_exception
    raise errorclass(errno, errval)
pymysql.err.ProgrammingError: (1146, "Table 'xiaoman.comp' doesn't exist")
&3ac37525a23ee0f8-Traceback (most recent call last):
  File "C:\Users\lenovo\Desktop\小满海关数据爬取\step2.py", line 104, in get_data
    self.write2sql(sql)
  File "C:\Users\lenovo\Desktop\小满海关数据爬取\step2.py", line 228, in write2sql
    cur.execute(sql)
  File "D:\ProgramData\Anaconda3\lib\site-packages\pymysql\cursors.py", line 170, in execute
    result = self._query(query)
  File "D:\ProgramData\Anaconda3\lib\site-packages\pymysql\cursors.py", line 328, in _query
    conn.query(q)
  File "D:\ProgramData\Anaconda3\lib\site-packages\pymysql\connections.py", line 516, in query
    self._affected_rows = self._read_query_result(unbuffered=unbuffered)
  File "D:\ProgramData\Anaconda3\lib\site-packages\pymysql\connections.py", line 727, in _read_query_result
    result.read()
  File "D:\ProgramData\Anaconda3\lib\site-packages\pymysql\connections.py", line 1066, in read
    first_packet = self.connection._read_packet()
  File "D:\ProgramData\Anaconda3\lib\site-packages\pymysql\connections.py", line 683, in _read_packet
    packet.check_error()
  File "D:\ProgramData\Anaconda3\lib\site-packages\pymysql\protocol.py", line 220, in check_error
    err.raise_mysql_exception(self._data)
  File "D:\ProgramData\Anaconda3\lib\site-packages\pymysql\err.py", line 109, in raise_mysql_exception
    raise errorclass(errno, errval)
pymysql.err.ProgrammingError: (1146, "Table 'xiaoman.comp' doesn't exist")
&73cd495dd83f5c27-Traceback (most recent call last):
  File "C:\Users\lenovo\Desktop\小满海关数据爬取\step2.py", line 104, in get_data
    self.write2sql(sql)
  File "C:\Users\lenovo\Desktop\小满海关数据爬取\step2.py", line 228, in write2sql
    cur.execute(sql)
  File "D:\ProgramData\Anaconda3\lib\site-packages\pymysql\cursors.py", line 170, in execute
    result = self._query(query)
  File "D:\ProgramData\Anaconda3\lib\site-packages\pymysql\cursors.py", line 328, in _query
    conn.query(q)
  File "D:\ProgramData\Anaconda3\lib\site-packages\pymysql\connections.py", line 516, in query
    self._affected_rows = self._read_query_result(unbuffered=unbuffered)
  File "D:\ProgramData\Anaconda3\lib\site-packages\pymysql\connections.py", line 727, in _read_query_result
    result.read()
  File "D:\ProgramData\Anaconda3\lib\site-packages\pymysql\connections.py", line 1066, in read
    first_packet = self.connection._read_packet()
  File "D:\ProgramData\Anaconda3\lib\site-packages\pymysql\connections.py", line 683, in _read_packet
    packet.check_error()
  File "D:\ProgramData\Anaconda3\lib\site-packages\pymysql\protocol.py", line 220, in check_error
    err.raise_mysql_exception(self._data)
  File "D:\ProgramData\Anaconda3\lib\site-packages\pymysql\err.py", line 109, in raise_mysql_exception
    raise errorclass(errno, errval)
pymysql.err.ProgrammingError: (1146, "Table 'xiaoman.comp' doesn't exist")
&uszide081fb2ba039158422b218de789595e-Traceback (most recent call last):
  File "C:\Users\lenovo\Desktop\小满海关数据爬取\step2.py", line 104, in get_data
    self.write2sql(sql)
  File "C:\Users\lenovo\Desktop\小满海关数据爬取\step2.py", line 228, in write2sql
    cur.execute(sql)
  File "D:\ProgramData\Anaconda3\lib\site-packages\pymysql\cursors.py", line 170, in execute
    result = self._query(query)
  File "D:\ProgramData\Anaconda3\lib\site-packages\pymysql\cursors.py", line 328, in _query
    conn.query(q)
  File "D:\ProgramData\Anaconda3\lib\site-packages\pymysql\connections.py", line 516, in query
    self._affected_rows = self._read_query_result(unbuffered=unbuffered)
  File "D:\ProgramData\Anaconda3\lib\site-packages\pymysql\connections.py", line 727, in _read_query_result
    result.read()
  File "D:\ProgramData\Anaconda3\lib\site-packages\pymysql\connections.py", line 1066, in read
    first_packet = self.connection._read_packet()
  File "D:\ProgramData\Anaconda3\lib\site-packages\pymysql\connections.py", line 683, in _read_packet
    packet.check_error()
  File "D:\ProgramData\Anaconda3\lib\site-packages\pymysql\protocol.py", line 220, in check_error
    err.raise_mysql_exception(self._data)
  File "D:\ProgramData\Anaconda3\lib\site-packages\pymysql\err.py", line 109, in raise_mysql_exception
    raise errorclass(errno, errval)
pymysql.err.ProgrammingError: (1146, "Table 'xiaoman.comp' doesn't exist")
&7529560624e17312-Traceback (most recent call last):
  File "C:\Users\lenovo\Desktop\小满海关数据爬取\step2.py", line 104, in get_data
    self.write2sql(sql)
  File "C:\Users\lenovo\Desktop\小满海关数据爬取\step2.py", line 228, in write2sql
    cur.execute(sql)
  File "D:\ProgramData\Anaconda3\lib\site-packages\pymysql\cursors.py", line 170, in execute
    result = self._query(query)
  File "D:\ProgramData\Anaconda3\lib\site-packages\pymysql\cursors.py", line 328, in _query
    conn.query(q)
  File "D:\ProgramData\Anaconda3\lib\site-packages\pymysql\connections.py", line 516, in query
    self._affected_rows = self._read_query_result(unbuffered=unbuffered)
  File "D:\ProgramData\Anaconda3\lib\site-packages\pymysql\connections.py", line 727, in _read_query_result
    result.read()
  File "D:\ProgramData\Anaconda3\lib\site-packages\pymysql\connections.py", line 1066, in read
    first_packet = self.connection._read_packet()
  File "D:\ProgramData\Anaconda3\lib\site-packages\pymysql\connections.py", line 683, in _read_packet
    packet.check_error()
  File "D:\ProgramData\Anaconda3\lib\site-packages\pymysql\protocol.py", line 220, in check_error
    err.raise_mysql_exception(self._data)
  File "D:\ProgramData\Anaconda3\lib\site-packages\pymysql\err.py", line 109, in raise_mysql_exception
    raise errorclass(errno, errval)
pymysql.err.ProgrammingError: (1146, "Table 'xiaoman.comp' doesn't exist")
&a178f201ed0d54a2-Traceback (most recent call last):
  File "C:\Users\lenovo\Desktop\小满海关数据爬取\step2.py", line 104, in get_data
    self.write2sql(sql)
  File "C:\Users\lenovo\Desktop\小满海关数据爬取\step2.py", line 228, in write2sql
    cur.execute(sql)
  File "D:\ProgramData\Anaconda3\lib\site-packages\pymysql\cursors.py", line 170, in execute
    result = self._query(query)
  File "D:\ProgramData\Anaconda3\lib\site-packages\pymysql\cursors.py", line 328, in _query
    conn.query(q)
  File "D:\ProgramData\Anaconda3\lib\site-packages\pymysql\connections.py", line 516, in query
    self._affected_rows = self._read_query_result(unbuffered=unbuffered)
  File "D:\ProgramData\Anaconda3\lib\site-packages\pymysql\connections.py", line 727, in _read_query_result
    result.read()
  File "D:\ProgramData\Anaconda3\lib\site-packages\pymysql\connections.py", line 1066, in read
    first_packet = self.connection._read_packet()
  File "D:\ProgramData\Anaconda3\lib\site-packages\pymysql\connections.py", line 683, in _read_packet
    packet.check_error()
  File "D:\ProgramData\Anaconda3\lib\site-packages\pymysql\protocol.py", line 220, in check_error
    err.raise_mysql_exception(self._data)
  File "D:\ProgramData\Anaconda3\lib\site-packages\pymysql\err.py", line 109, in raise_mysql_exception
    raise errorclass(errno, errval)
pymysql.err.ProgrammingError: (1146, "Table 'xiaoman.comp' doesn't exist")
&6fe5052b51367a75-Traceback (most recent call last):
  File "C:\Users\lenovo\Desktop\小满海关数据爬取\step2.py", line 104, in get_data
    self.write2sql(sql)
  File "C:\Users\lenovo\Desktop\小满海关数据爬取\step2.py", line 228, in write2sql
    cur.execute(sql)
  File "D:\ProgramData\Anaconda3\lib\site-packages\pymysql\cursors.py", line 170, in execute
    result = self._query(query)
  File "D:\ProgramData\Anaconda3\lib\site-packages\pymysql\cursors.py", line 328, in _query
    conn.query(q)
  File "D:\ProgramData\Anaconda3\lib\site-packages\pymysql\connections.py", line 516, in query
    self._affected_rows = self._read_query_result(unbuffered=unbuffered)
  File "D:\ProgramData\Anaconda3\lib\site-packages\pymysql\connections.py", line 727, in _read_query_result
    result.read()
  File "D:\ProgramData\Anaconda3\lib\site-packages\pymysql\connections.py", line 1066, in read
    first_packet = self.connection._read_packet()
  File "D:\ProgramData\Anaconda3\lib\site-packages\pymysql\connections.py", line 683, in _read_packet
    packet.check_error()
  File "D:\ProgramData\Anaconda3\lib\site-packages\pymysql\protocol.py", line 220, in check_error
    err.raise_mysql_exception(self._data)
  File "D:\ProgramData\Anaconda3\lib\site-packages\pymysql\err.py", line 109, in raise_mysql_exception
    raise errorclass(errno, errval)
pymysql.err.ProgrammingError: (1146, "Table 'xiaoman.comp' doesn't exist")
&c5dd09840d7d9c06-Traceback (most recent call last):
  File "C:\Users\lenovo\Desktop\小满海关数据爬取\step2.py", line 104, in get_data
    self.write2sql(sql)
  File "C:\Users\lenovo\Desktop\小满海关数据爬取\step2.py", line 228, in write2sql
    cur.execute(sql)
  File "D:\ProgramData\Anaconda3\lib\site-packages\pymysql\cursors.py", line 170, in execute
    result = self._query(query)
  File "D:\ProgramData\Anaconda3\lib\site-packages\pymysql\cursors.py", line 328, in _query
    conn.query(q)
  File "D:\ProgramData\Anaconda3\lib\site-packages\pymysql\connections.py", line 516, in query
    self._affected_rows = self._read_query_result(unbuffered=unbuffered)
  File "D:\ProgramData\Anaconda3\lib\site-packages\pymysql\connections.py", line 727, in _read_query_result
    result.read()
  File "D:\ProgramData\Anaconda3\lib\site-packages\pymysql\connections.py", line 1066, in read
    first_packet = self.connection._read_packet()
  File "D:\ProgramData\Anaconda3\lib\site-packages\pymysql\connections.py", line 683, in _read_packet
    packet.check_error()
  File "D:\ProgramData\Anaconda3\lib\site-packages\pymysql\protocol.py", line 220, in check_error
    err.raise_mysql_exception(self._data)
  File "D:\ProgramData\Anaconda3\lib\site-packages\pymysql\err.py", line 109, in raise_mysql_exception
    raise errorclass(errno, errval)
pymysql.err.ProgrammingError: (1146, "Table 'xiaoman.comp' doesn't exist")
&357cf056261b5313-Traceback (most recent call last):
  File "C:\Users\lenovo\Desktop\小满海关数据爬取\step2.py", line 104, in get_data
    self.write2sql(sql)
  File "C:\Users\lenovo\Desktop\小满海关数据爬取\step2.py", line 228, in write2sql
    cur.execute(sql)
  File "D:\ProgramData\Anaconda3\lib\site-packages\pymysql\cursors.py", line 170, in execute
    result = self._query(query)
  File "D:\ProgramData\Anaconda3\lib\site-packages\pymysql\cursors.py", line 328, in _query
    conn.query(q)
  File "D:\ProgramData\Anaconda3\lib\site-packages\pymysql\connections.py", line 516, in query
    self._affected_rows = self._read_query_result(unbuffered=unbuffered)
  File "D:\ProgramData\Anaconda3\lib\site-packages\pymysql\connections.py", line 727, in _read_query_result
    result.read()
  File "D:\ProgramData\Anaconda3\lib\site-packages\pymysql\connections.py", line 1066, in read
    first_packet = self.connection._read_packet()
  File "D:\ProgramData\Anaconda3\lib\site-packages\pymysql\connections.py", line 683, in _read_packet
    packet.check_error()
  File "D:\ProgramData\Anaconda3\lib\site-packages\pymysql\protocol.py", line 220, in check_error
    err.raise_mysql_exception(self._data)
  File "D:\ProgramData\Anaconda3\lib\site-packages\pymysql\err.py", line 109, in raise_mysql_exception
    raise errorclass(errno, errval)
pymysql.err.ProgrammingError: (1146, "Table 'xiaoman.comp' doesn't exist")
&b483f357a484239b-Traceback (most recent call last):
  File "C:\Users\lenovo\Desktop\小满海关数据爬取\step2.py", line 104, in get_data
    self.write2sql(sql)
  File "C:\Users\lenovo\Desktop\小满海关数据爬取\step2.py", line 228, in write2sql
    cur.execute(sql)
  File "D:\ProgramData\Anaconda3\lib\site-packages\pymysql\cursors.py", line 170, in execute
    result = self._query(query)
  File "D:\ProgramData\Anaconda3\lib\site-packages\pymysql\cursors.py", line 328, in _query
    conn.query(q)
  File "D:\ProgramData\Anaconda3\lib\site-packages\pymysql\connections.py", line 516, in query
    self._affected_rows = self._read_query_result(unbuffered=unbuffered)
  File "D:\ProgramData\Anaconda3\lib\site-packages\pymysql\connections.py", line 727, in _read_query_result
    result.read()
  File "D:\ProgramData\Anaconda3\lib\site-packages\pymysql\connections.py", line 1066, in read
    first_packet = self.connection._read_packet()
  File "D:\ProgramData\Anaconda3\lib\site-packages\pymysql\connections.py", line 683, in _read_packet
    packet.check_error()
  File "D:\ProgramData\Anaconda3\lib\site-packages\pymysql\protocol.py", line 220, in check_error
    err.raise_mysql_exception(self._data)
  File "D:\ProgramData\Anaconda3\lib\site-packages\pymysql\err.py", line 109, in raise_mysql_exception
    raise errorclass(errno, errval)
pymysql.err.ProgrammingError: (1146, "Table 'xiaoman.comp' doesn't exist")
&jpzi69baf8533bf3050bf3a879980ccbfa88-Traceback (most recent call last):
  File "C:\Users\lenovo\Desktop\小满海关数据爬取\step2.py", line 104, in get_data
    self.write2sql(sql)
  File "C:\Users\lenovo\Desktop\小满海关数据爬取\step2.py", line 228, in write2sql
    cur.execute(sql)
  File "D:\ProgramData\Anaconda3\lib\site-packages\pymysql\cursors.py", line 170, in execute
    result = self._query(query)
  File "D:\ProgramData\Anaconda3\lib\site-packages\pymysql\cursors.py", line 328, in _query
    conn.query(q)
  File "D:\ProgramData\Anaconda3\lib\site-packages\pymysql\connections.py", line 516, in query
    self._affected_rows = self._read_query_result(unbuffered=unbuffered)
  File "D:\ProgramData\Anaconda3\lib\site-packages\pymysql\connections.py", line 727, in _read_query_result
    result.read()
  File "D:\ProgramData\Anaconda3\lib\site-packages\pymysql\connections.py", line 1066, in read
    first_packet = self.connection._read_packet()
  File "D:\ProgramData\Anaconda3\lib\site-packages\pymysql\connections.py", line 683, in _read_packet
    packet.check_error()
  File "D:\ProgramData\Anaconda3\lib\site-packages\pymysql\protocol.py", line 220, in check_error
    err.raise_mysql_exception(self._data)
  File "D:\ProgramData\Anaconda3\lib\site-packages\pymysql\err.py", line 109, in raise_mysql_exception
    raise errorclass(errno, errval)
pymysql.err.ProgrammingError: (1146, "Table 'xiaoman.comp' doesn't exist")
&c1a0a40ff69e2f0f-Traceback (most recent call last):
  File "C:\Users\lenovo\Desktop\小满海关数据爬取\step2.py", line 104, in get_data
    self.write2sql(sql)
  File "C:\Users\lenovo\Desktop\小满海关数据爬取\step2.py", line 228, in write2sql
    cur.execute(sql)
  File "D:\ProgramData\Anaconda3\lib\site-packages\pymysql\cursors.py", line 170, in execute
    result = self._query(query)
  File "D:\ProgramData\Anaconda3\lib\site-packages\pymysql\cursors.py", line 328, in _query
    conn.query(q)
  File "D:\ProgramData\Anaconda3\lib\site-packages\pymysql\connections.py", line 516, in query
    self._affected_rows = self._read_query_result(unbuffered=unbuffered)
  File "D:\ProgramData\Anaconda3\lib\site-packages\pymysql\connections.py", line 727, in _read_query_result
    result.read()
  File "D:\ProgramData\Anaconda3\lib\site-packages\pymysql\connections.py", line 1066, in read
    first_packet = self.connection._read_packet()
  File "D:\ProgramData\Anaconda3\lib\site-packages\pymysql\connections.py", line 683, in _read_packet
    packet.check_error()
  File "D:\ProgramData\Anaconda3\lib\site-packages\pymysql\protocol.py", line 220, in check_error
    err.raise_mysql_exception(self._data)
  File "D:\ProgramData\Anaconda3\lib\site-packages\pymysql\err.py", line 109, in raise_mysql_exception
    raise errorclass(errno, errval)
pymysql.err.ProgrammingError: (1146, "Table 'xiaoman.comp' doesn't exist")
&dfed4fd0749bcddb-Traceback (most recent call last):
  File "C:\Users\lenovo\Desktop\小满海关数据爬取\step2.py", line 104, in get_data
    self.write2sql(sql)
  File "C:\Users\lenovo\Desktop\小满海关数据爬取\step2.py", line 228, in write2sql
    cur.execute(sql)
  File "D:\ProgramData\Anaconda3\lib\site-packages\pymysql\cursors.py", line 170, in execute
    result = self._query(query)
  File "D:\ProgramData\Anaconda3\lib\site-packages\pymysql\cursors.py", line 328, in _query
    conn.query(q)
  File "D:\ProgramData\Anaconda3\lib\site-packages\pymysql\connections.py", line 516, in query
    self._affected_rows = self._read_query_result(unbuffered=unbuffered)
  File "D:\ProgramData\Anaconda3\lib\site-packages\pymysql\connections.py", line 727, in _read_query_result
    result.read()
  File "D:\ProgramData\Anaconda3\lib\site-packages\pymysql\connections.py", line 1066, in read
    first_packet = self.connection._read_packet()
  File "D:\ProgramData\Anaconda3\lib\site-packages\pymysql\connections.py", line 683, in _read_packet
    packet.check_error()
  File "D:\ProgramData\Anaconda3\lib\site-packages\pymysql\protocol.py", line 220, in check_error
    err.raise_mysql_exception(self._data)
  File "D:\ProgramData\Anaconda3\lib\site-packages\pymysql\err.py", line 109, in raise_mysql_exception
    raise errorclass(errno, errval)
pymysql.err.ProgrammingError: (1146, "Table 'xiaoman.comp' doesn't exist")
&e24fa060e1630956-Traceback (most recent call last):
  File "C:\Users\lenovo\Desktop\小满海关数据爬取\step2.py", line 104, in get_data
    self.write2sql(sql)
  File "C:\Users\lenovo\Desktop\小满海关数据爬取\step2.py", line 228, in write2sql
    cur.execute(sql)
  File "D:\ProgramData\Anaconda3\lib\site-packages\pymysql\cursors.py", line 170, in execute
    result = self._query(query)
  File "D:\ProgramData\Anaconda3\lib\site-packages\pymysql\cursors.py", line 328, in _query
    conn.query(q)
  File "D:\ProgramData\Anaconda3\lib\site-packages\pymysql\connections.py", line 516, in query
    self._affected_rows = self._read_query_result(unbuffered=unbuffered)
  File "D:\ProgramData\Anaconda3\lib\site-packages\pymysql\connections.py", line 727, in _read_query_result
    result.read()
  File "D:\ProgramData\Anaconda3\lib\site-packages\pymysql\connections.py", line 1066, in read
    first_packet = self.connection._read_packet()
  File "D:\ProgramData\Anaconda3\lib\site-packages\pymysql\connections.py", line 683, in _read_packet
    packet.check_error()
  File "D:\ProgramData\Anaconda3\lib\site-packages\pymysql\protocol.py", line 220, in check_error
    err.raise_mysql_exception(self._data)
  File "D:\ProgramData\Anaconda3\lib\site-packages\pymysql\err.py", line 109, in raise_mysql_exception
    raise errorclass(errno, errval)
pymysql.err.ProgrammingError: (1146, "Table 'xiaoman.comp' doesn't exist")
&