uszi1e0014ea63399aa6365ea5324dc80506-5-EXPORT-Traceback (most recent call last):
  File "C:\Users\YQ\Desktop\小满海关数据爬取\login1.py", line 28, in get_login
    username = self.web.find_element_by_id('email')
  File "D:\Anaconda\lib\site-packages\selenium\webdriver\remote\webdriver.py", line 359, in find_element_by_id
    return self.find_element(by=By.ID, value=id_)
  File "D:\Anaconda\lib\site-packages\selenium\webdriver\remote\webdriver.py", line 966, in find_element
    'value': value})['value']
  File "D:\Anaconda\lib\site-packages\selenium\webdriver\remote\webdriver.py", line 320, in execute
    self.error_handler.check_response(response)
  File "D:\Anaconda\lib\site-packages\selenium\webdriver\remote\errorhandler.py", line 242, in check_response
    raise exception_class(message, screen, stacktrace)
selenium.common.exceptions.NoSuchElementException: Message: no such element: Unable to locate element: {"method":"id","selector":"email"}
  (Session info: chrome=68.0.3440.106)
  (Driver info: chromedriver=2.40.565498 (ea082db3280dd6843ebfb08a625e3eb905c4f5ab),platform=Windows NT 10.0.17134 x86_64)


During handling of the above exception, another exception occurred:

Traceback (most recent call last):
  File "C:\Users\YQ\Desktop\小满海关数据爬取\step3.py", line 123, in get_data
    self.get_data1(i['id'], hashid)
  File "C:\Users\YQ\Desktop\小满海关数据爬取\step3.py", line 151, in get_data1
    user, proxy, cookies = get_cookie()
  File "C:\Users\YQ\Desktop\小满海关数据爬取\Util\tools.py", line 139, in get_cookie
    user, proxy, cookies_ = cookies()
  File "C:\Users\YQ\Desktop\小满海关数据爬取\Util\tools.py", line 99, in cookies
    update_cookies()
  File "C:\Users\YQ\Desktop\小满海关数据爬取\Util\tools.py", line 74, in update_cookies
    users[params[0]]['proxy'], users[params[0]]['cookies'] = login(params[0], params[1])
  File "C:\Users\YQ\Desktop\小满海关数据爬取\login1.py", line 82, in login
    return sp.get_login(user, pwd)   #返回cookies
  File "C:\Users\YQ\Desktop\小满海关数据爬取\login1.py", line 55, in get_login
    return self.get_login(user, pwd)
  File "C:\Users\YQ\Desktop\小满海关数据爬取\login1.py", line 25, in get_login
    self.web.get('https://login.xiaoman.cn/login?system_id=discovery&return_url=https%3A%2F%2Fx.xiaoman.cn%2F')
  File "D:\Anaconda\lib\site-packages\selenium\webdriver\remote\webdriver.py", line 332, in get
    self.execute(Command.GET, {'url': url})
  File "D:\Anaconda\lib\site-packages\selenium\webdriver\remote\webdriver.py", line 320, in execute
    self.error_handler.check_response(response)
  File "D:\Anaconda\lib\site-packages\selenium\webdriver\remote\errorhandler.py", line 242, in check_response
    raise exception_class(message, screen, stacktrace)
selenium.common.exceptions.TimeoutException: Message: timeout
  (Session info: chrome=68.0.3440.106)
  (Driver info: chromedriver=2.40.565498 (ea082db3280dd6843ebfb08a625e3eb905c4f5ab),platform=Windows NT 10.0.17134 x86_64)

&