d74df03e05c0e2f0-2-EXPORT-Traceback (most recent call last):
  File "C:\Users\YQ\Desktop\小满海关数据爬取\step3.py", line 83, in get_data
    response = self.session.get(url=self.url1, params=params1, proxies={'http': proxy}).json()
  File "D:\Anaconda\lib\site-packages\requests\models.py", line 892, in json
    return complexjson.loads(self.text, **kwargs)
  File "D:\Anaconda\lib\json\__init__.py", line 354, in loads
    return _default_decoder.decode(s)
  File "D:\Anaconda\lib\json\decoder.py", line 339, in decode
    obj, end = self.raw_decode(s, idx=_w(s, 0).end())
  File "D:\Anaconda\lib\json\decoder.py", line 357, in raw_decode
    raise JSONDecodeError("Expecting value", s, err.value) from None
json.decoder.JSONDecodeError: Expecting value: line 1 column 1 (char 0)
&d74df03e05c0e2f0-3-EXPORT-Traceback (most recent call last):
  File "C:\Users\YQ\Desktop\小满海关数据爬取\step3.py", line 83, in get_data
    response = self.session.get(url=self.url1, params=params1, proxies={'http': proxy}).json()
  File "D:\Anaconda\lib\site-packages\requests\models.py", line 892, in json
    return complexjson.loads(self.text, **kwargs)
  File "D:\Anaconda\lib\json\__init__.py", line 354, in loads
    return _default_decoder.decode(s)
  File "D:\Anaconda\lib\json\decoder.py", line 339, in decode
    obj, end = self.raw_decode(s, idx=_w(s, 0).end())
  File "D:\Anaconda\lib\json\decoder.py", line 357, in raw_decode
    raise JSONDecodeError("Expecting value", s, err.value) from None
json.decoder.JSONDecodeError: Expecting value: line 1 column 1 (char 0)
&America2017V6452061-Traceback (most recent call last):
  File "C:\Users\YQ\Desktop\小满海关数据爬取\step3.py", line 211, in get_data1
    self.write2sql(sql)
  File "C:\Users\YQ\Desktop\小满海关数据爬取\step3.py", line 222, in write2sql
    cur.execute(sql)
  File "D:\Anaconda\lib\site-packages\pymysql\cursors.py", line 170, in execute
    result = self._query(query)
  File "D:\Anaconda\lib\site-packages\pymysql\cursors.py", line 328, in _query
    conn.query(q)
  File "D:\Anaconda\lib\site-packages\pymysql\connections.py", line 516, in query
    self._affected_rows = self._read_query_result(unbuffered=unbuffered)
  File "D:\Anaconda\lib\site-packages\pymysql\connections.py", line 727, in _read_query_result
    result.read()
  File "D:\Anaconda\lib\site-packages\pymysql\connections.py", line 1066, in read
    first_packet = self.connection._read_packet()
  File "D:\Anaconda\lib\site-packages\pymysql\connections.py", line 683, in _read_packet
    packet.check_error()
  File "D:\Anaconda\lib\site-packages\pymysql\protocol.py", line 220, in check_error
    err.raise_mysql_exception(self._data)
  File "D:\Anaconda\lib\site-packages\pymysql\err.py", line 109, in raise_mysql_exception
    raise errorclass(errno, errval)
pymysql.err.ProgrammingError: (1064, "You have an error in your SQL syntax; check the manual that corresponds to your MySQL server version for the right syntax to use near 'VIA TOSCANINI 1, ZZ, ALME\\', ITALY','843139', '843139','None', 'PARTS AND ELEMEN' at line 1")
&America2017V2567337-Traceback (most recent call last):
  File "C:\Users\YQ\Desktop\小满海关数据爬取\step3.py", line 211, in get_data1
    self.write2sql(sql)
  File "C:\Users\YQ\Desktop\小满海关数据爬取\step3.py", line 222, in write2sql
    cur.execute(sql)
  File "D:\Anaconda\lib\site-packages\pymysql\cursors.py", line 170, in execute
    result = self._query(query)
  File "D:\Anaconda\lib\site-packages\pymysql\cursors.py", line 328, in _query
    conn.query(q)
  File "D:\Anaconda\lib\site-packages\pymysql\connections.py", line 516, in query
    self._affected_rows = self._read_query_result(unbuffered=unbuffered)
  File "D:\Anaconda\lib\site-packages\pymysql\connections.py", line 727, in _read_query_result
    result.read()
  File "D:\Anaconda\lib\site-packages\pymysql\connections.py", line 1066, in read
    first_packet = self.connection._read_packet()
  File "D:\Anaconda\lib\site-packages\pymysql\connections.py", line 683, in _read_packet
    packet.check_error()
  File "D:\Anaconda\lib\site-packages\pymysql\protocol.py", line 220, in check_error
    err.raise_mysql_exception(self._data)
  File "D:\Anaconda\lib\site-packages\pymysql\err.py", line 109, in raise_mysql_exception
    raise errorclass(errno, errval)
pymysql.err.ProgrammingError: (1064, "You have an error in your SQL syntax; check the manual that corresponds to your MySQL server version for the right syntax to use near 'VIA TOSCANINI 1, ZZ, ALME\\', ITALY','843139', '843139','None', 'PARTS AND ELEMEN' at line 1")
&America2017T8051988-Traceback (most recent call last):
  File "C:\Users\YQ\Desktop\小满海关数据爬取\step3.py", line 211, in get_data1
    self.write2sql(sql)
  File "C:\Users\YQ\Desktop\小满海关数据爬取\step3.py", line 222, in write2sql
    cur.execute(sql)
  File "D:\Anaconda\lib\site-packages\pymysql\cursors.py", line 170, in execute
    result = self._query(query)
  File "D:\Anaconda\lib\site-packages\pymysql\cursors.py", line 328, in _query
    conn.query(q)
  File "D:\Anaconda\lib\site-packages\pymysql\connections.py", line 516, in query
    self._affected_rows = self._read_query_result(unbuffered=unbuffered)
  File "D:\Anaconda\lib\site-packages\pymysql\connections.py", line 727, in _read_query_result
    result.read()
  File "D:\Anaconda\lib\site-packages\pymysql\connections.py", line 1066, in read
    first_packet = self.connection._read_packet()
  File "D:\Anaconda\lib\site-packages\pymysql\connections.py", line 683, in _read_packet
    packet.check_error()
  File "D:\Anaconda\lib\site-packages\pymysql\protocol.py", line 220, in check_error
    err.raise_mysql_exception(self._data)
  File "D:\Anaconda\lib\site-packages\pymysql\err.py", line 109, in raise_mysql_exception
    raise errorclass(errno, errval)
pymysql.err.ProgrammingError: (1064, "You have an error in your SQL syntax; check the manual that corresponds to your MySQL server version for the right syntax to use near 'VIA TOSCANINI 1, ZZ, ALME\\', ITALY','847989', '847989','None', 'PARTS AND ELEMEN' at line 1")
&America2017S7926570-Traceback (most recent call last):
  File "C:\Users\YQ\Desktop\小满海关数据爬取\step3.py", line 211, in get_data1
    self.write2sql(sql)
  File "C:\Users\YQ\Desktop\小满海关数据爬取\step3.py", line 222, in write2sql
    cur.execute(sql)
  File "D:\Anaconda\lib\site-packages\pymysql\cursors.py", line 170, in execute
    result = self._query(query)
  File "D:\Anaconda\lib\site-packages\pymysql\cursors.py", line 328, in _query
    conn.query(q)
  File "D:\Anaconda\lib\site-packages\pymysql\connections.py", line 516, in query
    self._affected_rows = self._read_query_result(unbuffered=unbuffered)
  File "D:\Anaconda\lib\site-packages\pymysql\connections.py", line 727, in _read_query_result
    result.read()
  File "D:\Anaconda\lib\site-packages\pymysql\connections.py", line 1066, in read
    first_packet = self.connection._read_packet()
  File "D:\Anaconda\lib\site-packages\pymysql\connections.py", line 683, in _read_packet
    packet.check_error()
  File "D:\Anaconda\lib\site-packages\pymysql\protocol.py", line 220, in check_error
    err.raise_mysql_exception(self._data)
  File "D:\Anaconda\lib\site-packages\pymysql\err.py", line 109, in raise_mysql_exception
    raise errorclass(errno, errval)
pymysql.err.ProgrammingError: (1064, "You have an error in your SQL syntax; check the manual that corresponds to your MySQL server version for the right syntax to use near 'VIA TOSCANINI 1, ZZ, ALME\\', ITALY','847989', '847989','None', 'PARTS AND ELEMEN' at line 1")
&America2017S4520378-Traceback (most recent call last):
  File "C:\Users\YQ\Desktop\小满海关数据爬取\step3.py", line 211, in get_data1
    self.write2sql(sql)
  File "C:\Users\YQ\Desktop\小满海关数据爬取\step3.py", line 222, in write2sql
    cur.execute(sql)
  File "D:\Anaconda\lib\site-packages\pymysql\cursors.py", line 170, in execute
    result = self._query(query)
  File "D:\Anaconda\lib\site-packages\pymysql\cursors.py", line 328, in _query
    conn.query(q)
  File "D:\Anaconda\lib\site-packages\pymysql\connections.py", line 516, in query
    self._affected_rows = self._read_query_result(unbuffered=unbuffered)
  File "D:\Anaconda\lib\site-packages\pymysql\connections.py", line 727, in _read_query_result
    result.read()
  File "D:\Anaconda\lib\site-packages\pymysql\connections.py", line 1066, in read
    first_packet = self.connection._read_packet()
  File "D:\Anaconda\lib\site-packages\pymysql\connections.py", line 683, in _read_packet
    packet.check_error()
  File "D:\Anaconda\lib\site-packages\pymysql\protocol.py", line 220, in check_error
    err.raise_mysql_exception(self._data)
  File "D:\Anaconda\lib\site-packages\pymysql\err.py", line 109, in raise_mysql_exception
    raise errorclass(errno, errval)
pymysql.err.ProgrammingError: (1064, "You have an error in your SQL syntax; check the manual that corresponds to your MySQL server version for the right syntax to use near 'VIA TOSCANINI 1, ZZ, ALME\\', ITALY','847989', '847989','None', 'PARTS AND ELEMEN' at line 1")
&America2017U3059792-Traceback (most recent call last):
  File "C:\Users\YQ\Desktop\小满海关数据爬取\step3.py", line 142, in get_data1
    response = self.session.get(url=url, proxies={'http': proxy}).json()
  File "D:\Anaconda\lib\site-packages\requests\models.py", line 892, in json
    return complexjson.loads(self.text, **kwargs)
  File "D:\Anaconda\lib\json\__init__.py", line 354, in loads
    return _default_decoder.decode(s)
  File "D:\Anaconda\lib\json\decoder.py", line 339, in decode
    obj, end = self.raw_decode(s, idx=_w(s, 0).end())
  File "D:\Anaconda\lib\json\decoder.py", line 357, in raw_decode
    raise JSONDecodeError("Expecting value", s, err.value) from None
json.decoder.JSONDecodeError: Expecting value: line 1 column 1 (char 0)
&Peru201606b5fa2a165d3af050542e5859777ff9-Traceback (most recent call last):
  File "D:\Anaconda\lib\site-packages\urllib3\connectionpool.py", line 601, in urlopen
    chunked=chunked)
  File "D:\Anaconda\lib\site-packages\urllib3\connectionpool.py", line 387, in _make_request
    six.raise_from(e, None)
  File "<string>", line 2, in raise_from
  File "D:\Anaconda\lib\site-packages\urllib3\connectionpool.py", line 383, in _make_request
    httplib_response = conn.getresponse()
  File "D:\Anaconda\lib\http\client.py", line 1331, in getresponse
    response.begin()
  File "D:\Anaconda\lib\http\client.py", line 297, in begin
    version, status, reason = self._read_status()
  File "D:\Anaconda\lib\http\client.py", line 258, in _read_status
    line = str(self.fp.readline(_MAXLINE + 1), "iso-8859-1")
  File "D:\Anaconda\lib\socket.py", line 586, in readinto
    return self._sock.recv_into(b)
  File "D:\Anaconda\lib\site-packages\urllib3\contrib\pyopenssl.py", line 285, in recv_into
    raise SocketError(str(e))
OSError: (10053, 'WSAECONNABORTED')

During handling of the above exception, another exception occurred:

Traceback (most recent call last):
  File "D:\Anaconda\lib\site-packages\requests\adapters.py", line 440, in send
    timeout=timeout
  File "D:\Anaconda\lib\site-packages\urllib3\connectionpool.py", line 639, in urlopen
    _stacktrace=sys.exc_info()[2])
  File "D:\Anaconda\lib\site-packages\urllib3\util\retry.py", line 357, in increment
    raise six.reraise(type(error), error, _stacktrace)
  File "D:\Anaconda\lib\site-packages\urllib3\packages\six.py", line 685, in reraise
    raise value.with_traceback(tb)
  File "D:\Anaconda\lib\site-packages\urllib3\connectionpool.py", line 601, in urlopen
    chunked=chunked)
  File "D:\Anaconda\lib\site-packages\urllib3\connectionpool.py", line 387, in _make_request
    six.raise_from(e, None)
  File "<string>", line 2, in raise_from
  File "D:\Anaconda\lib\site-packages\urllib3\connectionpool.py", line 383, in _make_request
    httplib_response = conn.getresponse()
  File "D:\Anaconda\lib\http\client.py", line 1331, in getresponse
    response.begin()
  File "D:\Anaconda\lib\http\client.py", line 297, in begin
    version, status, reason = self._read_status()
  File "D:\Anaconda\lib\http\client.py", line 258, in _read_status
    line = str(self.fp.readline(_MAXLINE + 1), "iso-8859-1")
  File "D:\Anaconda\lib\socket.py", line 586, in readinto
    return self._sock.recv_into(b)
  File "D:\Anaconda\lib\site-packages\urllib3\contrib\pyopenssl.py", line 285, in recv_into
    raise SocketError(str(e))
urllib3.exceptions.ProtocolError: ('Connection aborted.', OSError("(10053, 'WSAECONNABORTED')",))

During handling of the above exception, another exception occurred:

Traceback (most recent call last):
  File "C:\Users\YQ\Desktop\小满海关数据爬取\step3.py", line 142, in get_data1
    response = self.session.get(url=url, proxies={'http': proxy}).json()
  File "D:\Anaconda\lib\site-packages\requests\sessions.py", line 521, in get
    return self.request('GET', url, **kwargs)
  File "D:\Anaconda\lib\site-packages\requests\sessions.py", line 508, in request
    resp = self.send(prep, **send_kwargs)
  File "D:\Anaconda\lib\site-packages\requests\sessions.py", line 618, in send
    r = adapter.send(request, **kwargs)
  File "D:\Anaconda\lib\site-packages\requests\adapters.py", line 490, in send
    raise ConnectionError(err, request=request)
requests.exceptions.ConnectionError: ('Connection aborted.', OSError("(10053, 'WSAECONNABORTED')",))
&